test_path/bar_codes/base/white.png /bar_codes/base/out/out.png
test_path/bar_codes/base/white.png /bar_codes/base/out/out.png
test_path/bar_codes/base/white.png /bar_codes/base/out/out.png
test_path/bar_codes/base/white.png /bar_codes/base/out/out.png
test_path/bar_codes/base/white.png /bar_codes/base/out/out.png
test_path/bar_codes/base/white.png /bar_codes/base/out/out.png
test_path/bar_codes/base/white.png /bar_codes/base/out/out.png
Internal Server Error: /api/v1/inventory/inventory/products/
Traceback (most recent call last):
  File "/Library/Frameworks/Python.framework/Versions/3.10/lib/python3.10/site-packages/django/core/paginator.py", line 48, in validate_number
    number = int(number)
TypeError: int() argument must be a string, a bytes-like object or a real number, not 'NoneType'

During handling of the above exception, another exception occurred:

Traceback (most recent call last):
  File "/Users/macmini/Machine Learning/kaarujbe/kaaruj/inventory/api/inventory/views.py", line 145, in paginate_queryset
    paginated_queryset = paginator.page(page)
  File "/Library/Frameworks/Python.framework/Versions/3.10/lib/python3.10/site-packages/django/core/paginator.py", line 75, in page
    number = self.validate_number(number)
  File "/Library/Frameworks/Python.framework/Versions/3.10/lib/python3.10/site-packages/django/core/paginator.py", line 50, in validate_number
    raise PageNotAnInteger(_("That page number is not an integer"))
django.core.paginator.PageNotAnInteger: That page number is not an integer

During handling of the above exception, another exception occurred:

Traceback (most recent call last):
  File "/Library/Frameworks/Python.framework/Versions/3.10/lib/python3.10/site-packages/django/core/handlers/exception.py", line 55, in inner
    response = get_response(request)
  File "/Library/Frameworks/Python.framework/Versions/3.10/lib/python3.10/site-packages/django/core/handlers/base.py", line 197, in _get_response
    response = wrapped_callback(request, *callback_args, **callback_kwargs)
  File "/Library/Frameworks/Python.framework/Versions/3.10/lib/python3.10/site-packages/django/views/decorators/csrf.py", line 54, in wrapped_view
    return view_func(*args, **kwargs)
  File "/Library/Frameworks/Python.framework/Versions/3.10/lib/python3.10/site-packages/rest_framework/viewsets.py", line 125, in view
    return self.dispatch(request, *args, **kwargs)
  File "/Library/Frameworks/Python.framework/Versions/3.10/lib/python3.10/site-packages/rest_framework/views.py", line 509, in dispatch
    response = self.handle_exception(exc)
  File "/Library/Frameworks/Python.framework/Versions/3.10/lib/python3.10/site-packages/rest_framework/views.py", line 469, in handle_exception
    self.raise_uncaught_exception(exc)
  File "/Library/Frameworks/Python.framework/Versions/3.10/lib/python3.10/site-packages/rest_framework/views.py", line 480, in raise_uncaught_exception
    raise exc
  File "/Library/Frameworks/Python.framework/Versions/3.10/lib/python3.10/site-packages/rest_framework/views.py", line 506, in dispatch
    response = handler(request, *args, **kwargs)
  File "/Library/Frameworks/Python.framework/Versions/3.10/lib/python3.10/site-packages/rest_framework/mixins.py", line 40, in list
    page = self.paginate_queryset(queryset)
  File "/Users/macmini/Machine Learning/kaarujbe/kaaruj/inventory/api/inventory/views.py", line 146, in paginate_queryset
    except EmptyPage:
NameError: name 'EmptyPage' is not defined
"GET /api/v1/inventory/inventory/products/ HTTP/1.1" 500 19561
Internal Server Error: /api/v1/inventory/inventory/products/
Traceback (most recent call last):
  File "/Library/Frameworks/Python.framework/Versions/3.10/lib/python3.10/site-packages/django/core/paginator.py", line 48, in validate_number
    number = int(number)
TypeError: int() argument must be a string, a bytes-like object or a real number, not 'NoneType'

During handling of the above exception, another exception occurred:

Traceback (most recent call last):
  File "/Users/macmini/Machine Learning/kaarujbe/kaaruj/inventory/api/inventory/views.py", line 145, in paginate_queryset
    paginated_queryset = paginator.page(page)
  File "/Library/Frameworks/Python.framework/Versions/3.10/lib/python3.10/site-packages/django/core/paginator.py", line 75, in page
    number = self.validate_number(number)
  File "/Library/Frameworks/Python.framework/Versions/3.10/lib/python3.10/site-packages/django/core/paginator.py", line 50, in validate_number
    raise PageNotAnInteger(_("That page number is not an integer"))
django.core.paginator.PageNotAnInteger: That page number is not an integer

During handling of the above exception, another exception occurred:

Traceback (most recent call last):
  File "/Library/Frameworks/Python.framework/Versions/3.10/lib/python3.10/site-packages/django/core/handlers/exception.py", line 55, in inner
    response = get_response(request)
  File "/Library/Frameworks/Python.framework/Versions/3.10/lib/python3.10/site-packages/django/core/handlers/base.py", line 197, in _get_response
    response = wrapped_callback(request, *callback_args, **callback_kwargs)
  File "/Library/Frameworks/Python.framework/Versions/3.10/lib/python3.10/site-packages/django/views/decorators/csrf.py", line 54, in wrapped_view
    return view_func(*args, **kwargs)
  File "/Library/Frameworks/Python.framework/Versions/3.10/lib/python3.10/site-packages/rest_framework/viewsets.py", line 125, in view
    return self.dispatch(request, *args, **kwargs)
  File "/Library/Frameworks/Python.framework/Versions/3.10/lib/python3.10/site-packages/rest_framework/views.py", line 509, in dispatch
    response = self.handle_exception(exc)
  File "/Library/Frameworks/Python.framework/Versions/3.10/lib/python3.10/site-packages/rest_framework/views.py", line 469, in handle_exception
    self.raise_uncaught_exception(exc)
  File "/Library/Frameworks/Python.framework/Versions/3.10/lib/python3.10/site-packages/rest_framework/views.py", line 480, in raise_uncaught_exception
    raise exc
  File "/Library/Frameworks/Python.framework/Versions/3.10/lib/python3.10/site-packages/rest_framework/views.py", line 506, in dispatch
    response = handler(request, *args, **kwargs)
  File "/Library/Frameworks/Python.framework/Versions/3.10/lib/python3.10/site-packages/rest_framework/mixins.py", line 40, in list
    page = self.paginate_queryset(queryset)
  File "/Users/macmini/Machine Learning/kaarujbe/kaaruj/inventory/api/inventory/views.py", line 146, in paginate_queryset
    except EmptyPage:
NameError: name 'EmptyPage' is not defined
"GET /api/v1/inventory/inventory/products/ HTTP/1.1" 500 19561
test_path/bar_codes/base/white.png /bar_codes/base/out/out.png
Internal Server Error: /api/v1/inventory/inventory/products/
Traceback (most recent call last):
  File "/Library/Frameworks/Python.framework/Versions/3.10/lib/python3.10/site-packages/django/core/paginator.py", line 48, in validate_number
    number = int(number)
TypeError: int() argument must be a string, a bytes-like object or a real number, not 'NoneType'

During handling of the above exception, another exception occurred:

Traceback (most recent call last):
  File "/Library/Frameworks/Python.framework/Versions/3.10/lib/python3.10/site-packages/django/core/handlers/exception.py", line 55, in inner
    response = get_response(request)
  File "/Library/Frameworks/Python.framework/Versions/3.10/lib/python3.10/site-packages/django/core/handlers/base.py", line 197, in _get_response
    response = wrapped_callback(request, *callback_args, **callback_kwargs)
  File "/Library/Frameworks/Python.framework/Versions/3.10/lib/python3.10/site-packages/django/views/decorators/csrf.py", line 54, in wrapped_view
    return view_func(*args, **kwargs)
  File "/Library/Frameworks/Python.framework/Versions/3.10/lib/python3.10/site-packages/rest_framework/viewsets.py", line 125, in view
    return self.dispatch(request, *args, **kwargs)
  File "/Library/Frameworks/Python.framework/Versions/3.10/lib/python3.10/site-packages/rest_framework/views.py", line 509, in dispatch
    response = self.handle_exception(exc)
  File "/Library/Frameworks/Python.framework/Versions/3.10/lib/python3.10/site-packages/rest_framework/views.py", line 469, in handle_exception
    self.raise_uncaught_exception(exc)
  File "/Library/Frameworks/Python.framework/Versions/3.10/lib/python3.10/site-packages/rest_framework/views.py", line 480, in raise_uncaught_exception
    raise exc
  File "/Library/Frameworks/Python.framework/Versions/3.10/lib/python3.10/site-packages/rest_framework/views.py", line 506, in dispatch
    response = handler(request, *args, **kwargs)
  File "/Library/Frameworks/Python.framework/Versions/3.10/lib/python3.10/site-packages/rest_framework/mixins.py", line 40, in list
    page = self.paginate_queryset(queryset)
  File "/Users/macmini/Machine Learning/kaarujbe/kaaruj/inventory/api/inventory/views.py", line 145, in paginate_queryset
    paginated_queryset = paginator.page(page)
  File "/Library/Frameworks/Python.framework/Versions/3.10/lib/python3.10/site-packages/django/core/paginator.py", line 75, in page
    number = self.validate_number(number)
  File "/Library/Frameworks/Python.framework/Versions/3.10/lib/python3.10/site-packages/django/core/paginator.py", line 50, in validate_number
    raise PageNotAnInteger(_("That page number is not an integer"))
django.core.paginator.PageNotAnInteger: That page number is not an integer
"GET /api/v1/inventory/inventory/products/ HTTP/1.1" 500 19331
test_path/bar_codes/base/white.png /bar_codes/base/out/out.png
test_path/bar_codes/base/white.png /bar_codes/base/out/out.png
Internal Server Error: /api/v1/inventory/inventory/products/
Traceback (most recent call last):
  File "/Library/Frameworks/Python.framework/Versions/3.10/lib/python3.10/site-packages/django/core/paginator.py", line 48, in validate_number
    number = int(number)
TypeError: int() argument must be a string, a bytes-like object or a real number, not 'NoneType'

During handling of the above exception, another exception occurred:

Traceback (most recent call last):
  File "/Library/Frameworks/Python.framework/Versions/3.10/lib/python3.10/site-packages/django/core/handlers/exception.py", line 55, in inner
    response = get_response(request)
  File "/Library/Frameworks/Python.framework/Versions/3.10/lib/python3.10/site-packages/django/core/handlers/base.py", line 197, in _get_response
    response = wrapped_callback(request, *callback_args, **callback_kwargs)
  File "/Library/Frameworks/Python.framework/Versions/3.10/lib/python3.10/site-packages/django/views/decorators/csrf.py", line 54, in wrapped_view
    return view_func(*args, **kwargs)
  File "/Library/Frameworks/Python.framework/Versions/3.10/lib/python3.10/site-packages/rest_framework/viewsets.py", line 125, in view
    return self.dispatch(request, *args, **kwargs)
  File "/Library/Frameworks/Python.framework/Versions/3.10/lib/python3.10/site-packages/rest_framework/views.py", line 509, in dispatch
    response = self.handle_exception(exc)
  File "/Library/Frameworks/Python.framework/Versions/3.10/lib/python3.10/site-packages/rest_framework/views.py", line 469, in handle_exception
    self.raise_uncaught_exception(exc)
  File "/Library/Frameworks/Python.framework/Versions/3.10/lib/python3.10/site-packages/rest_framework/views.py", line 480, in raise_uncaught_exception
    raise exc
  File "/Library/Frameworks/Python.framework/Versions/3.10/lib/python3.10/site-packages/rest_framework/views.py", line 506, in dispatch
    response = handler(request, *args, **kwargs)
  File "/Library/Frameworks/Python.framework/Versions/3.10/lib/python3.10/site-packages/rest_framework/mixins.py", line 40, in list
    page = self.paginate_queryset(queryset)
  File "/Users/macmini/Machine Learning/kaarujbe/kaaruj/inventory/api/inventory/views.py", line 145, in paginate_queryset
    paginated_queryset = paginator.page(page)
  File "/Library/Frameworks/Python.framework/Versions/3.10/lib/python3.10/site-packages/django/core/paginator.py", line 75, in page
    number = self.validate_number(number)
  File "/Library/Frameworks/Python.framework/Versions/3.10/lib/python3.10/site-packages/django/core/paginator.py", line 50, in validate_number
    raise PageNotAnInteger(_("That page number is not an integer"))
django.core.paginator.PageNotAnInteger: That page number is not an integer
"GET /api/v1/inventory/inventory/products/ HTTP/1.1" 500 19331
Internal Server Error: /api/v1/inventory/inventory/products/
Traceback (most recent call last):
  File "/Library/Frameworks/Python.framework/Versions/3.10/lib/python3.10/site-packages/django/core/paginator.py", line 48, in validate_number
    number = int(number)
TypeError: int() argument must be a string, a bytes-like object or a real number, not 'NoneType'

During handling of the above exception, another exception occurred:

Traceback (most recent call last):
  File "/Library/Frameworks/Python.framework/Versions/3.10/lib/python3.10/site-packages/django/core/handlers/exception.py", line 55, in inner
    response = get_response(request)
  File "/Library/Frameworks/Python.framework/Versions/3.10/lib/python3.10/site-packages/django/core/handlers/base.py", line 197, in _get_response
    response = wrapped_callback(request, *callback_args, **callback_kwargs)
  File "/Library/Frameworks/Python.framework/Versions/3.10/lib/python3.10/site-packages/django/views/decorators/csrf.py", line 54, in wrapped_view
    return view_func(*args, **kwargs)
  File "/Library/Frameworks/Python.framework/Versions/3.10/lib/python3.10/site-packages/rest_framework/viewsets.py", line 125, in view
    return self.dispatch(request, *args, **kwargs)
  File "/Library/Frameworks/Python.framework/Versions/3.10/lib/python3.10/site-packages/rest_framework/views.py", line 509, in dispatch
    response = self.handle_exception(exc)
  File "/Library/Frameworks/Python.framework/Versions/3.10/lib/python3.10/site-packages/rest_framework/views.py", line 469, in handle_exception
    self.raise_uncaught_exception(exc)
  File "/Library/Frameworks/Python.framework/Versions/3.10/lib/python3.10/site-packages/rest_framework/views.py", line 480, in raise_uncaught_exception
    raise exc
  File "/Library/Frameworks/Python.framework/Versions/3.10/lib/python3.10/site-packages/rest_framework/views.py", line 506, in dispatch
    response = handler(request, *args, **kwargs)
  File "/Library/Frameworks/Python.framework/Versions/3.10/lib/python3.10/site-packages/rest_framework/mixins.py", line 40, in list
    page = self.paginate_queryset(queryset)
  File "/Users/macmini/Machine Learning/kaarujbe/kaaruj/inventory/api/inventory/views.py", line 145, in paginate_queryset
    paginated_queryset = paginator.page(page)
  File "/Library/Frameworks/Python.framework/Versions/3.10/lib/python3.10/site-packages/django/core/paginator.py", line 75, in page
    number = self.validate_number(number)
  File "/Library/Frameworks/Python.framework/Versions/3.10/lib/python3.10/site-packages/django/core/paginator.py", line 50, in validate_number
    raise PageNotAnInteger(_("That page number is not an integer"))
django.core.paginator.PageNotAnInteger: That page number is not an integer
"GET /api/v1/inventory/inventory/products/ HTTP/1.1" 500 19331
test_path/bar_codes/base/white.png /bar_codes/base/out/out.png
test_path/bar_codes/base/white.png /bar_codes/base/out/out.png
Internal Server Error: /api/v1/inventory/inventory/products/
Traceback (most recent call last):
  File "/Library/Frameworks/Python.framework/Versions/3.10/lib/python3.10/site-packages/django/core/paginator.py", line 48, in validate_number
    number = int(number)
TypeError: int() argument must be a string, a bytes-like object or a real number, not 'NoneType'

During handling of the above exception, another exception occurred:

Traceback (most recent call last):
  File "/Library/Frameworks/Python.framework/Versions/3.10/lib/python3.10/site-packages/django/core/handlers/exception.py", line 55, in inner
    response = get_response(request)
  File "/Library/Frameworks/Python.framework/Versions/3.10/lib/python3.10/site-packages/django/core/handlers/base.py", line 197, in _get_response
    response = wrapped_callback(request, *callback_args, **callback_kwargs)
  File "/Library/Frameworks/Python.framework/Versions/3.10/lib/python3.10/site-packages/django/views/decorators/csrf.py", line 54, in wrapped_view
    return view_func(*args, **kwargs)
  File "/Library/Frameworks/Python.framework/Versions/3.10/lib/python3.10/site-packages/rest_framework/viewsets.py", line 125, in view
    return self.dispatch(request, *args, **kwargs)
  File "/Library/Frameworks/Python.framework/Versions/3.10/lib/python3.10/site-packages/rest_framework/views.py", line 509, in dispatch
    response = self.handle_exception(exc)
  File "/Library/Frameworks/Python.framework/Versions/3.10/lib/python3.10/site-packages/rest_framework/views.py", line 469, in handle_exception
    self.raise_uncaught_exception(exc)
  File "/Library/Frameworks/Python.framework/Versions/3.10/lib/python3.10/site-packages/rest_framework/views.py", line 480, in raise_uncaught_exception
    raise exc
  File "/Library/Frameworks/Python.framework/Versions/3.10/lib/python3.10/site-packages/rest_framework/views.py", line 506, in dispatch
    response = handler(request, *args, **kwargs)
  File "/Library/Frameworks/Python.framework/Versions/3.10/lib/python3.10/site-packages/rest_framework/mixins.py", line 40, in list
    page = self.paginate_queryset(queryset)
  File "/Users/macmini/Machine Learning/kaarujbe/kaaruj/inventory/api/inventory/views.py", line 146, in paginate_queryset
    paginated_queryset = paginator.page(page)
  File "/Library/Frameworks/Python.framework/Versions/3.10/lib/python3.10/site-packages/django/core/paginator.py", line 75, in page
    number = self.validate_number(number)
  File "/Library/Frameworks/Python.framework/Versions/3.10/lib/python3.10/site-packages/django/core/paginator.py", line 50, in validate_number
    raise PageNotAnInteger(_("That page number is not an integer"))
django.core.paginator.PageNotAnInteger: That page number is not an integer
"GET /api/v1/inventory/inventory/products/ HTTP/1.1" 500 19331
Internal Server Error: /api/v1/inventory/inventory/products/
Traceback (most recent call last):
  File "/Library/Frameworks/Python.framework/Versions/3.10/lib/python3.10/site-packages/django/core/paginator.py", line 48, in validate_number
    number = int(number)
TypeError: int() argument must be a string, a bytes-like object or a real number, not 'NoneType'

During handling of the above exception, another exception occurred:

Traceback (most recent call last):
  File "/Library/Frameworks/Python.framework/Versions/3.10/lib/python3.10/site-packages/django/core/handlers/exception.py", line 55, in inner
    response = get_response(request)
  File "/Library/Frameworks/Python.framework/Versions/3.10/lib/python3.10/site-packages/django/core/handlers/base.py", line 197, in _get_response
    response = wrapped_callback(request, *callback_args, **callback_kwargs)
  File "/Library/Frameworks/Python.framework/Versions/3.10/lib/python3.10/site-packages/django/views/decorators/csrf.py", line 54, in wrapped_view
    return view_func(*args, **kwargs)
  File "/Library/Frameworks/Python.framework/Versions/3.10/lib/python3.10/site-packages/rest_framework/viewsets.py", line 125, in view
    return self.dispatch(request, *args, **kwargs)
  File "/Library/Frameworks/Python.framework/Versions/3.10/lib/python3.10/site-packages/rest_framework/views.py", line 509, in dispatch
    response = self.handle_exception(exc)
  File "/Library/Frameworks/Python.framework/Versions/3.10/lib/python3.10/site-packages/rest_framework/views.py", line 469, in handle_exception
    self.raise_uncaught_exception(exc)
  File "/Library/Frameworks/Python.framework/Versions/3.10/lib/python3.10/site-packages/rest_framework/views.py", line 480, in raise_uncaught_exception
    raise exc
  File "/Library/Frameworks/Python.framework/Versions/3.10/lib/python3.10/site-packages/rest_framework/views.py", line 506, in dispatch
    response = handler(request, *args, **kwargs)
  File "/Library/Frameworks/Python.framework/Versions/3.10/lib/python3.10/site-packages/rest_framework/mixins.py", line 40, in list
    page = self.paginate_queryset(queryset)
  File "/Users/macmini/Machine Learning/kaarujbe/kaaruj/inventory/api/inventory/views.py", line 146, in paginate_queryset
    paginated_queryset = paginator.page(page)
  File "/Library/Frameworks/Python.framework/Versions/3.10/lib/python3.10/site-packages/django/core/paginator.py", line 75, in page
    number = self.validate_number(number)
  File "/Library/Frameworks/Python.framework/Versions/3.10/lib/python3.10/site-packages/django/core/paginator.py", line 50, in validate_number
    raise PageNotAnInteger(_("That page number is not an integer"))
django.core.paginator.PageNotAnInteger: That page number is not an integer
"GET /api/v1/inventory/inventory/products/ HTTP/1.1" 500 19331
test_path/bar_codes/base/white.png /bar_codes/base/out/out.png
test_path/bar_codes/base/white.png /bar_codes/base/out/out.png
test_path/bar_codes/base/white.png /bar_codes/base/out/out.png
Internal Server Error: /api/v1/inventory/inventory/products/
Traceback (most recent call last):
  File "/Library/Frameworks/Python.framework/Versions/3.10/lib/python3.10/site-packages/django/core/handlers/exception.py", line 55, in inner
    response = get_response(request)
  File "/Library/Frameworks/Python.framework/Versions/3.10/lib/python3.10/site-packages/django/core/handlers/base.py", line 197, in _get_response
    response = wrapped_callback(request, *callback_args, **callback_kwargs)
  File "/Library/Frameworks/Python.framework/Versions/3.10/lib/python3.10/site-packages/django/views/decorators/csrf.py", line 54, in wrapped_view
    return view_func(*args, **kwargs)
  File "/Library/Frameworks/Python.framework/Versions/3.10/lib/python3.10/site-packages/rest_framework/viewsets.py", line 125, in view
    return self.dispatch(request, *args, **kwargs)
  File "/Library/Frameworks/Python.framework/Versions/3.10/lib/python3.10/site-packages/rest_framework/views.py", line 509, in dispatch
    response = self.handle_exception(exc)
  File "/Library/Frameworks/Python.framework/Versions/3.10/lib/python3.10/site-packages/rest_framework/views.py", line 469, in handle_exception
    self.raise_uncaught_exception(exc)
  File "/Library/Frameworks/Python.framework/Versions/3.10/lib/python3.10/site-packages/rest_framework/views.py", line 480, in raise_uncaught_exception
    raise exc
  File "/Library/Frameworks/Python.framework/Versions/3.10/lib/python3.10/site-packages/rest_framework/views.py", line 506, in dispatch
    response = handler(request, *args, **kwargs)
  File "/Library/Frameworks/Python.framework/Versions/3.10/lib/python3.10/site-packages/rest_framework/mixins.py", line 43, in list
    return self.get_paginated_response(serializer.data)
  File "/Library/Frameworks/Python.framework/Versions/3.10/lib/python3.10/site-packages/rest_framework/generics.py", line 178, in get_paginated_response
    return self.paginator.get_paginated_response(data)
  File "/Library/Frameworks/Python.framework/Versions/3.10/lib/python3.10/site-packages/rest_framework/pagination.py", line 226, in get_paginated_response
    ('count', self.page.paginator.count),
AttributeError: 'CustomPageNumberPagination' object has no attribute 'page'
"GET /api/v1/inventory/inventory/products/ HTTP/1.1" 500 18916
test_path/bar_codes/base/white.png /bar_codes/base/out/out.png
test_path/bar_codes/base/white.png /bar_codes/base/out/out.png
test_path/bar_codes/base/white.png /bar_codes/base/out/out.png
test_path/bar_codes/base/white.png /bar_codes/base/out/out.png
Internal Server Error: /api/v1/inventory/inventory/products/
Traceback (most recent call last):
  File "/Library/Frameworks/Python.framework/Versions/3.10/lib/python3.10/site-packages/django/core/handlers/exception.py", line 55, in inner
    response = get_response(request)
  File "/Library/Frameworks/Python.framework/Versions/3.10/lib/python3.10/site-packages/django/core/handlers/base.py", line 197, in _get_response
    response = wrapped_callback(request, *callback_args, **callback_kwargs)
  File "/Library/Frameworks/Python.framework/Versions/3.10/lib/python3.10/site-packages/django/views/decorators/csrf.py", line 54, in wrapped_view
    return view_func(*args, **kwargs)
  File "/Library/Frameworks/Python.framework/Versions/3.10/lib/python3.10/site-packages/rest_framework/viewsets.py", line 125, in view
    return self.dispatch(request, *args, **kwargs)
  File "/Library/Frameworks/Python.framework/Versions/3.10/lib/python3.10/site-packages/rest_framework/views.py", line 509, in dispatch
    response = self.handle_exception(exc)
  File "/Library/Frameworks/Python.framework/Versions/3.10/lib/python3.10/site-packages/rest_framework/views.py", line 469, in handle_exception
    self.raise_uncaught_exception(exc)
  File "/Library/Frameworks/Python.framework/Versions/3.10/lib/python3.10/site-packages/rest_framework/views.py", line 480, in raise_uncaught_exception
    raise exc
  File "/Library/Frameworks/Python.framework/Versions/3.10/lib/python3.10/site-packages/rest_framework/views.py", line 506, in dispatch
    response = handler(request, *args, **kwargs)
  File "/Users/macmini/Machine Learning/kaarujbe/kaaruj/inventory/api/inventory/views.py", line 160, in list
    paginated_queryset = self.get_paginated_queryset(shuffled_queryset, page)
  File "/Users/macmini/Machine Learning/kaarujbe/kaaruj/inventory/api/inventory/views.py", line 147, in get_paginated_queryset
    paginator = Paginator(queryset, self.paginator.page_size)
AttributeError: 'LimitOffsetPagination' object has no attribute 'page_size'
"GET /api/v1/inventory/inventory/products/ HTTP/1.1" 500 18699
Internal Server Error: /api/v1/inventory/inventory/products/
Traceback (most recent call last):
  File "/Library/Frameworks/Python.framework/Versions/3.10/lib/python3.10/site-packages/django/core/handlers/exception.py", line 55, in inner
    response = get_response(request)
  File "/Library/Frameworks/Python.framework/Versions/3.10/lib/python3.10/site-packages/django/core/handlers/base.py", line 197, in _get_response
    response = wrapped_callback(request, *callback_args, **callback_kwargs)
  File "/Library/Frameworks/Python.framework/Versions/3.10/lib/python3.10/site-packages/django/views/decorators/csrf.py", line 54, in wrapped_view
    return view_func(*args, **kwargs)
  File "/Library/Frameworks/Python.framework/Versions/3.10/lib/python3.10/site-packages/rest_framework/viewsets.py", line 125, in view
    return self.dispatch(request, *args, **kwargs)
  File "/Library/Frameworks/Python.framework/Versions/3.10/lib/python3.10/site-packages/rest_framework/views.py", line 509, in dispatch
    response = self.handle_exception(exc)
  File "/Library/Frameworks/Python.framework/Versions/3.10/lib/python3.10/site-packages/rest_framework/views.py", line 469, in handle_exception
    self.raise_uncaught_exception(exc)
  File "/Library/Frameworks/Python.framework/Versions/3.10/lib/python3.10/site-packages/rest_framework/views.py", line 480, in raise_uncaught_exception
    raise exc
  File "/Library/Frameworks/Python.framework/Versions/3.10/lib/python3.10/site-packages/rest_framework/views.py", line 506, in dispatch
    response = handler(request, *args, **kwargs)
  File "/Users/macmini/Machine Learning/kaarujbe/kaaruj/inventory/api/inventory/views.py", line 160, in list
    paginated_queryset = self.get_paginated_queryset(shuffled_queryset, page)
  File "/Users/macmini/Machine Learning/kaarujbe/kaaruj/inventory/api/inventory/views.py", line 147, in get_paginated_queryset
    paginator = Paginator(queryset, self.paginator.page_size)
AttributeError: 'LimitOffsetPagination' object has no attribute 'page_size'
"GET /api/v1/inventory/inventory/products/ HTTP/1.1" 500 18699
Internal Server Error: /api/v1/inventory/inventory/products/
Traceback (most recent call last):
  File "/Library/Frameworks/Python.framework/Versions/3.10/lib/python3.10/site-packages/django/core/handlers/exception.py", line 55, in inner
    response = get_response(request)
  File "/Library/Frameworks/Python.framework/Versions/3.10/lib/python3.10/site-packages/django/core/handlers/base.py", line 197, in _get_response
    response = wrapped_callback(request, *callback_args, **callback_kwargs)
  File "/Library/Frameworks/Python.framework/Versions/3.10/lib/python3.10/site-packages/django/views/decorators/csrf.py", line 54, in wrapped_view
    return view_func(*args, **kwargs)
  File "/Library/Frameworks/Python.framework/Versions/3.10/lib/python3.10/site-packages/rest_framework/viewsets.py", line 125, in view
    return self.dispatch(request, *args, **kwargs)
  File "/Library/Frameworks/Python.framework/Versions/3.10/lib/python3.10/site-packages/rest_framework/views.py", line 509, in dispatch
    response = self.handle_exception(exc)
  File "/Library/Frameworks/Python.framework/Versions/3.10/lib/python3.10/site-packages/rest_framework/views.py", line 469, in handle_exception
    self.raise_uncaught_exception(exc)
  File "/Library/Frameworks/Python.framework/Versions/3.10/lib/python3.10/site-packages/rest_framework/views.py", line 480, in raise_uncaught_exception
    raise exc
  File "/Library/Frameworks/Python.framework/Versions/3.10/lib/python3.10/site-packages/rest_framework/views.py", line 506, in dispatch
    response = handler(request, *args, **kwargs)
  File "/Users/macmini/Machine Learning/kaarujbe/kaaruj/inventory/api/inventory/views.py", line 160, in list
    paginated_queryset = self.get_paginated_queryset(shuffled_queryset, page)
  File "/Users/macmini/Machine Learning/kaarujbe/kaaruj/inventory/api/inventory/views.py", line 147, in get_paginated_queryset
    paginator = Paginator(queryset, self.paginator.page_size)
AttributeError: 'LimitOffsetPagination' object has no attribute 'page_size'
"GET /api/v1/inventory/inventory/products/ HTTP/1.1" 500 18699
Internal Server Error: /api/v1/inventory/inventory/products/
Traceback (most recent call last):
  File "/Library/Frameworks/Python.framework/Versions/3.10/lib/python3.10/site-packages/django/core/handlers/exception.py", line 55, in inner
    response = get_response(request)
  File "/Library/Frameworks/Python.framework/Versions/3.10/lib/python3.10/site-packages/django/core/handlers/base.py", line 197, in _get_response
    response = wrapped_callback(request, *callback_args, **callback_kwargs)
  File "/Library/Frameworks/Python.framework/Versions/3.10/lib/python3.10/site-packages/django/views/decorators/csrf.py", line 54, in wrapped_view
    return view_func(*args, **kwargs)
  File "/Library/Frameworks/Python.framework/Versions/3.10/lib/python3.10/site-packages/rest_framework/viewsets.py", line 125, in view
    return self.dispatch(request, *args, **kwargs)
  File "/Library/Frameworks/Python.framework/Versions/3.10/lib/python3.10/site-packages/rest_framework/views.py", line 509, in dispatch
    response = self.handle_exception(exc)
  File "/Library/Frameworks/Python.framework/Versions/3.10/lib/python3.10/site-packages/rest_framework/views.py", line 469, in handle_exception
    self.raise_uncaught_exception(exc)
  File "/Library/Frameworks/Python.framework/Versions/3.10/lib/python3.10/site-packages/rest_framework/views.py", line 480, in raise_uncaught_exception
    raise exc
  File "/Library/Frameworks/Python.framework/Versions/3.10/lib/python3.10/site-packages/rest_framework/views.py", line 506, in dispatch
    response = handler(request, *args, **kwargs)
  File "/Users/macmini/Machine Learning/kaarujbe/kaaruj/inventory/api/inventory/views.py", line 160, in list
    paginated_queryset = self.get_paginated_queryset(shuffled_queryset, page)
  File "/Users/macmini/Machine Learning/kaarujbe/kaaruj/inventory/api/inventory/views.py", line 147, in get_paginated_queryset
    paginator = Paginator(queryset, self.paginator.page_size)
AttributeError: 'LimitOffsetPagination' object has no attribute 'page_size'
"GET /api/v1/inventory/inventory/products/ HTTP/1.1" 500 18699
Internal Server Error: /api/v1/inventory/inventory/products/
Traceback (most recent call last):
  File "/Library/Frameworks/Python.framework/Versions/3.10/lib/python3.10/site-packages/django/core/handlers/exception.py", line 55, in inner
    response = get_response(request)
  File "/Library/Frameworks/Python.framework/Versions/3.10/lib/python3.10/site-packages/django/core/handlers/base.py", line 197, in _get_response
    response = wrapped_callback(request, *callback_args, **callback_kwargs)
  File "/Library/Frameworks/Python.framework/Versions/3.10/lib/python3.10/site-packages/django/views/decorators/csrf.py", line 54, in wrapped_view
    return view_func(*args, **kwargs)
  File "/Library/Frameworks/Python.framework/Versions/3.10/lib/python3.10/site-packages/rest_framework/viewsets.py", line 125, in view
    return self.dispatch(request, *args, **kwargs)
  File "/Library/Frameworks/Python.framework/Versions/3.10/lib/python3.10/site-packages/rest_framework/views.py", line 509, in dispatch
    response = self.handle_exception(exc)
  File "/Library/Frameworks/Python.framework/Versions/3.10/lib/python3.10/site-packages/rest_framework/views.py", line 469, in handle_exception
    self.raise_uncaught_exception(exc)
  File "/Library/Frameworks/Python.framework/Versions/3.10/lib/python3.10/site-packages/rest_framework/views.py", line 480, in raise_uncaught_exception
    raise exc
  File "/Library/Frameworks/Python.framework/Versions/3.10/lib/python3.10/site-packages/rest_framework/views.py", line 506, in dispatch
    response = handler(request, *args, **kwargs)
  File "/Users/macmini/Machine Learning/kaarujbe/kaaruj/inventory/api/inventory/views.py", line 160, in list
    paginated_queryset = self.get_paginated_queryset(shuffled_queryset, page)
  File "/Users/macmini/Machine Learning/kaarujbe/kaaruj/inventory/api/inventory/views.py", line 147, in get_paginated_queryset
    paginator = Paginator(queryset, self.paginator.page_size)
AttributeError: 'LimitOffsetPagination' object has no attribute 'page_size'
"GET /api/v1/inventory/inventory/products/ HTTP/1.1" 500 18699
test_path/bar_codes/base/white.png /bar_codes/base/out/out.png
test_path/bar_codes/base/white.png /bar_codes/base/out/out.png
test_path/bar_codes/base/white.png /bar_codes/base/out/out.png
test_path/bar_codes/base/white.png /bar_codes/base/out/out.png
test_path/bar_codes/base/white.png /bar_codes/base/out/out.png
test_path/bar_codes/base/white.png /bar_codes/base/out/out.png
test_path/bar_codes/base/white.png /bar_codes/base/out/out.png
test_path/bar_codes/base/white.png /bar_codes/base/out/out.png
Error in generate_product_barcode:  
 Traceback (most recent call last):
  File "/Users/macmini/Machine Learning/kaarujbe/kaaruj/utility/utils/bar_image_utils.py", line 59, in add_images_and_text
    modified_image = insert_text(image_path, text, output_path, size=30, add_x=0, position_y=2,color='white')
  File "/Users/macmini/Machine Learning/kaarujbe/kaaruj/utility/utils/bar_image_utils.py", line 6, in insert_text
    image = Image.open(image_path)
  File "/Library/Frameworks/Python.framework/Versions/3.10/lib/python3.10/site-packages/PIL/Image.py", line 3236, in open
    fp = builtins.open(filename, "rb")
FileNotFoundError: [Errno 2] No such file or directory: '/bar_codes/base/white.png'

Error in generate_product_barcode:  
 Traceback (most recent call last):
  File "/Users/macmini/Machine Learning/kaarujbe/kaaruj/utility/utils/bar_image_utils.py", line 59, in add_images_and_text
    modified_image = insert_text(image_path, text, output_path, size=30, add_x=0, position_y=2,color='white')
  File "/Users/macmini/Machine Learning/kaarujbe/kaaruj/utility/utils/bar_image_utils.py", line 6, in insert_text
    image = Image.open(image_path)
  File "/Library/Frameworks/Python.framework/Versions/3.10/lib/python3.10/site-packages/PIL/Image.py", line 3236, in open
    fp = builtins.open(filename, "rb")
FileNotFoundError: [Errno 2] No such file or directory: '/bar_codes/base/white.png'

Error in generate_product_barcode:  
 Traceback (most recent call last):
  File "/Users/macmini/Machine Learning/kaarujbe/kaaruj/utility/utils/bar_image_utils.py", line 59, in add_images_and_text
    modified_image = insert_text(image_path, text, output_path, size=30, add_x=0, position_y=2,color='white')
  File "/Users/macmini/Machine Learning/kaarujbe/kaaruj/utility/utils/bar_image_utils.py", line 6, in insert_text
    image = Image.open(image_path)
  File "/Library/Frameworks/Python.framework/Versions/3.10/lib/python3.10/site-packages/PIL/Image.py", line 3236, in open
    fp = builtins.open(filename, "rb")
FileNotFoundError: [Errno 2] No such file or directory: '/bar_codes/base/white.png'

Error in generate_product_barcode:  
 Traceback (most recent call last):
  File "/Users/macmini/Machine Learning/kaarujbe/kaaruj/utility/utils/bar_image_utils.py", line 59, in add_images_and_text
    modified_image = insert_text(image_path, text, output_path, size=30, add_x=0, position_y=2,color='white')
  File "/Users/macmini/Machine Learning/kaarujbe/kaaruj/utility/utils/bar_image_utils.py", line 6, in insert_text
    image = Image.open(image_path)
  File "/Library/Frameworks/Python.framework/Versions/3.10/lib/python3.10/site-packages/PIL/Image.py", line 3236, in open
    fp = builtins.open(filename, "rb")
FileNotFoundError: [Errno 2] No such file or directory: '/bar_codes/base/white.png'

Error in generate_product_barcode:  
 Traceback (most recent call last):
  File "/Users/macmini/Machine Learning/kaarujbe/kaaruj/utility/utils/bar_image_utils.py", line 59, in add_images_and_text
    modified_image = insert_text(image_path, text, output_path, size=30, add_x=0, position_y=2,color='white')
  File "/Users/macmini/Machine Learning/kaarujbe/kaaruj/utility/utils/bar_image_utils.py", line 6, in insert_text
    image = Image.open(image_path)
  File "/Library/Frameworks/Python.framework/Versions/3.10/lib/python3.10/site-packages/PIL/Image.py", line 3236, in open
    fp = builtins.open(filename, "rb")
FileNotFoundError: [Errno 2] No such file or directory: '/bar_codes/base/white.png'

test_path/bar_codes/base/white.png /bar_codes/base/out/out.png
test_path/bar_codes/base/white.png /bar_codes/base/out/out.png
test_path/bar_codes/base/white.png /bar_codes/base/out/out.png
test_path/bar_codes/base/white.png /bar_codes/base/out/out.png
test_path/bar_codes/base/white.png /bar_codes/base/out/out.png
test_path/bar_codes/base/white.png /bar_codes/base/out/out.png
test_path/bar_codes/base/white.png /bar_codes/base/out/out.png
test_path/bar_codes/base/white.png /bar_codes/base/out/out.png
test_path/bar_codes/base/white.png /bar_codes/base/out/out.png
Internal Server Error: /api/v1/inventory/inventory/products/
Traceback (most recent call last):
  File "/Library/Frameworks/Python.framework/Versions/3.10/lib/python3.10/site-packages/django/core/handlers/exception.py", line 55, in inner
    response = get_response(request)
  File "/Library/Frameworks/Python.framework/Versions/3.10/lib/python3.10/site-packages/django/core/handlers/base.py", line 197, in _get_response
    response = wrapped_callback(request, *callback_args, **callback_kwargs)
  File "/Library/Frameworks/Python.framework/Versions/3.10/lib/python3.10/site-packages/django/views/decorators/csrf.py", line 54, in wrapped_view
    return view_func(*args, **kwargs)
  File "/Library/Frameworks/Python.framework/Versions/3.10/lib/python3.10/site-packages/rest_framework/viewsets.py", line 125, in view
    return self.dispatch(request, *args, **kwargs)
  File "/Library/Frameworks/Python.framework/Versions/3.10/lib/python3.10/site-packages/rest_framework/views.py", line 509, in dispatch
    response = self.handle_exception(exc)
  File "/Library/Frameworks/Python.framework/Versions/3.10/lib/python3.10/site-packages/rest_framework/views.py", line 469, in handle_exception
    self.raise_uncaught_exception(exc)
  File "/Library/Frameworks/Python.framework/Versions/3.10/lib/python3.10/site-packages/rest_framework/views.py", line 480, in raise_uncaught_exception
    raise exc
  File "/Library/Frameworks/Python.framework/Versions/3.10/lib/python3.10/site-packages/rest_framework/views.py", line 506, in dispatch
    response = handler(request, *args, **kwargs)
  File "/Users/macmini/Machine Learning/kaarujbe/kaaruj/inventory/api/inventory/views.py", line 153, in list
    random.shuffle(paginator)
  File "/Library/Frameworks/Python.framework/Versions/3.10/lib/python3.10/random.py", line 391, in shuffle
    for i in reversed(range(1, len(x))):
TypeError: object of type 'RandomPageNumberPagination' has no len()
"GET /api/v1/inventory/inventory/products/?page=1 HTTP/1.1" 500 97551
Internal Server Error: /api/v1/inventory/inventory/products/
Traceback (most recent call last):
  File "/Library/Frameworks/Python.framework/Versions/3.10/lib/python3.10/site-packages/django/core/handlers/exception.py", line 55, in inner
    response = get_response(request)
  File "/Library/Frameworks/Python.framework/Versions/3.10/lib/python3.10/site-packages/django/core/handlers/base.py", line 197, in _get_response
    response = wrapped_callback(request, *callback_args, **callback_kwargs)
  File "/Library/Frameworks/Python.framework/Versions/3.10/lib/python3.10/site-packages/django/views/decorators/csrf.py", line 54, in wrapped_view
    return view_func(*args, **kwargs)
  File "/Library/Frameworks/Python.framework/Versions/3.10/lib/python3.10/site-packages/rest_framework/viewsets.py", line 125, in view
    return self.dispatch(request, *args, **kwargs)
  File "/Library/Frameworks/Python.framework/Versions/3.10/lib/python3.10/site-packages/rest_framework/views.py", line 509, in dispatch
    response = self.handle_exception(exc)
  File "/Library/Frameworks/Python.framework/Versions/3.10/lib/python3.10/site-packages/rest_framework/views.py", line 469, in handle_exception
    self.raise_uncaught_exception(exc)
  File "/Library/Frameworks/Python.framework/Versions/3.10/lib/python3.10/site-packages/rest_framework/views.py", line 480, in raise_uncaught_exception
    raise exc
  File "/Library/Frameworks/Python.framework/Versions/3.10/lib/python3.10/site-packages/rest_framework/views.py", line 506, in dispatch
    response = handler(request, *args, **kwargs)
  File "/Users/macmini/Machine Learning/kaarujbe/kaaruj/inventory/api/inventory/views.py", line 153, in list
    random.shuffle(paginator)
  File "/Library/Frameworks/Python.framework/Versions/3.10/lib/python3.10/random.py", line 391, in shuffle
    for i in reversed(range(1, len(x))):
TypeError: object of type 'RandomPageNumberPagination' has no len()
"GET /api/v1/inventory/inventory/products/?page=1 HTTP/1.1" 500 97551
Internal Server Error: /api/v1/inventory/inventory/products/
Traceback (most recent call last):
  File "/Library/Frameworks/Python.framework/Versions/3.10/lib/python3.10/site-packages/django/core/handlers/exception.py", line 55, in inner
    response = get_response(request)
  File "/Library/Frameworks/Python.framework/Versions/3.10/lib/python3.10/site-packages/django/core/handlers/base.py", line 197, in _get_response
    response = wrapped_callback(request, *callback_args, **callback_kwargs)
  File "/Library/Frameworks/Python.framework/Versions/3.10/lib/python3.10/site-packages/django/views/decorators/csrf.py", line 54, in wrapped_view
    return view_func(*args, **kwargs)
  File "/Library/Frameworks/Python.framework/Versions/3.10/lib/python3.10/site-packages/rest_framework/viewsets.py", line 125, in view
    return self.dispatch(request, *args, **kwargs)
  File "/Library/Frameworks/Python.framework/Versions/3.10/lib/python3.10/site-packages/rest_framework/views.py", line 509, in dispatch
    response = self.handle_exception(exc)
  File "/Library/Frameworks/Python.framework/Versions/3.10/lib/python3.10/site-packages/rest_framework/views.py", line 469, in handle_exception
    self.raise_uncaught_exception(exc)
  File "/Library/Frameworks/Python.framework/Versions/3.10/lib/python3.10/site-packages/rest_framework/views.py", line 480, in raise_uncaught_exception
    raise exc
  File "/Library/Frameworks/Python.framework/Versions/3.10/lib/python3.10/site-packages/rest_framework/views.py", line 506, in dispatch
    response = handler(request, *args, **kwargs)
  File "/Users/macmini/Machine Learning/kaarujbe/kaaruj/inventory/api/inventory/views.py", line 153, in list
    random.shuffle(paginator)
  File "/Library/Frameworks/Python.framework/Versions/3.10/lib/python3.10/random.py", line 391, in shuffle
    for i in reversed(range(1, len(x))):
TypeError: object of type 'RandomPageNumberPagination' has no len()
"GET /api/v1/inventory/inventory/products/?page=1 HTTP/1.1" 500 97551
test_path/bar_codes/base/white.png /bar_codes/base/out/out.png
test_path/bar_codes/base/white.png /bar_codes/base/out/out.png
test_path/bar_codes/base/white.png /bar_codes/base/out/out.png
test_path/bar_codes/base/white.png /bar_codes/base/out/out.png
test_path/bar_codes/base/white.png /bar_codes/base/out/out.png
test_path/bar_codes/base/white.png /bar_codes/base/out/out.png
test_path/bar_codes/base/white.png /bar_codes/base/out/out.png
test_path/bar_codes/base/white.png /bar_codes/base/out/out.png
test_path/bar_codes/base/white.png /bar_codes/base/out/out.png
test_path/bar_codes/base/white.png /bar_codes/base/out/out.png
test_path/bar_codes/base/white.png /bar_codes/base/out/out.png
test_path/bar_codes/base/white.png /bar_codes/base/out/out.png
test_path/bar_codes/base/white.png /bar_codes/base/out/out.png
test_path/bar_codes/base/white.png /bar_codes/base/out/out.png
test_path/bar_codes/base/white.png /bar_codes/base/out/out.png
test_path/bar_codes/base/white.png /bar_codes/base/out/out.png
test_path/bar_codes/base/white.png /bar_codes/base/out/out.png
test_path/bar_codes/base/white.png /bar_codes/base/out/out.png
test_path/bar_codes/base/white.png /bar_codes/base/out/out.png
test_path/bar_codes/base/white.png /bar_codes/base/out/out.png
test_path/bar_codes/base/white.png /bar_codes/base/out/out.png
test_path/bar_codes/base/white.png /bar_codes/base/out/out.png
test_path/bar_codes/base/white.png /bar_codes/base/out/out.png
test_path/bar_codes/base/white.png /bar_codes/base/out/out.png
test_path/bar_codes/base/white.png /bar_codes/base/out/out.png
test_path/bar_codes/base/white.png /bar_codes/base/out/out.png
test_path/bar_codes/base/white.png /bar_codes/base/out/out.png
test_path/bar_codes/base/white.png /bar_codes/base/out/out.png
test_path/bar_codes/base/white.png /bar_codes/base/out/out.png
test_path/bar_codes/base/white.png /bar_codes/base/out/out.png
test_path/bar_codes/base/white.png /bar_codes/base/out/out.png
test_path/bar_codes/base/white.png /bar_codes/base/out/out.png
test_path/bar_codes/base/white.png /bar_codes/base/out/out.png
test_path/bar_codes/base/white.png /bar_codes/base/out/out.png
test_path/bar_codes/base/white.png /bar_codes/base/out/out.png
test_path/bar_codes/base/white.png /bar_codes/base/out/out.png
test_path/bar_codes/base/white.png /bar_codes/base/out/out.png
test_path/bar_codes/base/white.png /bar_codes/base/out/out.png
test_path/bar_codes/base/white.png /bar_codes/base/out/out.png
test_path/bar_codes/base/white.png /bar_codes/base/out/out.png
Internal Server Error: /api/v1/inventory/inventory/products/
Traceback (most recent call last):
  File "/Library/Frameworks/Python.framework/Versions/3.10/lib/python3.10/site-packages/django/core/handlers/exception.py", line 55, in inner
    response = get_response(request)
  File "/Library/Frameworks/Python.framework/Versions/3.10/lib/python3.10/site-packages/django/core/handlers/base.py", line 197, in _get_response
    response = wrapped_callback(request, *callback_args, **callback_kwargs)
  File "/Library/Frameworks/Python.framework/Versions/3.10/lib/python3.10/site-packages/django/views/decorators/csrf.py", line 54, in wrapped_view
    return view_func(*args, **kwargs)
  File "/Library/Frameworks/Python.framework/Versions/3.10/lib/python3.10/site-packages/rest_framework/viewsets.py", line 125, in view
    return self.dispatch(request, *args, **kwargs)
  File "/Library/Frameworks/Python.framework/Versions/3.10/lib/python3.10/site-packages/rest_framework/views.py", line 509, in dispatch
    response = self.handle_exception(exc)
  File "/Library/Frameworks/Python.framework/Versions/3.10/lib/python3.10/site-packages/rest_framework/views.py", line 469, in handle_exception
    self.raise_uncaught_exception(exc)
  File "/Library/Frameworks/Python.framework/Versions/3.10/lib/python3.10/site-packages/rest_framework/views.py", line 480, in raise_uncaught_exception
    raise exc
  File "/Library/Frameworks/Python.framework/Versions/3.10/lib/python3.10/site-packages/rest_framework/views.py", line 506, in dispatch
    response = handler(request, *args, **kwargs)
  File "/Users/macmini/Machine Learning/kaarujbe/kaaruj/inventory/api/inventory/views.py", line 160, in list
    paginated_queryset = paginator.paginate_queryset(queryset, request).order_by('?')
AttributeError: 'list' object has no attribute 'order_by'
"GET /api/v1/inventory/inventory/products/?page=1 HTTP/1.1" 500 93476
test_path/bar_codes/base/white.png /bar_codes/base/out/out.png
test_path/bar_codes/base/white.png /bar_codes/base/out/out.png
test_path/bar_codes/base/white.png /bar_codes/base/out/out.png
test_path/bar_codes/base/white.png /bar_codes/base/out/out.png
test_path/bar_codes/base/white.png /bar_codes/base/out/out.png
Error in generate_product_barcode:  
 Traceback (most recent call last):
  File "/Users/macmini/Machine Learning/kaarujbe/kaaruj/utility/utils/bar_image_utils.py", line 59, in add_images_and_text
    modified_image = insert_text(image_path, text, output_path, size=30, add_x=0, position_y=2,color='white')
  File "/Users/macmini/Machine Learning/kaarujbe/kaaruj/utility/utils/bar_image_utils.py", line 6, in insert_text
    image = Image.open(image_path)
  File "/Library/Frameworks/Python.framework/Versions/3.10/lib/python3.10/site-packages/PIL/Image.py", line 3236, in open
    fp = builtins.open(filename, "rb")
FileNotFoundError: [Errno 2] No such file or directory: '/bar_codes/base/white.png'

Error in generate_product_barcode:  
 Traceback (most recent call last):
  File "/Users/macmini/Machine Learning/kaarujbe/kaaruj/utility/utils/bar_image_utils.py", line 59, in add_images_and_text
    modified_image = insert_text(image_path, text, output_path, size=30, add_x=0, position_y=2,color='white')
  File "/Users/macmini/Machine Learning/kaarujbe/kaaruj/utility/utils/bar_image_utils.py", line 6, in insert_text
    image = Image.open(image_path)
  File "/Library/Frameworks/Python.framework/Versions/3.10/lib/python3.10/site-packages/PIL/Image.py", line 3236, in open
    fp = builtins.open(filename, "rb")
FileNotFoundError: [Errno 2] No such file or directory: '/bar_codes/base/white.png'

Error in generate_product_barcode:  
 Traceback (most recent call last):
  File "/Users/macmini/Machine Learning/kaarujbe/kaaruj/utility/utils/bar_image_utils.py", line 59, in add_images_and_text
    modified_image = insert_text(image_path, text, output_path, size=30, add_x=0, position_y=2,color='white')
  File "/Users/macmini/Machine Learning/kaarujbe/kaaruj/utility/utils/bar_image_utils.py", line 6, in insert_text
    image = Image.open(image_path)
  File "/Library/Frameworks/Python.framework/Versions/3.10/lib/python3.10/site-packages/PIL/Image.py", line 3236, in open
    fp = builtins.open(filename, "rb")
FileNotFoundError: [Errno 2] No such file or directory: '/bar_codes/base/white.png'

Error in generate_product_barcode:  
 Traceback (most recent call last):
  File "/Users/macmini/Machine Learning/kaarujbe/kaaruj/utility/utils/bar_image_utils.py", line 59, in add_images_and_text
    modified_image = insert_text(image_path, text, output_path, size=30, add_x=0, position_y=2,color='white')
  File "/Users/macmini/Machine Learning/kaarujbe/kaaruj/utility/utils/bar_image_utils.py", line 6, in insert_text
    image = Image.open(image_path)
  File "/Library/Frameworks/Python.framework/Versions/3.10/lib/python3.10/site-packages/PIL/Image.py", line 3236, in open
    fp = builtins.open(filename, "rb")
FileNotFoundError: [Errno 2] No such file or directory: '/bar_codes/base/white.png'

Error in generate_product_barcode:  
 Traceback (most recent call last):
  File "/Users/macmini/Machine Learning/kaarujbe/kaaruj/utility/utils/bar_image_utils.py", line 59, in add_images_and_text
    modified_image = insert_text(image_path, text, output_path, size=30, add_x=0, position_y=2,color='white')
  File "/Users/macmini/Machine Learning/kaarujbe/kaaruj/utility/utils/bar_image_utils.py", line 6, in insert_text
    image = Image.open(image_path)
  File "/Library/Frameworks/Python.framework/Versions/3.10/lib/python3.10/site-packages/PIL/Image.py", line 3236, in open
    fp = builtins.open(filename, "rb")
FileNotFoundError: [Errno 2] No such file or directory: '/bar_codes/base/white.png'

Error in generate_product_barcode:  
 Traceback (most recent call last):
  File "/Users/macmini/Machine Learning/kaarujbe/kaaruj/utility/utils/bar_image_utils.py", line 59, in add_images_and_text
    modified_image = insert_text(image_path, text, output_path, size=30, add_x=0, position_y=2,color='white')
  File "/Users/macmini/Machine Learning/kaarujbe/kaaruj/utility/utils/bar_image_utils.py", line 6, in insert_text
    image = Image.open(image_path)
  File "/Library/Frameworks/Python.framework/Versions/3.10/lib/python3.10/site-packages/PIL/Image.py", line 3236, in open
    fp = builtins.open(filename, "rb")
FileNotFoundError: [Errno 2] No such file or directory: '/bar_codes/base/white.png'

Error in generate_product_barcode:  
 Traceback (most recent call last):
  File "/Users/macmini/Machine Learning/kaarujbe/kaaruj/utility/utils/bar_image_utils.py", line 59, in add_images_and_text
    modified_image = insert_text(image_path, text, output_path, size=30, add_x=0, position_y=2,color='white')
  File "/Users/macmini/Machine Learning/kaarujbe/kaaruj/utility/utils/bar_image_utils.py", line 6, in insert_text
    image = Image.open(image_path)
  File "/Library/Frameworks/Python.framework/Versions/3.10/lib/python3.10/site-packages/PIL/Image.py", line 3236, in open
    fp = builtins.open(filename, "rb")
FileNotFoundError: [Errno 2] No such file or directory: '/bar_codes/base/white.png'

test_path/bar_codes/base/white.png /bar_codes/base/out/out.png
test_path/bar_codes/base/white.png /bar_codes/base/out/out.png
test_path/bar_codes/base/white.png /bar_codes/base/out/out.png
