test_path/bar_codes/base/white.png /bar_codes/base/out/out.png
test_path/bar_codes/base/white.png /bar_codes/base/out/out.png
test_path/bar_codes/base/white.png /bar_codes/base/out/out.png
test_path/bar_codes/base/white.png /bar_codes/base/out/out.png
Internal Server Error: /api/v1/sales/inventory/inventory/notifications
Traceback (most recent call last):
  File "/Library/Frameworks/Python.framework/Versions/3.10/lib/python3.10/site-packages/django/core/handlers/exception.py", line 55, in inner
    response = get_response(request)
  File "/Library/Frameworks/Python.framework/Versions/3.10/lib/python3.10/site-packages/django/core/handlers/base.py", line 197, in _get_response
    response = wrapped_callback(request, *callback_args, **callback_kwargs)
  File "/Library/Frameworks/Python.framework/Versions/3.10/lib/python3.10/site-packages/django/views/decorators/csrf.py", line 54, in wrapped_view
    return view_func(*args, **kwargs)
  File "/Library/Frameworks/Python.framework/Versions/3.10/lib/python3.10/site-packages/django/views/generic/base.py", line 103, in view
    return self.dispatch(request, *args, **kwargs)
  File "/Library/Frameworks/Python.framework/Versions/3.10/lib/python3.10/site-packages/rest_framework/views.py", line 509, in dispatch
    response = self.handle_exception(exc)
  File "/Library/Frameworks/Python.framework/Versions/3.10/lib/python3.10/site-packages/rest_framework/views.py", line 469, in handle_exception
    self.raise_uncaught_exception(exc)
  File "/Library/Frameworks/Python.framework/Versions/3.10/lib/python3.10/site-packages/rest_framework/views.py", line 480, in raise_uncaught_exception
    raise exc
  File "/Library/Frameworks/Python.framework/Versions/3.10/lib/python3.10/site-packages/rest_framework/views.py", line 506, in dispatch
    response = handler(request, *args, **kwargs)
  File "/Users/macmini/Machine Learning/backup12_07/sales/api/inventory/views.py", line 816, in get
    notification = Notification.objects.get(user=user)
  File "/Library/Frameworks/Python.framework/Versions/3.10/lib/python3.10/site-packages/django/db/models/manager.py", line 85, in manager_method
    return getattr(self.get_queryset(), name)(*args, **kwargs)
  File "/Library/Frameworks/Python.framework/Versions/3.10/lib/python3.10/site-packages/django/db/models/query.py", line 650, in get
    raise self.model.DoesNotExist(
sales.models.Notification.DoesNotExist: Notification matching query does not exist.
"GET /api/v1/sales/inventory/inventory/notifications HTTP/1.1" 500 99656
test_path/bar_codes/base/white.png /bar_codes/base/out/out.png
test_path/bar_codes/base/white.png /bar_codes/base/out/out.png
Internal Server Error: /api/v1/sales/inventory/inventory/notifications
Traceback (most recent call last):
  File "/Library/Frameworks/Python.framework/Versions/3.10/lib/python3.10/site-packages/django/core/handlers/exception.py", line 55, in inner
    response = get_response(request)
  File "/Library/Frameworks/Python.framework/Versions/3.10/lib/python3.10/site-packages/django/core/handlers/base.py", line 197, in _get_response
    response = wrapped_callback(request, *callback_args, **callback_kwargs)
  File "/Library/Frameworks/Python.framework/Versions/3.10/lib/python3.10/site-packages/django/views/decorators/csrf.py", line 54, in wrapped_view
    return view_func(*args, **kwargs)
  File "/Library/Frameworks/Python.framework/Versions/3.10/lib/python3.10/site-packages/django/views/generic/base.py", line 103, in view
    return self.dispatch(request, *args, **kwargs)
  File "/Library/Frameworks/Python.framework/Versions/3.10/lib/python3.10/site-packages/rest_framework/views.py", line 509, in dispatch
    response = self.handle_exception(exc)
  File "/Library/Frameworks/Python.framework/Versions/3.10/lib/python3.10/site-packages/rest_framework/views.py", line 469, in handle_exception
    self.raise_uncaught_exception(exc)
  File "/Library/Frameworks/Python.framework/Versions/3.10/lib/python3.10/site-packages/rest_framework/views.py", line 480, in raise_uncaught_exception
    raise exc
  File "/Library/Frameworks/Python.framework/Versions/3.10/lib/python3.10/site-packages/rest_framework/views.py", line 506, in dispatch
    response = handler(request, *args, **kwargs)
  File "/Users/macmini/Machine Learning/backup12_07/sales/api/inventory/views.py", line 816, in get
    notification = Notification.objects.get(user=user)
  File "/Library/Frameworks/Python.framework/Versions/3.10/lib/python3.10/site-packages/django/db/models/manager.py", line 85, in manager_method
    return getattr(self.get_queryset(), name)(*args, **kwargs)
  File "/Library/Frameworks/Python.framework/Versions/3.10/lib/python3.10/site-packages/django/db/models/query.py", line 650, in get
    raise self.model.DoesNotExist(
sales.models.Notification.DoesNotExist: Notification matching query does not exist.
"GET /api/v1/sales/inventory/inventory/notifications HTTP/1.1" 500 99656
test_path/bar_codes/base/white.png /bar_codes/base/out/out.png
Internal Server Error: /api/v1/sales/inventory/inventory/notifications
Traceback (most recent call last):
  File "/Library/Frameworks/Python.framework/Versions/3.10/lib/python3.10/site-packages/django/core/handlers/exception.py", line 55, in inner
    response = get_response(request)
  File "/Library/Frameworks/Python.framework/Versions/3.10/lib/python3.10/site-packages/django/core/handlers/base.py", line 197, in _get_response
    response = wrapped_callback(request, *callback_args, **callback_kwargs)
  File "/Library/Frameworks/Python.framework/Versions/3.10/lib/python3.10/site-packages/django/views/decorators/csrf.py", line 54, in wrapped_view
    return view_func(*args, **kwargs)
  File "/Library/Frameworks/Python.framework/Versions/3.10/lib/python3.10/site-packages/django/views/generic/base.py", line 103, in view
    return self.dispatch(request, *args, **kwargs)
  File "/Library/Frameworks/Python.framework/Versions/3.10/lib/python3.10/site-packages/rest_framework/views.py", line 509, in dispatch
    response = self.handle_exception(exc)
  File "/Library/Frameworks/Python.framework/Versions/3.10/lib/python3.10/site-packages/rest_framework/views.py", line 469, in handle_exception
    self.raise_uncaught_exception(exc)
  File "/Library/Frameworks/Python.framework/Versions/3.10/lib/python3.10/site-packages/rest_framework/views.py", line 480, in raise_uncaught_exception
    raise exc
  File "/Library/Frameworks/Python.framework/Versions/3.10/lib/python3.10/site-packages/rest_framework/views.py", line 506, in dispatch
    response = handler(request, *args, **kwargs)
  File "/Users/macmini/Machine Learning/backup12_07/sales/api/inventory/views.py", line 816, in get
    notification = Notification.objects.get(user=user)
  File "/Library/Frameworks/Python.framework/Versions/3.10/lib/python3.10/site-packages/django/db/models/manager.py", line 85, in manager_method
    return getattr(self.get_queryset(), name)(*args, **kwargs)
  File "/Library/Frameworks/Python.framework/Versions/3.10/lib/python3.10/site-packages/django/db/models/query.py", line 650, in get
    raise self.model.DoesNotExist(
sales.models.Notification.DoesNotExist: Notification matching query does not exist.
"GET /api/v1/sales/inventory/inventory/notifications HTTP/1.1" 500 99656
test_path/bar_codes/base/white.png /bar_codes/base/out/out.png
test_path/bar_codes/base/white.png /bar_codes/base/out/out.png
Internal Server Error: /api/v1/sales/inventory/inventory/notifications
Traceback (most recent call last):
  File "/Library/Frameworks/Python.framework/Versions/3.10/lib/python3.10/site-packages/django/core/handlers/exception.py", line 55, in inner
    response = get_response(request)
  File "/Library/Frameworks/Python.framework/Versions/3.10/lib/python3.10/site-packages/django/core/handlers/base.py", line 220, in _get_response
    response = response.render()
  File "/Library/Frameworks/Python.framework/Versions/3.10/lib/python3.10/site-packages/django/template/response.py", line 114, in render
    self.content = self.rendered_content
  File "/Library/Frameworks/Python.framework/Versions/3.10/lib/python3.10/site-packages/rest_framework/response.py", line 70, in rendered_content
    ret = renderer.render(self.data, accepted_media_type, context)
  File "/Users/macmini/Machine Learning/backup12_07/coreapp/renderers.py", line 26, in render
    return super(CustomRenderer, self).render(response, accepted_media_type, renderer_context)
  File "/Library/Frameworks/Python.framework/Versions/3.10/lib/python3.10/site-packages/rest_framework/renderers.py", line 99, in render
    ret = json.dumps(
  File "/Library/Frameworks/Python.framework/Versions/3.10/lib/python3.10/site-packages/rest_framework/utils/json.py", line 25, in dumps
    return json.dumps(*args, **kwargs)
  File "/Library/Frameworks/Python.framework/Versions/3.10/lib/python3.10/json/__init__.py", line 238, in dumps
    **kw).encode(obj)
  File "/Library/Frameworks/Python.framework/Versions/3.10/lib/python3.10/json/encoder.py", line 199, in encode
    chunks = self.iterencode(o, _one_shot=True)
  File "/Library/Frameworks/Python.framework/Versions/3.10/lib/python3.10/json/encoder.py", line 257, in iterencode
    return _iterencode(o, 0)
  File "/Library/Frameworks/Python.framework/Versions/3.10/lib/python3.10/site-packages/rest_framework/utils/encoders.py", line 67, in default
    return super().default(obj)
  File "/Library/Frameworks/Python.framework/Versions/3.10/lib/python3.10/json/encoder.py", line 179, in default
    raise TypeError(f'Object of type {o.__class__.__name__} '
TypeError: Object of type User is not JSON serializable
"GET /api/v1/sales/inventory/inventory/notifications HTTP/1.1" 500 104572
Internal Server Error: /api/v1/sales/inventory/inventory/notifications
Traceback (most recent call last):
  File "/Library/Frameworks/Python.framework/Versions/3.10/lib/python3.10/site-packages/django/core/handlers/exception.py", line 55, in inner
    response = get_response(request)
  File "/Library/Frameworks/Python.framework/Versions/3.10/lib/python3.10/site-packages/django/core/handlers/base.py", line 220, in _get_response
    response = response.render()
  File "/Library/Frameworks/Python.framework/Versions/3.10/lib/python3.10/site-packages/django/template/response.py", line 114, in render
    self.content = self.rendered_content
  File "/Library/Frameworks/Python.framework/Versions/3.10/lib/python3.10/site-packages/rest_framework/response.py", line 70, in rendered_content
    ret = renderer.render(self.data, accepted_media_type, context)
  File "/Users/macmini/Machine Learning/backup12_07/coreapp/renderers.py", line 26, in render
    return super(CustomRenderer, self).render(response, accepted_media_type, renderer_context)
  File "/Library/Frameworks/Python.framework/Versions/3.10/lib/python3.10/site-packages/rest_framework/renderers.py", line 99, in render
    ret = json.dumps(
  File "/Library/Frameworks/Python.framework/Versions/3.10/lib/python3.10/site-packages/rest_framework/utils/json.py", line 25, in dumps
    return json.dumps(*args, **kwargs)
  File "/Library/Frameworks/Python.framework/Versions/3.10/lib/python3.10/json/__init__.py", line 238, in dumps
    **kw).encode(obj)
  File "/Library/Frameworks/Python.framework/Versions/3.10/lib/python3.10/json/encoder.py", line 199, in encode
    chunks = self.iterencode(o, _one_shot=True)
  File "/Library/Frameworks/Python.framework/Versions/3.10/lib/python3.10/json/encoder.py", line 257, in iterencode
    return _iterencode(o, 0)
  File "/Library/Frameworks/Python.framework/Versions/3.10/lib/python3.10/site-packages/rest_framework/utils/encoders.py", line 67, in default
    return super().default(obj)
  File "/Library/Frameworks/Python.framework/Versions/3.10/lib/python3.10/json/encoder.py", line 179, in default
    raise TypeError(f'Object of type {o.__class__.__name__} '
TypeError: Object of type User is not JSON serializable
"GET /api/v1/sales/inventory/inventory/notifications HTTP/1.1" 500 104572
Internal Server Error: /api/v1/sales/inventory/inventory/notifications
Traceback (most recent call last):
  File "/Library/Frameworks/Python.framework/Versions/3.10/lib/python3.10/site-packages/django/core/handlers/exception.py", line 55, in inner
    response = get_response(request)
  File "/Library/Frameworks/Python.framework/Versions/3.10/lib/python3.10/site-packages/django/core/handlers/base.py", line 220, in _get_response
    response = response.render()
  File "/Library/Frameworks/Python.framework/Versions/3.10/lib/python3.10/site-packages/django/template/response.py", line 114, in render
    self.content = self.rendered_content
  File "/Library/Frameworks/Python.framework/Versions/3.10/lib/python3.10/site-packages/rest_framework/response.py", line 70, in rendered_content
    ret = renderer.render(self.data, accepted_media_type, context)
  File "/Users/macmini/Machine Learning/backup12_07/coreapp/renderers.py", line 26, in render
    return super(CustomRenderer, self).render(response, accepted_media_type, renderer_context)
  File "/Library/Frameworks/Python.framework/Versions/3.10/lib/python3.10/site-packages/rest_framework/renderers.py", line 99, in render
    ret = json.dumps(
  File "/Library/Frameworks/Python.framework/Versions/3.10/lib/python3.10/site-packages/rest_framework/utils/json.py", line 25, in dumps
    return json.dumps(*args, **kwargs)
  File "/Library/Frameworks/Python.framework/Versions/3.10/lib/python3.10/json/__init__.py", line 238, in dumps
    **kw).encode(obj)
  File "/Library/Frameworks/Python.framework/Versions/3.10/lib/python3.10/json/encoder.py", line 199, in encode
    chunks = self.iterencode(o, _one_shot=True)
  File "/Library/Frameworks/Python.framework/Versions/3.10/lib/python3.10/json/encoder.py", line 257, in iterencode
    return _iterencode(o, 0)
  File "/Library/Frameworks/Python.framework/Versions/3.10/lib/python3.10/site-packages/rest_framework/utils/encoders.py", line 67, in default
    return super().default(obj)
  File "/Library/Frameworks/Python.framework/Versions/3.10/lib/python3.10/json/encoder.py", line 179, in default
    raise TypeError(f'Object of type {o.__class__.__name__} '
TypeError: Object of type User is not JSON serializable
"GET /api/v1/sales/inventory/inventory/notifications HTTP/1.1" 500 104572
Internal Server Error: /api/v1/sales/inventory/inventory/notifications
Traceback (most recent call last):
  File "/Library/Frameworks/Python.framework/Versions/3.10/lib/python3.10/site-packages/django/core/handlers/exception.py", line 55, in inner
    response = get_response(request)
  File "/Library/Frameworks/Python.framework/Versions/3.10/lib/python3.10/site-packages/django/core/handlers/base.py", line 220, in _get_response
    response = response.render()
  File "/Library/Frameworks/Python.framework/Versions/3.10/lib/python3.10/site-packages/django/template/response.py", line 114, in render
    self.content = self.rendered_content
  File "/Library/Frameworks/Python.framework/Versions/3.10/lib/python3.10/site-packages/rest_framework/response.py", line 70, in rendered_content
    ret = renderer.render(self.data, accepted_media_type, context)
  File "/Users/macmini/Machine Learning/backup12_07/coreapp/renderers.py", line 26, in render
    return super(CustomRenderer, self).render(response, accepted_media_type, renderer_context)
  File "/Library/Frameworks/Python.framework/Versions/3.10/lib/python3.10/site-packages/rest_framework/renderers.py", line 99, in render
    ret = json.dumps(
  File "/Library/Frameworks/Python.framework/Versions/3.10/lib/python3.10/site-packages/rest_framework/utils/json.py", line 25, in dumps
    return json.dumps(*args, **kwargs)
  File "/Library/Frameworks/Python.framework/Versions/3.10/lib/python3.10/json/__init__.py", line 238, in dumps
    **kw).encode(obj)
  File "/Library/Frameworks/Python.framework/Versions/3.10/lib/python3.10/json/encoder.py", line 199, in encode
    chunks = self.iterencode(o, _one_shot=True)
  File "/Library/Frameworks/Python.framework/Versions/3.10/lib/python3.10/json/encoder.py", line 257, in iterencode
    return _iterencode(o, 0)
  File "/Library/Frameworks/Python.framework/Versions/3.10/lib/python3.10/site-packages/rest_framework/utils/encoders.py", line 67, in default
    return super().default(obj)
  File "/Library/Frameworks/Python.framework/Versions/3.10/lib/python3.10/json/encoder.py", line 179, in default
    raise TypeError(f'Object of type {o.__class__.__name__} '
TypeError: Object of type User is not JSON serializable
"GET /api/v1/sales/inventory/inventory/notifications HTTP/1.1" 500 104572
test_path/bar_codes/base/white.png /bar_codes/base/out/out.png
test_path/bar_codes/base/white.png /bar_codes/base/out/out.png
Internal Server Error: /api/v1/sales/inventory/inventory/notifications
Traceback (most recent call last):
  File "/Library/Frameworks/Python.framework/Versions/3.10/lib/python3.10/site-packages/django/core/handlers/exception.py", line 55, in inner
    response = get_response(request)
  File "/Library/Frameworks/Python.framework/Versions/3.10/lib/python3.10/site-packages/django/core/handlers/base.py", line 220, in _get_response
    response = response.render()
  File "/Library/Frameworks/Python.framework/Versions/3.10/lib/python3.10/site-packages/django/template/response.py", line 114, in render
    self.content = self.rendered_content
  File "/Library/Frameworks/Python.framework/Versions/3.10/lib/python3.10/site-packages/rest_framework/response.py", line 70, in rendered_content
    ret = renderer.render(self.data, accepted_media_type, context)
  File "/Users/macmini/Machine Learning/backup12_07/coreapp/renderers.py", line 26, in render
    return super(CustomRenderer, self).render(response, accepted_media_type, renderer_context)
  File "/Library/Frameworks/Python.framework/Versions/3.10/lib/python3.10/site-packages/rest_framework/renderers.py", line 99, in render
    ret = json.dumps(
  File "/Library/Frameworks/Python.framework/Versions/3.10/lib/python3.10/site-packages/rest_framework/utils/json.py", line 25, in dumps
    return json.dumps(*args, **kwargs)
  File "/Library/Frameworks/Python.framework/Versions/3.10/lib/python3.10/json/__init__.py", line 238, in dumps
    **kw).encode(obj)
  File "/Library/Frameworks/Python.framework/Versions/3.10/lib/python3.10/json/encoder.py", line 199, in encode
    chunks = self.iterencode(o, _one_shot=True)
  File "/Library/Frameworks/Python.framework/Versions/3.10/lib/python3.10/json/encoder.py", line 257, in iterencode
    return _iterencode(o, 0)
  File "/Library/Frameworks/Python.framework/Versions/3.10/lib/python3.10/site-packages/rest_framework/utils/encoders.py", line 67, in default
    return super().default(obj)
  File "/Library/Frameworks/Python.framework/Versions/3.10/lib/python3.10/json/encoder.py", line 179, in default
    raise TypeError(f'Object of type {o.__class__.__name__} '
TypeError: Object of type User is not JSON serializable
"GET /api/v1/sales/inventory/inventory/notifications HTTP/1.1" 500 104572
Internal Server Error: /api/v1/sales/inventory/inventory/notifications
Traceback (most recent call last):
  File "/Library/Frameworks/Python.framework/Versions/3.10/lib/python3.10/site-packages/django/core/handlers/exception.py", line 55, in inner
    response = get_response(request)
  File "/Library/Frameworks/Python.framework/Versions/3.10/lib/python3.10/site-packages/django/core/handlers/base.py", line 220, in _get_response
    response = response.render()
  File "/Library/Frameworks/Python.framework/Versions/3.10/lib/python3.10/site-packages/django/template/response.py", line 114, in render
    self.content = self.rendered_content
  File "/Library/Frameworks/Python.framework/Versions/3.10/lib/python3.10/site-packages/rest_framework/response.py", line 70, in rendered_content
    ret = renderer.render(self.data, accepted_media_type, context)
  File "/Users/macmini/Machine Learning/backup12_07/coreapp/renderers.py", line 26, in render
    return super(CustomRenderer, self).render(response, accepted_media_type, renderer_context)
  File "/Library/Frameworks/Python.framework/Versions/3.10/lib/python3.10/site-packages/rest_framework/renderers.py", line 99, in render
    ret = json.dumps(
  File "/Library/Frameworks/Python.framework/Versions/3.10/lib/python3.10/site-packages/rest_framework/utils/json.py", line 25, in dumps
    return json.dumps(*args, **kwargs)
  File "/Library/Frameworks/Python.framework/Versions/3.10/lib/python3.10/json/__init__.py", line 238, in dumps
    **kw).encode(obj)
  File "/Library/Frameworks/Python.framework/Versions/3.10/lib/python3.10/json/encoder.py", line 199, in encode
    chunks = self.iterencode(o, _one_shot=True)
  File "/Library/Frameworks/Python.framework/Versions/3.10/lib/python3.10/json/encoder.py", line 257, in iterencode
    return _iterencode(o, 0)
  File "/Library/Frameworks/Python.framework/Versions/3.10/lib/python3.10/site-packages/rest_framework/utils/encoders.py", line 67, in default
    return super().default(obj)
  File "/Library/Frameworks/Python.framework/Versions/3.10/lib/python3.10/json/encoder.py", line 179, in default
    raise TypeError(f'Object of type {o.__class__.__name__} '
TypeError: Object of type User is not JSON serializable
"GET /api/v1/sales/inventory/inventory/notifications HTTP/1.1" 500 104572
Internal Server Error: /api/v1/sales/inventory/inventory/notifications
Traceback (most recent call last):
  File "/Library/Frameworks/Python.framework/Versions/3.10/lib/python3.10/site-packages/django/core/handlers/exception.py", line 55, in inner
    response = get_response(request)
  File "/Library/Frameworks/Python.framework/Versions/3.10/lib/python3.10/site-packages/django/core/handlers/base.py", line 220, in _get_response
    response = response.render()
  File "/Library/Frameworks/Python.framework/Versions/3.10/lib/python3.10/site-packages/django/template/response.py", line 114, in render
    self.content = self.rendered_content
  File "/Library/Frameworks/Python.framework/Versions/3.10/lib/python3.10/site-packages/rest_framework/response.py", line 70, in rendered_content
    ret = renderer.render(self.data, accepted_media_type, context)
  File "/Users/macmini/Machine Learning/backup12_07/coreapp/renderers.py", line 26, in render
    return super(CustomRenderer, self).render(response, accepted_media_type, renderer_context)
  File "/Library/Frameworks/Python.framework/Versions/3.10/lib/python3.10/site-packages/rest_framework/renderers.py", line 99, in render
    ret = json.dumps(
  File "/Library/Frameworks/Python.framework/Versions/3.10/lib/python3.10/site-packages/rest_framework/utils/json.py", line 25, in dumps
    return json.dumps(*args, **kwargs)
  File "/Library/Frameworks/Python.framework/Versions/3.10/lib/python3.10/json/__init__.py", line 238, in dumps
    **kw).encode(obj)
  File "/Library/Frameworks/Python.framework/Versions/3.10/lib/python3.10/json/encoder.py", line 199, in encode
    chunks = self.iterencode(o, _one_shot=True)
  File "/Library/Frameworks/Python.framework/Versions/3.10/lib/python3.10/json/encoder.py", line 257, in iterencode
    return _iterencode(o, 0)
  File "/Library/Frameworks/Python.framework/Versions/3.10/lib/python3.10/site-packages/rest_framework/utils/encoders.py", line 67, in default
    return super().default(obj)
  File "/Library/Frameworks/Python.framework/Versions/3.10/lib/python3.10/json/encoder.py", line 179, in default
    raise TypeError(f'Object of type {o.__class__.__name__} '
TypeError: Object of type User is not JSON serializable
"GET /api/v1/sales/inventory/inventory/notifications HTTP/1.1" 500 104572
Internal Server Error: /api/v1/sales/inventory/inventory/notifications
Traceback (most recent call last):
  File "/Library/Frameworks/Python.framework/Versions/3.10/lib/python3.10/site-packages/django/core/handlers/exception.py", line 55, in inner
    response = get_response(request)
  File "/Library/Frameworks/Python.framework/Versions/3.10/lib/python3.10/site-packages/django/core/handlers/base.py", line 220, in _get_response
    response = response.render()
  File "/Library/Frameworks/Python.framework/Versions/3.10/lib/python3.10/site-packages/django/template/response.py", line 114, in render
    self.content = self.rendered_content
  File "/Library/Frameworks/Python.framework/Versions/3.10/lib/python3.10/site-packages/rest_framework/response.py", line 70, in rendered_content
    ret = renderer.render(self.data, accepted_media_type, context)
  File "/Users/macmini/Machine Learning/backup12_07/coreapp/renderers.py", line 26, in render
    return super(CustomRenderer, self).render(response, accepted_media_type, renderer_context)
  File "/Library/Frameworks/Python.framework/Versions/3.10/lib/python3.10/site-packages/rest_framework/renderers.py", line 99, in render
    ret = json.dumps(
  File "/Library/Frameworks/Python.framework/Versions/3.10/lib/python3.10/site-packages/rest_framework/utils/json.py", line 25, in dumps
    return json.dumps(*args, **kwargs)
  File "/Library/Frameworks/Python.framework/Versions/3.10/lib/python3.10/json/__init__.py", line 238, in dumps
    **kw).encode(obj)
  File "/Library/Frameworks/Python.framework/Versions/3.10/lib/python3.10/json/encoder.py", line 199, in encode
    chunks = self.iterencode(o, _one_shot=True)
  File "/Library/Frameworks/Python.framework/Versions/3.10/lib/python3.10/json/encoder.py", line 257, in iterencode
    return _iterencode(o, 0)
  File "/Library/Frameworks/Python.framework/Versions/3.10/lib/python3.10/site-packages/rest_framework/utils/encoders.py", line 67, in default
    return super().default(obj)
  File "/Library/Frameworks/Python.framework/Versions/3.10/lib/python3.10/json/encoder.py", line 179, in default
    raise TypeError(f'Object of type {o.__class__.__name__} '
TypeError: Object of type User is not JSON serializable
"GET /api/v1/sales/inventory/inventory/notifications HTTP/1.1" 500 104572
Internal Server Error: /api/v1/sales/inventory/inventory/notifications
Traceback (most recent call last):
  File "/Library/Frameworks/Python.framework/Versions/3.10/lib/python3.10/site-packages/django/core/handlers/exception.py", line 55, in inner
    response = get_response(request)
  File "/Library/Frameworks/Python.framework/Versions/3.10/lib/python3.10/site-packages/django/core/handlers/base.py", line 220, in _get_response
    response = response.render()
  File "/Library/Frameworks/Python.framework/Versions/3.10/lib/python3.10/site-packages/django/template/response.py", line 114, in render
    self.content = self.rendered_content
  File "/Library/Frameworks/Python.framework/Versions/3.10/lib/python3.10/site-packages/rest_framework/response.py", line 70, in rendered_content
    ret = renderer.render(self.data, accepted_media_type, context)
  File "/Users/macmini/Machine Learning/backup12_07/coreapp/renderers.py", line 26, in render
    return super(CustomRenderer, self).render(response, accepted_media_type, renderer_context)
  File "/Library/Frameworks/Python.framework/Versions/3.10/lib/python3.10/site-packages/rest_framework/renderers.py", line 99, in render
    ret = json.dumps(
  File "/Library/Frameworks/Python.framework/Versions/3.10/lib/python3.10/site-packages/rest_framework/utils/json.py", line 25, in dumps
    return json.dumps(*args, **kwargs)
  File "/Library/Frameworks/Python.framework/Versions/3.10/lib/python3.10/json/__init__.py", line 238, in dumps
    **kw).encode(obj)
  File "/Library/Frameworks/Python.framework/Versions/3.10/lib/python3.10/json/encoder.py", line 199, in encode
    chunks = self.iterencode(o, _one_shot=True)
  File "/Library/Frameworks/Python.framework/Versions/3.10/lib/python3.10/json/encoder.py", line 257, in iterencode
    return _iterencode(o, 0)
  File "/Library/Frameworks/Python.framework/Versions/3.10/lib/python3.10/site-packages/rest_framework/utils/encoders.py", line 67, in default
    return super().default(obj)
  File "/Library/Frameworks/Python.framework/Versions/3.10/lib/python3.10/json/encoder.py", line 179, in default
    raise TypeError(f'Object of type {o.__class__.__name__} '
TypeError: Object of type User is not JSON serializable
"GET /api/v1/sales/inventory/inventory/notifications HTTP/1.1" 500 104572
test_path/bar_codes/base/white.png /bar_codes/base/out/out.png
test_path/bar_codes/base/white.png /bar_codes/base/out/out.png
Internal Server Error: /api/v1/sales/inventory/inventory/notifications
Traceback (most recent call last):
  File "/Library/Frameworks/Python.framework/Versions/3.10/lib/python3.10/site-packages/django/core/handlers/exception.py", line 55, in inner
    response = get_response(request)
  File "/Library/Frameworks/Python.framework/Versions/3.10/lib/python3.10/site-packages/django/core/handlers/base.py", line 220, in _get_response
    response = response.render()
  File "/Library/Frameworks/Python.framework/Versions/3.10/lib/python3.10/site-packages/django/template/response.py", line 114, in render
    self.content = self.rendered_content
  File "/Library/Frameworks/Python.framework/Versions/3.10/lib/python3.10/site-packages/rest_framework/response.py", line 70, in rendered_content
    ret = renderer.render(self.data, accepted_media_type, context)
  File "/Users/macmini/Machine Learning/backup12_07/coreapp/renderers.py", line 26, in render
    return super(CustomRenderer, self).render(response, accepted_media_type, renderer_context)
  File "/Library/Frameworks/Python.framework/Versions/3.10/lib/python3.10/site-packages/rest_framework/renderers.py", line 99, in render
    ret = json.dumps(
  File "/Library/Frameworks/Python.framework/Versions/3.10/lib/python3.10/site-packages/rest_framework/utils/json.py", line 25, in dumps
    return json.dumps(*args, **kwargs)
  File "/Library/Frameworks/Python.framework/Versions/3.10/lib/python3.10/json/__init__.py", line 238, in dumps
    **kw).encode(obj)
  File "/Library/Frameworks/Python.framework/Versions/3.10/lib/python3.10/json/encoder.py", line 199, in encode
    chunks = self.iterencode(o, _one_shot=True)
  File "/Library/Frameworks/Python.framework/Versions/3.10/lib/python3.10/json/encoder.py", line 257, in iterencode
    return _iterencode(o, 0)
  File "/Library/Frameworks/Python.framework/Versions/3.10/lib/python3.10/site-packages/rest_framework/utils/encoders.py", line 67, in default
    return super().default(obj)
  File "/Library/Frameworks/Python.framework/Versions/3.10/lib/python3.10/json/encoder.py", line 179, in default
    raise TypeError(f'Object of type {o.__class__.__name__} '
TypeError: Object of type User is not JSON serializable
"GET /api/v1/sales/inventory/inventory/notifications HTTP/1.1" 500 104572
test_path/bar_codes/base/white.png /bar_codes/base/out/out.png
Internal Server Error: /admin/sales/invoice/14/change/
Traceback (most recent call last):
  File "/Library/Frameworks/Python.framework/Versions/3.10/lib/python3.10/site-packages/django/core/handlers/exception.py", line 55, in inner
    response = get_response(request)
  File "/Library/Frameworks/Python.framework/Versions/3.10/lib/python3.10/site-packages/django/core/handlers/base.py", line 197, in _get_response
    response = wrapped_callback(request, *callback_args, **callback_kwargs)
  File "/Library/Frameworks/Python.framework/Versions/3.10/lib/python3.10/site-packages/django/contrib/admin/options.py", line 686, in wrapper
    return self.admin_site.admin_view(view)(*args, **kwargs)
  File "/Library/Frameworks/Python.framework/Versions/3.10/lib/python3.10/site-packages/django/utils/decorators.py", line 133, in _wrapped_view
    response = view_func(request, *args, **kwargs)
  File "/Library/Frameworks/Python.framework/Versions/3.10/lib/python3.10/site-packages/django/views/decorators/cache.py", line 62, in _wrapped_view_func
    response = view_func(request, *args, **kwargs)
  File "/Library/Frameworks/Python.framework/Versions/3.10/lib/python3.10/site-packages/django/contrib/admin/sites.py", line 242, in inner
    return view(request, *args, **kwargs)
  File "/Library/Frameworks/Python.framework/Versions/3.10/lib/python3.10/site-packages/django/contrib/admin/options.py", line 1893, in change_view
    return self.changeform_view(request, object_id, form_url, extra_context)
  File "/Library/Frameworks/Python.framework/Versions/3.10/lib/python3.10/site-packages/django/utils/decorators.py", line 46, in _wrapper
    return bound_method(*args, **kwargs)
  File "/Library/Frameworks/Python.framework/Versions/3.10/lib/python3.10/site-packages/django/utils/decorators.py", line 133, in _wrapped_view
    response = view_func(request, *args, **kwargs)
  File "/Library/Frameworks/Python.framework/Versions/3.10/lib/python3.10/site-packages/django/contrib/admin/options.py", line 1750, in changeform_view
    return self._changeform_view(request, object_id, form_url, extra_context)
  File "/Library/Frameworks/Python.framework/Versions/3.10/lib/python3.10/site-packages/django/contrib/admin/options.py", line 1802, in _changeform_view
    self.save_model(request, new_object, form, not add)
  File "/Users/macmini/Machine Learning/backup12_07/sales/admin.py", line 13, in save_model
    obj.save()
  File "/Users/macmini/Machine Learning/backup12_07/sales/models.py", line 138, in save
    notification, created = Notification.objects.get_or_create(user=self.user)
AttributeError: 'Invoice' object has no attribute 'user'
"POST /admin/sales/invoice/14/change/ HTTP/1.1" 500 122797
Error in generate_product_barcode:  
 Traceback (most recent call last):
  File "/Users/macmini/Machine Learning/backup12_07/utility/utils/bar_image_utils.py", line 59, in add_images_and_text
    modified_image = insert_text(image_path, text, output_path, size=30, add_x=0, position_y=2,color='white')
  File "/Users/macmini/Machine Learning/backup12_07/utility/utils/bar_image_utils.py", line 6, in insert_text
    image = Image.open(image_path)
  File "/Library/Frameworks/Python.framework/Versions/3.10/lib/python3.10/site-packages/PIL/Image.py", line 3236, in open
    fp = builtins.open(filename, "rb")
FileNotFoundError: [Errno 2] No such file or directory: '/bar_codes/base/white.png'

test_path/bar_codes/base/white.png /bar_codes/base/out/out.png
test_path/bar_codes/base/white.png /bar_codes/base/out/out.png
test_path/bar_codes/base/white.png /bar_codes/base/out/out.png
test_path/bar_codes/base/white.png /bar_codes/base/out/out.png
test_path/bar_codes/base/white.png /bar_codes/base/out/out.png
Internal Server Error: /admin/sales/invoice/add/
Traceback (most recent call last):
  File "/Library/Frameworks/Python.framework/Versions/3.10/lib/python3.10/site-packages/django/core/handlers/exception.py", line 55, in inner
    response = get_response(request)
  File "/Library/Frameworks/Python.framework/Versions/3.10/lib/python3.10/site-packages/django/core/handlers/base.py", line 197, in _get_response
    response = wrapped_callback(request, *callback_args, **callback_kwargs)
  File "/Library/Frameworks/Python.framework/Versions/3.10/lib/python3.10/site-packages/django/contrib/admin/options.py", line 686, in wrapper
    return self.admin_site.admin_view(view)(*args, **kwargs)
  File "/Library/Frameworks/Python.framework/Versions/3.10/lib/python3.10/site-packages/django/utils/decorators.py", line 133, in _wrapped_view
    response = view_func(request, *args, **kwargs)
  File "/Library/Frameworks/Python.framework/Versions/3.10/lib/python3.10/site-packages/django/views/decorators/cache.py", line 62, in _wrapped_view_func
    response = view_func(request, *args, **kwargs)
  File "/Library/Frameworks/Python.framework/Versions/3.10/lib/python3.10/site-packages/django/contrib/admin/sites.py", line 242, in inner
    return view(request, *args, **kwargs)
  File "/Library/Frameworks/Python.framework/Versions/3.10/lib/python3.10/site-packages/django/contrib/admin/options.py", line 1890, in add_view
    return self.changeform_view(request, None, form_url, extra_context)
  File "/Library/Frameworks/Python.framework/Versions/3.10/lib/python3.10/site-packages/django/utils/decorators.py", line 46, in _wrapper
    return bound_method(*args, **kwargs)
  File "/Library/Frameworks/Python.framework/Versions/3.10/lib/python3.10/site-packages/django/utils/decorators.py", line 133, in _wrapped_view
    response = view_func(request, *args, **kwargs)
  File "/Library/Frameworks/Python.framework/Versions/3.10/lib/python3.10/site-packages/django/contrib/admin/options.py", line 1750, in changeform_view
    return self._changeform_view(request, object_id, form_url, extra_context)
  File "/Library/Frameworks/Python.framework/Versions/3.10/lib/python3.10/site-packages/django/contrib/admin/options.py", line 1802, in _changeform_view
    self.save_model(request, new_object, form, not add)
  File "/Users/macmini/Machine Learning/backup12_07/sales/admin.py", line 13, in save_model
    obj.save()
  File "/Users/macmini/Machine Learning/backup12_07/sales/models.py", line 138, in save
    notification, created = Notification.objects.get_or_create(user=self.user)
AttributeError: 'Invoice' object has no attribute 'user'
"POST /admin/sales/invoice/add/ HTTP/1.1" 500 122148
Internal Server Error: /admin/sales/invoice/add/
Traceback (most recent call last):
  File "/Library/Frameworks/Python.framework/Versions/3.10/lib/python3.10/site-packages/django/core/handlers/exception.py", line 55, in inner
    response = get_response(request)
  File "/Library/Frameworks/Python.framework/Versions/3.10/lib/python3.10/site-packages/django/core/handlers/base.py", line 197, in _get_response
    response = wrapped_callback(request, *callback_args, **callback_kwargs)
  File "/Library/Frameworks/Python.framework/Versions/3.10/lib/python3.10/site-packages/django/contrib/admin/options.py", line 686, in wrapper
    return self.admin_site.admin_view(view)(*args, **kwargs)
  File "/Library/Frameworks/Python.framework/Versions/3.10/lib/python3.10/site-packages/django/utils/decorators.py", line 133, in _wrapped_view
    response = view_func(request, *args, **kwargs)
  File "/Library/Frameworks/Python.framework/Versions/3.10/lib/python3.10/site-packages/django/views/decorators/cache.py", line 62, in _wrapped_view_func
    response = view_func(request, *args, **kwargs)
  File "/Library/Frameworks/Python.framework/Versions/3.10/lib/python3.10/site-packages/django/contrib/admin/sites.py", line 242, in inner
    return view(request, *args, **kwargs)
  File "/Library/Frameworks/Python.framework/Versions/3.10/lib/python3.10/site-packages/django/contrib/admin/options.py", line 1890, in add_view
    return self.changeform_view(request, None, form_url, extra_context)
  File "/Library/Frameworks/Python.framework/Versions/3.10/lib/python3.10/site-packages/django/utils/decorators.py", line 46, in _wrapper
    return bound_method(*args, **kwargs)
  File "/Library/Frameworks/Python.framework/Versions/3.10/lib/python3.10/site-packages/django/utils/decorators.py", line 133, in _wrapped_view
    response = view_func(request, *args, **kwargs)
  File "/Library/Frameworks/Python.framework/Versions/3.10/lib/python3.10/site-packages/django/contrib/admin/options.py", line 1750, in changeform_view
    return self._changeform_view(request, object_id, form_url, extra_context)
  File "/Library/Frameworks/Python.framework/Versions/3.10/lib/python3.10/site-packages/django/contrib/admin/options.py", line 1802, in _changeform_view
    self.save_model(request, new_object, form, not add)
  File "/Users/macmini/Machine Learning/backup12_07/sales/admin.py", line 13, in save_model
    obj.save()
  File "/Users/macmini/Machine Learning/backup12_07/sales/models.py", line 138, in save
    notification, created = Notification.objects.get_or_create(user=self.user)
AttributeError: 'Invoice' object has no attribute 'user'
"POST /admin/sales/invoice/add/ HTTP/1.1" 500 122148
test_path/bar_codes/base/white.png /bar_codes/base/out/out.png
test_path/bar_codes/base/white.png /bar_codes/base/out/out.png
test_path/bar_codes/base/white.png /bar_codes/base/out/out.png
test_path/bar_codes/base/white.png /bar_codes/base/out/out.png
test_path/bar_codes/base/white.png /bar_codes/base/out/out.png
test_path/bar_codes/base/white.png /bar_codes/base/out/out.png
test_path/bar_codes/base/white.png /bar_codes/base/out/out.png
test_path/bar_codes/base/white.png /bar_codes/base/out/out.png
Internal Server Error: /admin/sales/invoice/add/
Traceback (most recent call last):
  File "/Library/Frameworks/Python.framework/Versions/3.10/lib/python3.10/site-packages/django/core/handlers/exception.py", line 55, in inner
    response = get_response(request)
  File "/Library/Frameworks/Python.framework/Versions/3.10/lib/python3.10/site-packages/django/core/handlers/base.py", line 197, in _get_response
    response = wrapped_callback(request, *callback_args, **callback_kwargs)
  File "/Library/Frameworks/Python.framework/Versions/3.10/lib/python3.10/site-packages/django/contrib/admin/options.py", line 686, in wrapper
    return self.admin_site.admin_view(view)(*args, **kwargs)
  File "/Library/Frameworks/Python.framework/Versions/3.10/lib/python3.10/site-packages/django/utils/decorators.py", line 133, in _wrapped_view
    response = view_func(request, *args, **kwargs)
  File "/Library/Frameworks/Python.framework/Versions/3.10/lib/python3.10/site-packages/django/views/decorators/cache.py", line 62, in _wrapped_view_func
    response = view_func(request, *args, **kwargs)
  File "/Library/Frameworks/Python.framework/Versions/3.10/lib/python3.10/site-packages/django/contrib/admin/sites.py", line 242, in inner
    return view(request, *args, **kwargs)
  File "/Library/Frameworks/Python.framework/Versions/3.10/lib/python3.10/site-packages/django/contrib/admin/options.py", line 1890, in add_view
    return self.changeform_view(request, None, form_url, extra_context)
  File "/Library/Frameworks/Python.framework/Versions/3.10/lib/python3.10/site-packages/django/utils/decorators.py", line 46, in _wrapper
    return bound_method(*args, **kwargs)
  File "/Library/Frameworks/Python.framework/Versions/3.10/lib/python3.10/site-packages/django/utils/decorators.py", line 133, in _wrapped_view
    response = view_func(request, *args, **kwargs)
  File "/Library/Frameworks/Python.framework/Versions/3.10/lib/python3.10/site-packages/django/contrib/admin/options.py", line 1750, in changeform_view
    return self._changeform_view(request, object_id, form_url, extra_context)
  File "/Library/Frameworks/Python.framework/Versions/3.10/lib/python3.10/site-packages/django/contrib/admin/options.py", line 1802, in _changeform_view
    self.save_model(request, new_object, form, not add)
  File "/Users/macmini/Machine Learning/backup12_07/sales/admin.py", line 13, in save_model
    obj.save()
  File "/Users/macmini/Machine Learning/backup12_07/sales/models.py", line 138, in save
    notification, created = Notification.objects.get_or_create(user=self.user)
AttributeError: 'Invoice' object has no attribute 'user'
"POST /admin/sales/invoice/add/ HTTP/1.1" 500 122016
test_path/bar_codes/base/white.png /bar_codes/base/out/out.png
test_path/bar_codes/base/white.png /bar_codes/base/out/out.png
test_path/bar_codes/base/white.png /bar_codes/base/out/out.png
test_path/bar_codes/base/white.png /bar_codes/base/out/out.png
Internal Server Error: /admin/sales/invoice/17/change/
Traceback (most recent call last):
  File "/Library/Frameworks/Python.framework/Versions/3.10/lib/python3.10/site-packages/django/core/handlers/exception.py", line 55, in inner
    response = get_response(request)
  File "/Library/Frameworks/Python.framework/Versions/3.10/lib/python3.10/site-packages/django/core/handlers/base.py", line 197, in _get_response
    response = wrapped_callback(request, *callback_args, **callback_kwargs)
  File "/Library/Frameworks/Python.framework/Versions/3.10/lib/python3.10/site-packages/django/contrib/admin/options.py", line 686, in wrapper
    return self.admin_site.admin_view(view)(*args, **kwargs)
  File "/Library/Frameworks/Python.framework/Versions/3.10/lib/python3.10/site-packages/django/utils/decorators.py", line 133, in _wrapped_view
    response = view_func(request, *args, **kwargs)
  File "/Library/Frameworks/Python.framework/Versions/3.10/lib/python3.10/site-packages/django/views/decorators/cache.py", line 62, in _wrapped_view_func
    response = view_func(request, *args, **kwargs)
  File "/Library/Frameworks/Python.framework/Versions/3.10/lib/python3.10/site-packages/django/contrib/admin/sites.py", line 242, in inner
    return view(request, *args, **kwargs)
  File "/Library/Frameworks/Python.framework/Versions/3.10/lib/python3.10/site-packages/django/contrib/admin/options.py", line 1893, in change_view
    return self.changeform_view(request, object_id, form_url, extra_context)
  File "/Library/Frameworks/Python.framework/Versions/3.10/lib/python3.10/site-packages/django/utils/decorators.py", line 46, in _wrapper
    return bound_method(*args, **kwargs)
  File "/Library/Frameworks/Python.framework/Versions/3.10/lib/python3.10/site-packages/django/utils/decorators.py", line 133, in _wrapped_view
    response = view_func(request, *args, **kwargs)
  File "/Library/Frameworks/Python.framework/Versions/3.10/lib/python3.10/site-packages/django/contrib/admin/options.py", line 1750, in changeform_view
    return self._changeform_view(request, object_id, form_url, extra_context)
  File "/Library/Frameworks/Python.framework/Versions/3.10/lib/python3.10/site-packages/django/contrib/admin/options.py", line 1802, in _changeform_view
    self.save_model(request, new_object, form, not add)
  File "/Users/macmini/Machine Learning/backup12_07/sales/admin.py", line 13, in save_model
    obj.save()
  File "/Users/macmini/Machine Learning/backup12_07/sales/models.py", line 135, in save
    super().save(*args, **kwargs)
  File "/Library/Frameworks/Python.framework/Versions/3.10/lib/python3.10/site-packages/django/db/models/base.py", line 831, in save
    self.save_base(
  File "/Library/Frameworks/Python.framework/Versions/3.10/lib/python3.10/site-packages/django/db/models/base.py", line 897, in save_base
    post_save.send(
  File "/Library/Frameworks/Python.framework/Versions/3.10/lib/python3.10/site-packages/django/dispatch/dispatcher.py", line 176, in send
    return [
  File "/Library/Frameworks/Python.framework/Versions/3.10/lib/python3.10/site-packages/django/dispatch/dispatcher.py", line 177, in <listcomp>
    (receiver, receiver(signal=self, sender=sender, **named))
  File "/Users/macmini/Machine Learning/backup12_07/sales/models.py", line 157, in increment_notification_count
    notification, _ = Notification.objects.get_or_create(user=instance.user)
AttributeError: 'Invoice' object has no attribute 'user'
"POST /admin/sales/invoice/17/change/ HTTP/1.1" 500 145061
test_path/bar_codes/base/white.png /bar_codes/base/out/out.png
test_path/bar_codes/base/white.png /bar_codes/base/out/out.png
test_path/bar_codes/base/white.png /bar_codes/base/out/out.png
