test_path/home/clientsdevs/kaaruj.backend.clients.devsstream.com/media/bar_codes/base/white.png /home/clientsdevs/kaaruj.backend.clients.devsstream.com/media/bar_codes/base/out/out.png
test_path/home/clientsdevs/kaaruj.backend.clients.devsstream.com/media/bar_codes/base/white.png /home/clientsdevs/kaaruj.backend.clients.devsstream.com/media/bar_codes/base/out/out.png
test_path/home/clientsdevs/kaaruj.backend.clients.devsstream.com/media/bar_codes/base/white.png /home/clientsdevs/kaaruj.backend.clients.devsstream.com/media/bar_codes/base/out/out.png
test_path/home/clientsdevs/kaaruj.backend.clients.devsstream.com/media/bar_codes/base/white.png /home/clientsdevs/kaaruj.backend.clients.devsstream.com/media/bar_codes/base/out/out.png
test_path/home/clientsdevs/kaaruj.backend.clients.devsstream.com/media/bar_codes/base/white.png /home/clientsdevs/kaaruj.backend.clients.devsstream.com/media/bar_codes/base/out/out.png
test_path/home/clientsdevs/kaaruj.backend.clients.devsstream.com/media/bar_codes/base/white.png /home/clientsdevs/kaaruj.backend.clients.devsstream.com/media/bar_codes/base/out/out.png
test_path/home/clientsdevs/kaaruj.backend.clients.devsstream.com/media/bar_codes/base/white.png /home/clientsdevs/kaaruj.backend.clients.devsstream.com/media/bar_codes/base/out/out.png
test_path/home/clientsdevs/kaaruj.backend.clients.devsstream.com/media/bar_codes/base/white.png /home/clientsdevs/kaaruj.backend.clients.devsstream.com/media/bar_codes/base/out/out.png
test_path/home/clientsdevs/kaaruj.backend.clients.devsstream.com/media/bar_codes/base/white.png /home/clientsdevs/kaaruj.backend.clients.devsstream.com/media/bar_codes/base/out/out.png
test_path/home/clientsdevs/kaaruj.backend.clients.devsstream.com/media/bar_codes/base/white.png /home/clientsdevs/kaaruj.backend.clients.devsstream.com/media/bar_codes/base/out/out.png
test_path/home/clientsdevs/kaaruj.backend.clients.devsstream.com/media/bar_codes/base/white.png /home/clientsdevs/kaaruj.backend.clients.devsstream.com/media/bar_codes/base/out/out.png
test_path/home/clientsdevs/kaaruj.backend.clients.devsstream.com/media/bar_codes/base/white.png /home/clientsdevs/kaaruj.backend.clients.devsstream.com/media/bar_codes/base/out/out.png
test_path/home/clientsdevs/kaaruj.backend.clients.devsstream.com/media/bar_codes/base/white.png /home/clientsdevs/kaaruj.backend.clients.devsstream.com/media/bar_codes/base/out/out.png
test_path/home/clientsdevs/kaaruj.backend.clients.devsstream.com/media/bar_codes/base/white.png /home/clientsdevs/kaaruj.backend.clients.devsstream.com/media/bar_codes/base/out/out.png
test_path/home/clientsdevs/kaaruj.backend.clients.devsstream.com/media/bar_codes/base/white.png /home/clientsdevs/kaaruj.backend.clients.devsstream.com/media/bar_codes/base/out/out.png
Invalid HTTP_HOST header: '127.0.0.1:8000'. You may need to add '127.0.0.1' to ALLOWED_HOSTS.
Traceback (most recent call last):
  File "/Users/macmini/Phitron/backup12_07/venv/lib/python3.10/site-packages/django/core/handlers/exception.py", line 55, in inner
    response = get_response(request)
  File "/Users/macmini/Phitron/backup12_07/venv/lib/python3.10/site-packages/django/utils/deprecation.py", line 135, in __call__
    response = self.process_request(request)
  File "/Users/macmini/Phitron/backup12_07/venv/lib/python3.10/site-packages/django/middleware/common.py", line 48, in process_request
    host = request.get_host()
  File "/Users/macmini/Phitron/backup12_07/venv/lib/python3.10/site-packages/django/http/request.py", line 148, in get_host
    raise DisallowedHost(msg)
django.core.exceptions.DisallowedHost: Invalid HTTP_HOST header: '127.0.0.1:8000'. You may need to add '127.0.0.1' to ALLOWED_HOSTS.
Invalid HTTP_HOST header: '127.0.0.1:8000'. You may need to add '127.0.0.1' to ALLOWED_HOSTS.
Traceback (most recent call last):
  File "/Users/macmini/Phitron/backup12_07/venv/lib/python3.10/site-packages/django/core/handlers/exception.py", line 55, in inner
    response = get_response(request)
  File "/Users/macmini/Phitron/backup12_07/venv/lib/python3.10/site-packages/django/utils/deprecation.py", line 135, in __call__
    response = self.process_request(request)
  File "/Users/macmini/Phitron/backup12_07/venv/lib/python3.10/site-packages/django/middleware/common.py", line 48, in process_request
    host = request.get_host()
  File "/Users/macmini/Phitron/backup12_07/venv/lib/python3.10/site-packages/django/http/request.py", line 148, in get_host
    raise DisallowedHost(msg)
django.core.exceptions.DisallowedHost: Invalid HTTP_HOST header: '127.0.0.1:8000'. You may need to add '127.0.0.1' to ALLOWED_HOSTS.
Invalid HTTP_HOST header: '127.0.0.1:8000'. You may need to add '127.0.0.1' to ALLOWED_HOSTS.
Traceback (most recent call last):
  File "/Users/macmini/Phitron/backup12_07/venv/lib/python3.10/site-packages/django/core/handlers/exception.py", line 55, in inner
    response = get_response(request)
  File "/Users/macmini/Phitron/backup12_07/venv/lib/python3.10/site-packages/django/utils/deprecation.py", line 135, in __call__
    response = self.process_request(request)
  File "/Users/macmini/Phitron/backup12_07/venv/lib/python3.10/site-packages/django/middleware/common.py", line 48, in process_request
    host = request.get_host()
  File "/Users/macmini/Phitron/backup12_07/venv/lib/python3.10/site-packages/django/http/request.py", line 148, in get_host
    raise DisallowedHost(msg)
django.core.exceptions.DisallowedHost: Invalid HTTP_HOST header: '127.0.0.1:8000'. You may need to add '127.0.0.1' to ALLOWED_HOSTS.
Invalid HTTP_HOST header: '127.0.0.1:8000'. You may need to add '127.0.0.1' to ALLOWED_HOSTS.
Traceback (most recent call last):
  File "/Users/macmini/Phitron/backup12_07/venv/lib/python3.10/site-packages/django/core/handlers/exception.py", line 55, in inner
    response = get_response(request)
  File "/Users/macmini/Phitron/backup12_07/venv/lib/python3.10/site-packages/django/utils/deprecation.py", line 135, in __call__
    response = self.process_request(request)
  File "/Users/macmini/Phitron/backup12_07/venv/lib/python3.10/site-packages/django/middleware/common.py", line 48, in process_request
    host = request.get_host()
  File "/Users/macmini/Phitron/backup12_07/venv/lib/python3.10/site-packages/django/http/request.py", line 148, in get_host
    raise DisallowedHost(msg)
django.core.exceptions.DisallowedHost: Invalid HTTP_HOST header: '127.0.0.1:8000'. You may need to add '127.0.0.1' to ALLOWED_HOSTS.
Invalid HTTP_HOST header: '127.0.0.1:8000'. You may need to add '127.0.0.1' to ALLOWED_HOSTS.
Traceback (most recent call last):
  File "/Users/macmini/Phitron/backup12_07/venv/lib/python3.10/site-packages/django/core/handlers/exception.py", line 55, in inner
    response = get_response(request)
  File "/Users/macmini/Phitron/backup12_07/venv/lib/python3.10/site-packages/django/utils/deprecation.py", line 135, in __call__
    response = self.process_request(request)
  File "/Users/macmini/Phitron/backup12_07/venv/lib/python3.10/site-packages/django/middleware/common.py", line 48, in process_request
    host = request.get_host()
  File "/Users/macmini/Phitron/backup12_07/venv/lib/python3.10/site-packages/django/http/request.py", line 148, in get_host
    raise DisallowedHost(msg)
django.core.exceptions.DisallowedHost: Invalid HTTP_HOST header: '127.0.0.1:8000'. You may need to add '127.0.0.1' to ALLOWED_HOSTS.
Invalid HTTP_HOST header: '127.0.0.1:8000'. You may need to add '127.0.0.1' to ALLOWED_HOSTS.
Traceback (most recent call last):
  File "/Users/macmini/Phitron/backup12_07/venv/lib/python3.10/site-packages/django/core/handlers/exception.py", line 55, in inner
    response = get_response(request)
  File "/Users/macmini/Phitron/backup12_07/venv/lib/python3.10/site-packages/django/utils/deprecation.py", line 135, in __call__
    response = self.process_request(request)
  File "/Users/macmini/Phitron/backup12_07/venv/lib/python3.10/site-packages/django/middleware/common.py", line 48, in process_request
    host = request.get_host()
  File "/Users/macmini/Phitron/backup12_07/venv/lib/python3.10/site-packages/django/http/request.py", line 148, in get_host
    raise DisallowedHost(msg)
django.core.exceptions.DisallowedHost: Invalid HTTP_HOST header: '127.0.0.1:8000'. You may need to add '127.0.0.1' to ALLOWED_HOSTS.
test_path/home/clientsdevs/kaaruj.backend.clients.devsstream.com/media/bar_codes/base/white.png /home/clientsdevs/kaaruj.backend.clients.devsstream.com/media/bar_codes/base/out/out.png
test_path/home/clientsdevs/kaaruj.backend.clients.devsstream.com/media/bar_codes/base/white.png /home/clientsdevs/kaaruj.backend.clients.devsstream.com/media/bar_codes/base/out/out.png
test_path/home/clientsdevs/kaaruj.backend.clients.devsstream.com/media/bar_codes/base/white.png /home/clientsdevs/kaaruj.backend.clients.devsstream.com/media/bar_codes/base/out/out.png
test_path/home/clientsdevs/kaaruj.backend.clients.devsstream.com/media/bar_codes/base/white.png /home/clientsdevs/kaaruj.backend.clients.devsstream.com/media/bar_codes/base/out/out.png
test_path/home/clientsdevs/kaaruj.backend.clients.devsstream.com/media/bar_codes/base/white.png /home/clientsdevs/kaaruj.backend.clients.devsstream.com/media/bar_codes/base/out/out.png
test_path/home/clientsdevs/kaaruj.backend.clients.devsstream.com/media/bar_codes/base/white.png /home/clientsdevs/kaaruj.backend.clients.devsstream.com/media/bar_codes/base/out/out.png
test_path/home/clientsdevs/kaaruj.backend.clients.devsstream.com/media/bar_codes/base/white.png /home/clientsdevs/kaaruj.backend.clients.devsstream.com/media/bar_codes/base/out/out.png
test_path/home/clientsdevs/kaaruj.backend.clients.devsstream.com/media/bar_codes/base/white.png /home/clientsdevs/kaaruj.backend.clients.devsstream.com/media/bar_codes/base/out/out.png
test_path/home/clientsdevs/kaaruj.backend.clients.devsstream.com/media/bar_codes/base/white.png /home/clientsdevs/kaaruj.backend.clients.devsstream.com/media/bar_codes/base/out/out.png
test_path/home/clientsdevs/kaaruj.backend.clients.devsstream.com/media/bar_codes/base/white.png /home/clientsdevs/kaaruj.backend.clients.devsstream.com/media/bar_codes/base/out/out.png
test_path/home/clientsdevs/kaaruj.backend.clients.devsstream.com/media/bar_codes/base/white.png /home/clientsdevs/kaaruj.backend.clients.devsstream.com/media/bar_codes/base/out/out.png
test_path/home/clientsdevs/kaaruj.backend.clients.devsstream.com/media/bar_codes/base/white.png /home/clientsdevs/kaaruj.backend.clients.devsstream.com/media/bar_codes/base/out/out.png
test_path/home/clientsdevs/kaaruj.backend.clients.devsstream.com/media/bar_codes/base/white.png /home/clientsdevs/kaaruj.backend.clients.devsstream.com/media/bar_codes/base/out/out.png
test_path/home/clientsdevs/kaaruj.backend.clients.devsstream.com/media/bar_codes/base/white.png /home/clientsdevs/kaaruj.backend.clients.devsstream.com/media/bar_codes/base/out/out.png
test_path/home/clientsdevs/kaaruj.backend.clients.devsstream.com/media/bar_codes/base/white.png /home/clientsdevs/kaaruj.backend.clients.devsstream.com/media/bar_codes/base/out/out.png
test_path/home/clientsdevs/kaaruj.backend.clients.devsstream.com/media/bar_codes/base/white.png /home/clientsdevs/kaaruj.backend.clients.devsstream.com/media/bar_codes/base/out/out.png
test_path/home/clientsdevs/kaaruj.backend.clients.devsstream.com/media/bar_codes/base/white.png /home/clientsdevs/kaaruj.backend.clients.devsstream.com/media/bar_codes/base/out/out.png
test_path/home/clientsdevs/kaaruj.backend.clients.devsstream.com/media/bar_codes/base/white.png /home/clientsdevs/kaaruj.backend.clients.devsstream.com/media/bar_codes/base/out/out.png
test_path/home/clientsdevs/kaaruj.backend.clients.devsstream.com/media/bar_codes/base/white.png /home/clientsdevs/kaaruj.backend.clients.devsstream.com/media/bar_codes/base/out/out.png
test_path/home/clientsdevs/kaaruj.backend.clients.devsstream.com/media/bar_codes/base/white.png /home/clientsdevs/kaaruj.backend.clients.devsstream.com/media/bar_codes/base/out/out.png
Internal Server Error: /admin/coreapp/document/add/
Traceback (most recent call last):
  File "/Users/macmini/Phitron/backup12_07/venv/lib/python3.10/site-packages/django/core/handlers/exception.py", line 55, in inner
    response = get_response(request)
  File "/Users/macmini/Phitron/backup12_07/venv/lib/python3.10/site-packages/django/core/handlers/base.py", line 197, in _get_response
    response = wrapped_callback(request, *callback_args, **callback_kwargs)
  File "/Users/macmini/Phitron/backup12_07/venv/lib/python3.10/site-packages/django/contrib/admin/options.py", line 686, in wrapper
    return self.admin_site.admin_view(view)(*args, **kwargs)
  File "/Users/macmini/Phitron/backup12_07/venv/lib/python3.10/site-packages/django/utils/decorators.py", line 133, in _wrapped_view
    response = view_func(request, *args, **kwargs)
  File "/Users/macmini/Phitron/backup12_07/venv/lib/python3.10/site-packages/django/views/decorators/cache.py", line 62, in _wrapped_view_func
    response = view_func(request, *args, **kwargs)
  File "/Users/macmini/Phitron/backup12_07/venv/lib/python3.10/site-packages/django/contrib/admin/sites.py", line 242, in inner
    return view(request, *args, **kwargs)
  File "/Users/macmini/Phitron/backup12_07/venv/lib/python3.10/site-packages/django/contrib/admin/options.py", line 1890, in add_view
    return self.changeform_view(request, None, form_url, extra_context)
  File "/Users/macmini/Phitron/backup12_07/venv/lib/python3.10/site-packages/django/utils/decorators.py", line 46, in _wrapper
    return bound_method(*args, **kwargs)
  File "/Users/macmini/Phitron/backup12_07/venv/lib/python3.10/site-packages/django/utils/decorators.py", line 133, in _wrapped_view
    response = view_func(request, *args, **kwargs)
  File "/Users/macmini/Phitron/backup12_07/venv/lib/python3.10/site-packages/django/contrib/admin/options.py", line 1750, in changeform_view
    return self._changeform_view(request, object_id, form_url, extra_context)
  File "/Users/macmini/Phitron/backup12_07/venv/lib/python3.10/site-packages/django/contrib/admin/options.py", line 1802, in _changeform_view
    self.save_model(request, new_object, form, not add)
  File "/Users/macmini/Phitron/backup12_07/venv/lib/python3.10/site-packages/django/contrib/admin/options.py", line 1225, in save_model
    obj.save()
  File "/Users/macmini/Phitron/backup12_07/venv/lib/python3.10/site-packages/django/db/models/base.py", line 831, in save
    self.save_base(
  File "/Users/macmini/Phitron/backup12_07/venv/lib/python3.10/site-packages/django/db/models/base.py", line 882, in save_base
    updated = self._save_table(
  File "/Users/macmini/Phitron/backup12_07/venv/lib/python3.10/site-packages/django/db/models/base.py", line 1025, in _save_table
    results = self._do_insert(
  File "/Users/macmini/Phitron/backup12_07/venv/lib/python3.10/site-packages/django/db/models/base.py", line 1066, in _do_insert
    return manager._insert(
  File "/Users/macmini/Phitron/backup12_07/venv/lib/python3.10/site-packages/django/db/models/manager.py", line 85, in manager_method
    return getattr(self.get_queryset(), name)(*args, **kwargs)
  File "/Users/macmini/Phitron/backup12_07/venv/lib/python3.10/site-packages/django/db/models/query.py", line 1790, in _insert
    return query.get_compiler(using=using).execute_sql(returning_fields)
  File "/Users/macmini/Phitron/backup12_07/venv/lib/python3.10/site-packages/django/db/models/sql/compiler.py", line 1656, in execute_sql
    for sql, params in self.as_sql():
  File "/Users/macmini/Phitron/backup12_07/venv/lib/python3.10/site-packages/django/db/models/sql/compiler.py", line 1580, in as_sql
    value_rows = [
  File "/Users/macmini/Phitron/backup12_07/venv/lib/python3.10/site-packages/django/db/models/sql/compiler.py", line 1581, in <listcomp>
    [
  File "/Users/macmini/Phitron/backup12_07/venv/lib/python3.10/site-packages/django/db/models/sql/compiler.py", line 1582, in <listcomp>
    self.prepare_value(field, self.pre_save_val(field, obj))
  File "/Users/macmini/Phitron/backup12_07/venv/lib/python3.10/site-packages/django/db/models/sql/compiler.py", line 1530, in pre_save_val
    return field.pre_save(obj, add=True)
  File "/Users/macmini/Phitron/backup12_07/venv/lib/python3.10/site-packages/django/db/models/fields/files.py", line 316, in pre_save
    file.save(file.name, file.file, save=False)
  File "/Users/macmini/Phitron/backup12_07/venv/lib/python3.10/site-packages/django/db/models/fields/files.py", line 92, in save
    self.name = self.storage.save(name, content, max_length=self.field.max_length)
  File "/Users/macmini/Phitron/backup12_07/venv/lib/python3.10/site-packages/django/core/files/storage.py", line 56, in save
    name = self._save(name, content)
  File "/Users/macmini/Phitron/backup12_07/venv/lib/python3.10/site-packages/django/core/files/storage.py", line 295, in _save
    os.makedirs(directory, exist_ok=True)
  File "/Library/Frameworks/Python.framework/Versions/3.10/lib/python3.10/os.py", line 215, in makedirs
    makedirs(head, exist_ok=exist_ok)
  File "/Library/Frameworks/Python.framework/Versions/3.10/lib/python3.10/os.py", line 215, in makedirs
    makedirs(head, exist_ok=exist_ok)
  File "/Library/Frameworks/Python.framework/Versions/3.10/lib/python3.10/os.py", line 215, in makedirs
    makedirs(head, exist_ok=exist_ok)
  [Previous line repeated 3 more times]
  File "/Library/Frameworks/Python.framework/Versions/3.10/lib/python3.10/os.py", line 225, in makedirs
    mkdir(name, mode)
OSError: [Errno 45] Operation not supported: '/home/clientsdevs'
"POST /admin/coreapp/document/add/?_to_field=id&_popup=1 HTTP/1.1" 500 210327
Error in generate_product_barcode:  
 Traceback (most recent call last):
  File "/Users/macmini/Phitron/backup12_07/utility/utils/model_utils.py", line 117, in generate_product_barcode
    self.barcode.save(f"{self.name}.png", File(resized_buffer), save=False)
  File "/Users/macmini/Phitron/backup12_07/venv/lib/python3.10/site-packages/django/db/models/fields/files.py", line 92, in save
    self.name = self.storage.save(name, content, max_length=self.field.max_length)
  File "/Users/macmini/Phitron/backup12_07/venv/lib/python3.10/site-packages/django/core/files/storage.py", line 56, in save
    name = self._save(name, content)
  File "/Users/macmini/Phitron/backup12_07/venv/lib/python3.10/site-packages/django/core/files/storage.py", line 295, in _save
    os.makedirs(directory, exist_ok=True)
  File "/Library/Frameworks/Python.framework/Versions/3.10/lib/python3.10/os.py", line 215, in makedirs
    makedirs(head, exist_ok=exist_ok)
  File "/Library/Frameworks/Python.framework/Versions/3.10/lib/python3.10/os.py", line 215, in makedirs
    makedirs(head, exist_ok=exist_ok)
  File "/Library/Frameworks/Python.framework/Versions/3.10/lib/python3.10/os.py", line 215, in makedirs
    makedirs(head, exist_ok=exist_ok)
  [Previous line repeated 1 more time]
  File "/Library/Frameworks/Python.framework/Versions/3.10/lib/python3.10/os.py", line 225, in makedirs
    mkdir(name, mode)
OSError: [Errno 45] Operation not supported: '/home/clientsdevs'

Internal Server Error: /admin/inventory/products/add/
Traceback (most recent call last):
  File "/Users/macmini/Phitron/backup12_07/venv/lib/python3.10/site-packages/django/core/handlers/exception.py", line 55, in inner
    response = get_response(request)
  File "/Users/macmini/Phitron/backup12_07/venv/lib/python3.10/site-packages/django/core/handlers/base.py", line 197, in _get_response
    response = wrapped_callback(request, *callback_args, **callback_kwargs)
  File "/Users/macmini/Phitron/backup12_07/venv/lib/python3.10/site-packages/django/contrib/admin/options.py", line 686, in wrapper
    return self.admin_site.admin_view(view)(*args, **kwargs)
  File "/Users/macmini/Phitron/backup12_07/venv/lib/python3.10/site-packages/django/utils/decorators.py", line 133, in _wrapped_view
    response = view_func(request, *args, **kwargs)
  File "/Users/macmini/Phitron/backup12_07/venv/lib/python3.10/site-packages/django/views/decorators/cache.py", line 62, in _wrapped_view_func
    response = view_func(request, *args, **kwargs)
  File "/Users/macmini/Phitron/backup12_07/venv/lib/python3.10/site-packages/django/contrib/admin/sites.py", line 242, in inner
    return view(request, *args, **kwargs)
  File "/Users/macmini/Phitron/backup12_07/venv/lib/python3.10/site-packages/django/contrib/admin/options.py", line 1890, in add_view
    return self.changeform_view(request, None, form_url, extra_context)
  File "/Users/macmini/Phitron/backup12_07/venv/lib/python3.10/site-packages/django/utils/decorators.py", line 46, in _wrapper
    return bound_method(*args, **kwargs)
  File "/Users/macmini/Phitron/backup12_07/venv/lib/python3.10/site-packages/django/utils/decorators.py", line 133, in _wrapped_view
    response = view_func(request, *args, **kwargs)
  File "/Users/macmini/Phitron/backup12_07/venv/lib/python3.10/site-packages/django/contrib/admin/options.py", line 1750, in changeform_view
    return self._changeform_view(request, object_id, form_url, extra_context)
  File "/Users/macmini/Phitron/backup12_07/venv/lib/python3.10/site-packages/django/contrib/admin/options.py", line 1802, in _changeform_view
    self.save_model(request, new_object, form, not add)
  File "/Users/macmini/Phitron/backup12_07/venv/lib/python3.10/site-packages/django/contrib/admin/options.py", line 1225, in save_model
    obj.save()
  File "/Users/macmini/Phitron/backup12_07/inventory/models.py", line 65, in save
    model_utils.generate_qrcode(self,text)
  File "/Users/macmini/Phitron/backup12_07/utility/utils/model_utils.py", line 168, in generate_qrcode
    self.qr_code.save(fname, File(buffer), save=False)
  File "/Users/macmini/Phitron/backup12_07/venv/lib/python3.10/site-packages/django/db/models/fields/files.py", line 92, in save
    self.name = self.storage.save(name, content, max_length=self.field.max_length)
  File "/Users/macmini/Phitron/backup12_07/venv/lib/python3.10/site-packages/django/core/files/storage.py", line 56, in save
    name = self._save(name, content)
  File "/Users/macmini/Phitron/backup12_07/venv/lib/python3.10/site-packages/django/core/files/storage.py", line 295, in _save
    os.makedirs(directory, exist_ok=True)
  File "/Library/Frameworks/Python.framework/Versions/3.10/lib/python3.10/os.py", line 215, in makedirs
    makedirs(head, exist_ok=exist_ok)
  File "/Library/Frameworks/Python.framework/Versions/3.10/lib/python3.10/os.py", line 215, in makedirs
    makedirs(head, exist_ok=exist_ok)
  File "/Library/Frameworks/Python.framework/Versions/3.10/lib/python3.10/os.py", line 215, in makedirs
    makedirs(head, exist_ok=exist_ok)
  [Previous line repeated 1 more time]
  File "/Library/Frameworks/Python.framework/Versions/3.10/lib/python3.10/os.py", line 225, in makedirs
    mkdir(name, mode)
OSError: [Errno 45] Operation not supported: '/home/clientsdevs'
"POST /admin/inventory/products/add/ HTTP/1.1" 500 155387
Error in generate_product_barcode:  
 Traceback (most recent call last):
  File "/Users/macmini/Phitron/backup12_07/utility/utils/model_utils.py", line 117, in generate_product_barcode
    self.barcode.save(f"{self.name}.png", File(resized_buffer), save=False)
  File "/Users/macmini/Phitron/backup12_07/venv/lib/python3.10/site-packages/django/db/models/fields/files.py", line 92, in save
    self.name = self.storage.save(name, content, max_length=self.field.max_length)
  File "/Users/macmini/Phitron/backup12_07/venv/lib/python3.10/site-packages/django/core/files/storage.py", line 56, in save
    name = self._save(name, content)
  File "/Users/macmini/Phitron/backup12_07/venv/lib/python3.10/site-packages/django/core/files/storage.py", line 295, in _save
    os.makedirs(directory, exist_ok=True)
  File "/Library/Frameworks/Python.framework/Versions/3.10/lib/python3.10/os.py", line 215, in makedirs
    makedirs(head, exist_ok=exist_ok)
  File "/Library/Frameworks/Python.framework/Versions/3.10/lib/python3.10/os.py", line 215, in makedirs
    makedirs(head, exist_ok=exist_ok)
  File "/Library/Frameworks/Python.framework/Versions/3.10/lib/python3.10/os.py", line 215, in makedirs
    makedirs(head, exist_ok=exist_ok)
  [Previous line repeated 1 more time]
  File "/Library/Frameworks/Python.framework/Versions/3.10/lib/python3.10/os.py", line 225, in makedirs
    mkdir(name, mode)
OSError: [Errno 45] Operation not supported: '/home/clientsdevs'

Internal Server Error: /admin/inventory/products/add/
Traceback (most recent call last):
  File "/Users/macmini/Phitron/backup12_07/venv/lib/python3.10/site-packages/django/core/handlers/exception.py", line 55, in inner
    response = get_response(request)
  File "/Users/macmini/Phitron/backup12_07/venv/lib/python3.10/site-packages/django/core/handlers/base.py", line 197, in _get_response
    response = wrapped_callback(request, *callback_args, **callback_kwargs)
  File "/Users/macmini/Phitron/backup12_07/venv/lib/python3.10/site-packages/django/contrib/admin/options.py", line 686, in wrapper
    return self.admin_site.admin_view(view)(*args, **kwargs)
  File "/Users/macmini/Phitron/backup12_07/venv/lib/python3.10/site-packages/django/utils/decorators.py", line 133, in _wrapped_view
    response = view_func(request, *args, **kwargs)
  File "/Users/macmini/Phitron/backup12_07/venv/lib/python3.10/site-packages/django/views/decorators/cache.py", line 62, in _wrapped_view_func
    response = view_func(request, *args, **kwargs)
  File "/Users/macmini/Phitron/backup12_07/venv/lib/python3.10/site-packages/django/contrib/admin/sites.py", line 242, in inner
    return view(request, *args, **kwargs)
  File "/Users/macmini/Phitron/backup12_07/venv/lib/python3.10/site-packages/django/contrib/admin/options.py", line 1890, in add_view
    return self.changeform_view(request, None, form_url, extra_context)
  File "/Users/macmini/Phitron/backup12_07/venv/lib/python3.10/site-packages/django/utils/decorators.py", line 46, in _wrapper
    return bound_method(*args, **kwargs)
  File "/Users/macmini/Phitron/backup12_07/venv/lib/python3.10/site-packages/django/utils/decorators.py", line 133, in _wrapped_view
    response = view_func(request, *args, **kwargs)
  File "/Users/macmini/Phitron/backup12_07/venv/lib/python3.10/site-packages/django/contrib/admin/options.py", line 1750, in changeform_view
    return self._changeform_view(request, object_id, form_url, extra_context)
  File "/Users/macmini/Phitron/backup12_07/venv/lib/python3.10/site-packages/django/contrib/admin/options.py", line 1802, in _changeform_view
    self.save_model(request, new_object, form, not add)
  File "/Users/macmini/Phitron/backup12_07/venv/lib/python3.10/site-packages/django/contrib/admin/options.py", line 1225, in save_model
    obj.save()
  File "/Users/macmini/Phitron/backup12_07/inventory/models.py", line 65, in save
    model_utils.generate_qrcode(self,text)
  File "/Users/macmini/Phitron/backup12_07/utility/utils/model_utils.py", line 168, in generate_qrcode
    self.qr_code.save(fname, File(buffer), save=False)
  File "/Users/macmini/Phitron/backup12_07/venv/lib/python3.10/site-packages/django/db/models/fields/files.py", line 92, in save
    self.name = self.storage.save(name, content, max_length=self.field.max_length)
  File "/Users/macmini/Phitron/backup12_07/venv/lib/python3.10/site-packages/django/core/files/storage.py", line 56, in save
    name = self._save(name, content)
  File "/Users/macmini/Phitron/backup12_07/venv/lib/python3.10/site-packages/django/core/files/storage.py", line 295, in _save
    os.makedirs(directory, exist_ok=True)
  File "/Library/Frameworks/Python.framework/Versions/3.10/lib/python3.10/os.py", line 215, in makedirs
    makedirs(head, exist_ok=exist_ok)
  File "/Library/Frameworks/Python.framework/Versions/3.10/lib/python3.10/os.py", line 215, in makedirs
    makedirs(head, exist_ok=exist_ok)
  File "/Library/Frameworks/Python.framework/Versions/3.10/lib/python3.10/os.py", line 215, in makedirs
    makedirs(head, exist_ok=exist_ok)
  [Previous line repeated 1 more time]
  File "/Library/Frameworks/Python.framework/Versions/3.10/lib/python3.10/os.py", line 225, in makedirs
    mkdir(name, mode)
OSError: [Errno 45] Operation not supported: '/home/clientsdevs'
"POST /admin/inventory/products/add/ HTTP/1.1" 500 155543
test_path/absolute/path/to/media/root//bar_codes/base/white.png /absolute/path/to/media/root//bar_codes/base/out/out.png
test_path/absolute/path/to/media/root//bar_codes/base/white.png /absolute/path/to/media/root//bar_codes/base/out/out.png
Error in generate_product_barcode:  
 Traceback (most recent call last):
  File "/Users/macmini/Phitron/backup12_07/utility/utils/model_utils.py", line 117, in generate_product_barcode
    self.barcode.save(f"{self.name}.png", File(resized_buffer), save=False)
  File "/Users/macmini/Phitron/backup12_07/venv/lib/python3.10/site-packages/django/db/models/fields/files.py", line 92, in save
    self.name = self.storage.save(name, content, max_length=self.field.max_length)
  File "/Users/macmini/Phitron/backup12_07/venv/lib/python3.10/site-packages/django/core/files/storage.py", line 56, in save
    name = self._save(name, content)
  File "/Users/macmini/Phitron/backup12_07/venv/lib/python3.10/site-packages/django/core/files/storage.py", line 295, in _save
    os.makedirs(directory, exist_ok=True)
  File "/Library/Frameworks/Python.framework/Versions/3.10/lib/python3.10/os.py", line 215, in makedirs
    makedirs(head, exist_ok=exist_ok)
  File "/Library/Frameworks/Python.framework/Versions/3.10/lib/python3.10/os.py", line 215, in makedirs
    makedirs(head, exist_ok=exist_ok)
  File "/Library/Frameworks/Python.framework/Versions/3.10/lib/python3.10/os.py", line 215, in makedirs
    makedirs(head, exist_ok=exist_ok)
  [Previous line repeated 3 more times]
  File "/Library/Frameworks/Python.framework/Versions/3.10/lib/python3.10/os.py", line 225, in makedirs
    mkdir(name, mode)
OSError: [Errno 30] Read-only file system: '/absolute'

Internal Server Error: /admin/inventory/products/add/
Traceback (most recent call last):
  File "/Users/macmini/Phitron/backup12_07/venv/lib/python3.10/site-packages/django/core/handlers/exception.py", line 55, in inner
    response = get_response(request)
  File "/Users/macmini/Phitron/backup12_07/venv/lib/python3.10/site-packages/django/core/handlers/base.py", line 197, in _get_response
    response = wrapped_callback(request, *callback_args, **callback_kwargs)
  File "/Users/macmini/Phitron/backup12_07/venv/lib/python3.10/site-packages/django/contrib/admin/options.py", line 686, in wrapper
    return self.admin_site.admin_view(view)(*args, **kwargs)
  File "/Users/macmini/Phitron/backup12_07/venv/lib/python3.10/site-packages/django/utils/decorators.py", line 133, in _wrapped_view
    response = view_func(request, *args, **kwargs)
  File "/Users/macmini/Phitron/backup12_07/venv/lib/python3.10/site-packages/django/views/decorators/cache.py", line 62, in _wrapped_view_func
    response = view_func(request, *args, **kwargs)
  File "/Users/macmini/Phitron/backup12_07/venv/lib/python3.10/site-packages/django/contrib/admin/sites.py", line 242, in inner
    return view(request, *args, **kwargs)
  File "/Users/macmini/Phitron/backup12_07/venv/lib/python3.10/site-packages/django/contrib/admin/options.py", line 1890, in add_view
    return self.changeform_view(request, None, form_url, extra_context)
  File "/Users/macmini/Phitron/backup12_07/venv/lib/python3.10/site-packages/django/utils/decorators.py", line 46, in _wrapper
    return bound_method(*args, **kwargs)
  File "/Users/macmini/Phitron/backup12_07/venv/lib/python3.10/site-packages/django/utils/decorators.py", line 133, in _wrapped_view
    response = view_func(request, *args, **kwargs)
  File "/Users/macmini/Phitron/backup12_07/venv/lib/python3.10/site-packages/django/contrib/admin/options.py", line 1750, in changeform_view
    return self._changeform_view(request, object_id, form_url, extra_context)
  File "/Users/macmini/Phitron/backup12_07/venv/lib/python3.10/site-packages/django/contrib/admin/options.py", line 1802, in _changeform_view
    self.save_model(request, new_object, form, not add)
  File "/Users/macmini/Phitron/backup12_07/venv/lib/python3.10/site-packages/django/contrib/admin/options.py", line 1225, in save_model
    obj.save()
  File "/Users/macmini/Phitron/backup12_07/inventory/models.py", line 65, in save
    model_utils.generate_qrcode(self,text)
  File "/Users/macmini/Phitron/backup12_07/utility/utils/model_utils.py", line 168, in generate_qrcode
    self.qr_code.save(fname, File(buffer), save=False)
  File "/Users/macmini/Phitron/backup12_07/venv/lib/python3.10/site-packages/django/db/models/fields/files.py", line 92, in save
    self.name = self.storage.save(name, content, max_length=self.field.max_length)
  File "/Users/macmini/Phitron/backup12_07/venv/lib/python3.10/site-packages/django/core/files/storage.py", line 56, in save
    name = self._save(name, content)
  File "/Users/macmini/Phitron/backup12_07/venv/lib/python3.10/site-packages/django/core/files/storage.py", line 295, in _save
    os.makedirs(directory, exist_ok=True)
  File "/Library/Frameworks/Python.framework/Versions/3.10/lib/python3.10/os.py", line 215, in makedirs
    makedirs(head, exist_ok=exist_ok)
  File "/Library/Frameworks/Python.framework/Versions/3.10/lib/python3.10/os.py", line 215, in makedirs
    makedirs(head, exist_ok=exist_ok)
  File "/Library/Frameworks/Python.framework/Versions/3.10/lib/python3.10/os.py", line 215, in makedirs
    makedirs(head, exist_ok=exist_ok)
  [Previous line repeated 3 more times]
  File "/Library/Frameworks/Python.framework/Versions/3.10/lib/python3.10/os.py", line 225, in makedirs
    mkdir(name, mode)
OSError: [Errno 30] Read-only file system: '/absolute'
"POST /admin/inventory/products/add/ HTTP/1.1" 500 145
test_path/absolute/path/to/media/root//bar_codes/base/white.png /absolute/path/to/media/root//bar_codes/base/out/out.png
test_path/absolute/path/to/media/root//bar_codes/base/white.png /absolute/path/to/media/root//bar_codes/base/out/out.png
Error in generate_product_barcode:  
 Traceback (most recent call last):
  File "/Users/macmini/Phitron/backup12_07/utility/utils/model_utils.py", line 117, in generate_product_barcode
    self.barcode.save(f"{self.name}.png", File(resized_buffer), save=False)
  File "/Users/macmini/Phitron/backup12_07/venv/lib/python3.10/site-packages/django/db/models/fields/files.py", line 92, in save
    self.name = self.storage.save(name, content, max_length=self.field.max_length)
  File "/Users/macmini/Phitron/backup12_07/venv/lib/python3.10/site-packages/django/core/files/storage.py", line 56, in save
    name = self._save(name, content)
  File "/Users/macmini/Phitron/backup12_07/venv/lib/python3.10/site-packages/django/core/files/storage.py", line 295, in _save
    os.makedirs(directory, exist_ok=True)
  File "/Library/Frameworks/Python.framework/Versions/3.10/lib/python3.10/os.py", line 215, in makedirs
    makedirs(head, exist_ok=exist_ok)
  File "/Library/Frameworks/Python.framework/Versions/3.10/lib/python3.10/os.py", line 215, in makedirs
    makedirs(head, exist_ok=exist_ok)
  File "/Library/Frameworks/Python.framework/Versions/3.10/lib/python3.10/os.py", line 215, in makedirs
    makedirs(head, exist_ok=exist_ok)
  [Previous line repeated 3 more times]
  File "/Library/Frameworks/Python.framework/Versions/3.10/lib/python3.10/os.py", line 225, in makedirs
    mkdir(name, mode)
OSError: [Errno 30] Read-only file system: '/absolute'

Internal Server Error: /admin/inventory/products/add/
Traceback (most recent call last):
  File "/Users/macmini/Phitron/backup12_07/venv/lib/python3.10/site-packages/django/core/handlers/exception.py", line 55, in inner
    response = get_response(request)
  File "/Users/macmini/Phitron/backup12_07/venv/lib/python3.10/site-packages/django/core/handlers/base.py", line 197, in _get_response
    response = wrapped_callback(request, *callback_args, **callback_kwargs)
  File "/Users/macmini/Phitron/backup12_07/venv/lib/python3.10/site-packages/django/contrib/admin/options.py", line 686, in wrapper
    return self.admin_site.admin_view(view)(*args, **kwargs)
  File "/Users/macmini/Phitron/backup12_07/venv/lib/python3.10/site-packages/django/utils/decorators.py", line 133, in _wrapped_view
    response = view_func(request, *args, **kwargs)
  File "/Users/macmini/Phitron/backup12_07/venv/lib/python3.10/site-packages/django/views/decorators/cache.py", line 62, in _wrapped_view_func
    response = view_func(request, *args, **kwargs)
  File "/Users/macmini/Phitron/backup12_07/venv/lib/python3.10/site-packages/django/contrib/admin/sites.py", line 242, in inner
    return view(request, *args, **kwargs)
  File "/Users/macmini/Phitron/backup12_07/venv/lib/python3.10/site-packages/django/contrib/admin/options.py", line 1890, in add_view
    return self.changeform_view(request, None, form_url, extra_context)
  File "/Users/macmini/Phitron/backup12_07/venv/lib/python3.10/site-packages/django/utils/decorators.py", line 46, in _wrapper
    return bound_method(*args, **kwargs)
  File "/Users/macmini/Phitron/backup12_07/venv/lib/python3.10/site-packages/django/utils/decorators.py", line 133, in _wrapped_view
    response = view_func(request, *args, **kwargs)
  File "/Users/macmini/Phitron/backup12_07/venv/lib/python3.10/site-packages/django/contrib/admin/options.py", line 1750, in changeform_view
    return self._changeform_view(request, object_id, form_url, extra_context)
  File "/Users/macmini/Phitron/backup12_07/venv/lib/python3.10/site-packages/django/contrib/admin/options.py", line 1802, in _changeform_view
    self.save_model(request, new_object, form, not add)
  File "/Users/macmini/Phitron/backup12_07/venv/lib/python3.10/site-packages/django/contrib/admin/options.py", line 1225, in save_model
    obj.save()
  File "/Users/macmini/Phitron/backup12_07/inventory/models.py", line 65, in save
    model_utils.generate_qrcode(self,text)
  File "/Users/macmini/Phitron/backup12_07/utility/utils/model_utils.py", line 168, in generate_qrcode
    self.qr_code.save(fname, File(buffer), save=False)
  File "/Users/macmini/Phitron/backup12_07/venv/lib/python3.10/site-packages/django/db/models/fields/files.py", line 92, in save
    self.name = self.storage.save(name, content, max_length=self.field.max_length)
  File "/Users/macmini/Phitron/backup12_07/venv/lib/python3.10/site-packages/django/core/files/storage.py", line 56, in save
    name = self._save(name, content)
  File "/Users/macmini/Phitron/backup12_07/venv/lib/python3.10/site-packages/django/core/files/storage.py", line 295, in _save
    os.makedirs(directory, exist_ok=True)
  File "/Library/Frameworks/Python.framework/Versions/3.10/lib/python3.10/os.py", line 215, in makedirs
    makedirs(head, exist_ok=exist_ok)
  File "/Library/Frameworks/Python.framework/Versions/3.10/lib/python3.10/os.py", line 215, in makedirs
    makedirs(head, exist_ok=exist_ok)
  File "/Library/Frameworks/Python.framework/Versions/3.10/lib/python3.10/os.py", line 215, in makedirs
    makedirs(head, exist_ok=exist_ok)
  [Previous line repeated 3 more times]
  File "/Library/Frameworks/Python.framework/Versions/3.10/lib/python3.10/os.py", line 225, in makedirs
    mkdir(name, mode)
OSError: [Errno 30] Read-only file system: '/absolute'
"POST /admin/inventory/products/add/ HTTP/1.1" 500 145
Error in generate_product_barcode:  
 Traceback (most recent call last):
  File "/Users/macmini/Phitron/backup12_07/utility/utils/model_utils.py", line 117, in generate_product_barcode
    self.barcode.save(f"{self.name}.png", File(resized_buffer), save=False)
  File "/Users/macmini/Phitron/backup12_07/venv/lib/python3.10/site-packages/django/db/models/fields/files.py", line 92, in save
    self.name = self.storage.save(name, content, max_length=self.field.max_length)
  File "/Users/macmini/Phitron/backup12_07/venv/lib/python3.10/site-packages/django/core/files/storage.py", line 56, in save
    name = self._save(name, content)
  File "/Users/macmini/Phitron/backup12_07/venv/lib/python3.10/site-packages/django/core/files/storage.py", line 295, in _save
    os.makedirs(directory, exist_ok=True)
  File "/Library/Frameworks/Python.framework/Versions/3.10/lib/python3.10/os.py", line 215, in makedirs
    makedirs(head, exist_ok=exist_ok)
  File "/Library/Frameworks/Python.framework/Versions/3.10/lib/python3.10/os.py", line 215, in makedirs
    makedirs(head, exist_ok=exist_ok)
  File "/Library/Frameworks/Python.framework/Versions/3.10/lib/python3.10/os.py", line 215, in makedirs
    makedirs(head, exist_ok=exist_ok)
  [Previous line repeated 3 more times]
  File "/Library/Frameworks/Python.framework/Versions/3.10/lib/python3.10/os.py", line 225, in makedirs
    mkdir(name, mode)
OSError: [Errno 30] Read-only file system: '/absolute'

Internal Server Error: /admin/inventory/products/add/
Traceback (most recent call last):
  File "/Users/macmini/Phitron/backup12_07/venv/lib/python3.10/site-packages/django/core/handlers/exception.py", line 55, in inner
    response = get_response(request)
  File "/Users/macmini/Phitron/backup12_07/venv/lib/python3.10/site-packages/django/core/handlers/base.py", line 197, in _get_response
    response = wrapped_callback(request, *callback_args, **callback_kwargs)
  File "/Users/macmini/Phitron/backup12_07/venv/lib/python3.10/site-packages/django/contrib/admin/options.py", line 686, in wrapper
    return self.admin_site.admin_view(view)(*args, **kwargs)
  File "/Users/macmini/Phitron/backup12_07/venv/lib/python3.10/site-packages/django/utils/decorators.py", line 133, in _wrapped_view
    response = view_func(request, *args, **kwargs)
  File "/Users/macmini/Phitron/backup12_07/venv/lib/python3.10/site-packages/django/views/decorators/cache.py", line 62, in _wrapped_view_func
    response = view_func(request, *args, **kwargs)
  File "/Users/macmini/Phitron/backup12_07/venv/lib/python3.10/site-packages/django/contrib/admin/sites.py", line 242, in inner
    return view(request, *args, **kwargs)
  File "/Users/macmini/Phitron/backup12_07/venv/lib/python3.10/site-packages/django/contrib/admin/options.py", line 1890, in add_view
    return self.changeform_view(request, None, form_url, extra_context)
  File "/Users/macmini/Phitron/backup12_07/venv/lib/python3.10/site-packages/django/utils/decorators.py", line 46, in _wrapper
    return bound_method(*args, **kwargs)
  File "/Users/macmini/Phitron/backup12_07/venv/lib/python3.10/site-packages/django/utils/decorators.py", line 133, in _wrapped_view
    response = view_func(request, *args, **kwargs)
  File "/Users/macmini/Phitron/backup12_07/venv/lib/python3.10/site-packages/django/contrib/admin/options.py", line 1750, in changeform_view
    return self._changeform_view(request, object_id, form_url, extra_context)
  File "/Users/macmini/Phitron/backup12_07/venv/lib/python3.10/site-packages/django/contrib/admin/options.py", line 1802, in _changeform_view
    self.save_model(request, new_object, form, not add)
  File "/Users/macmini/Phitron/backup12_07/venv/lib/python3.10/site-packages/django/contrib/admin/options.py", line 1225, in save_model
    obj.save()
  File "/Users/macmini/Phitron/backup12_07/inventory/models.py", line 65, in save
    model_utils.generate_qrcode(self,text)
  File "/Users/macmini/Phitron/backup12_07/utility/utils/model_utils.py", line 168, in generate_qrcode
    self.qr_code.save(fname, File(buffer), save=False)
  File "/Users/macmini/Phitron/backup12_07/venv/lib/python3.10/site-packages/django/db/models/fields/files.py", line 92, in save
    self.name = self.storage.save(name, content, max_length=self.field.max_length)
  File "/Users/macmini/Phitron/backup12_07/venv/lib/python3.10/site-packages/django/core/files/storage.py", line 56, in save
    name = self._save(name, content)
  File "/Users/macmini/Phitron/backup12_07/venv/lib/python3.10/site-packages/django/core/files/storage.py", line 295, in _save
    os.makedirs(directory, exist_ok=True)
  File "/Library/Frameworks/Python.framework/Versions/3.10/lib/python3.10/os.py", line 215, in makedirs
    makedirs(head, exist_ok=exist_ok)
  File "/Library/Frameworks/Python.framework/Versions/3.10/lib/python3.10/os.py", line 215, in makedirs
    makedirs(head, exist_ok=exist_ok)
  File "/Library/Frameworks/Python.framework/Versions/3.10/lib/python3.10/os.py", line 215, in makedirs
    makedirs(head, exist_ok=exist_ok)
  [Previous line repeated 3 more times]
  File "/Library/Frameworks/Python.framework/Versions/3.10/lib/python3.10/os.py", line 225, in makedirs
    mkdir(name, mode)
OSError: [Errno 30] Read-only file system: '/absolute'
"POST /admin/inventory/products/add/ HTTP/1.1" 500 145
Error in generate_product_barcode:  
 Traceback (most recent call last):
  File "/Users/macmini/Phitron/backup12_07/utility/utils/model_utils.py", line 117, in generate_product_barcode
    self.barcode.save(f"{self.name}.png", File(resized_buffer), save=False)
  File "/Users/macmini/Phitron/backup12_07/venv/lib/python3.10/site-packages/django/db/models/fields/files.py", line 92, in save
    self.name = self.storage.save(name, content, max_length=self.field.max_length)
  File "/Users/macmini/Phitron/backup12_07/venv/lib/python3.10/site-packages/django/core/files/storage.py", line 56, in save
    name = self._save(name, content)
  File "/Users/macmini/Phitron/backup12_07/venv/lib/python3.10/site-packages/django/core/files/storage.py", line 295, in _save
    os.makedirs(directory, exist_ok=True)
  File "/Library/Frameworks/Python.framework/Versions/3.10/lib/python3.10/os.py", line 215, in makedirs
    makedirs(head, exist_ok=exist_ok)
  File "/Library/Frameworks/Python.framework/Versions/3.10/lib/python3.10/os.py", line 215, in makedirs
    makedirs(head, exist_ok=exist_ok)
  File "/Library/Frameworks/Python.framework/Versions/3.10/lib/python3.10/os.py", line 215, in makedirs
    makedirs(head, exist_ok=exist_ok)
  [Previous line repeated 3 more times]
  File "/Library/Frameworks/Python.framework/Versions/3.10/lib/python3.10/os.py", line 225, in makedirs
    mkdir(name, mode)
OSError: [Errno 30] Read-only file system: '/absolute'

Internal Server Error: /admin/inventory/products/add/
Traceback (most recent call last):
  File "/Users/macmini/Phitron/backup12_07/venv/lib/python3.10/site-packages/django/core/handlers/exception.py", line 55, in inner
    response = get_response(request)
  File "/Users/macmini/Phitron/backup12_07/venv/lib/python3.10/site-packages/django/core/handlers/base.py", line 197, in _get_response
    response = wrapped_callback(request, *callback_args, **callback_kwargs)
  File "/Users/macmini/Phitron/backup12_07/venv/lib/python3.10/site-packages/django/contrib/admin/options.py", line 686, in wrapper
    return self.admin_site.admin_view(view)(*args, **kwargs)
  File "/Users/macmini/Phitron/backup12_07/venv/lib/python3.10/site-packages/django/utils/decorators.py", line 133, in _wrapped_view
    response = view_func(request, *args, **kwargs)
  File "/Users/macmini/Phitron/backup12_07/venv/lib/python3.10/site-packages/django/views/decorators/cache.py", line 62, in _wrapped_view_func
    response = view_func(request, *args, **kwargs)
  File "/Users/macmini/Phitron/backup12_07/venv/lib/python3.10/site-packages/django/contrib/admin/sites.py", line 242, in inner
    return view(request, *args, **kwargs)
  File "/Users/macmini/Phitron/backup12_07/venv/lib/python3.10/site-packages/django/contrib/admin/options.py", line 1890, in add_view
    return self.changeform_view(request, None, form_url, extra_context)
  File "/Users/macmini/Phitron/backup12_07/venv/lib/python3.10/site-packages/django/utils/decorators.py", line 46, in _wrapper
    return bound_method(*args, **kwargs)
  File "/Users/macmini/Phitron/backup12_07/venv/lib/python3.10/site-packages/django/utils/decorators.py", line 133, in _wrapped_view
    response = view_func(request, *args, **kwargs)
  File "/Users/macmini/Phitron/backup12_07/venv/lib/python3.10/site-packages/django/contrib/admin/options.py", line 1750, in changeform_view
    return self._changeform_view(request, object_id, form_url, extra_context)
  File "/Users/macmini/Phitron/backup12_07/venv/lib/python3.10/site-packages/django/contrib/admin/options.py", line 1802, in _changeform_view
    self.save_model(request, new_object, form, not add)
  File "/Users/macmini/Phitron/backup12_07/venv/lib/python3.10/site-packages/django/contrib/admin/options.py", line 1225, in save_model
    obj.save()
  File "/Users/macmini/Phitron/backup12_07/inventory/models.py", line 65, in save
    model_utils.generate_qrcode(self,text)
  File "/Users/macmini/Phitron/backup12_07/utility/utils/model_utils.py", line 168, in generate_qrcode
    self.qr_code.save(fname, File(buffer), save=False)
  File "/Users/macmini/Phitron/backup12_07/venv/lib/python3.10/site-packages/django/db/models/fields/files.py", line 92, in save
    self.name = self.storage.save(name, content, max_length=self.field.max_length)
  File "/Users/macmini/Phitron/backup12_07/venv/lib/python3.10/site-packages/django/core/files/storage.py", line 56, in save
    name = self._save(name, content)
  File "/Users/macmini/Phitron/backup12_07/venv/lib/python3.10/site-packages/django/core/files/storage.py", line 295, in _save
    os.makedirs(directory, exist_ok=True)
  File "/Library/Frameworks/Python.framework/Versions/3.10/lib/python3.10/os.py", line 215, in makedirs
    makedirs(head, exist_ok=exist_ok)
  File "/Library/Frameworks/Python.framework/Versions/3.10/lib/python3.10/os.py", line 215, in makedirs
    makedirs(head, exist_ok=exist_ok)
  File "/Library/Frameworks/Python.framework/Versions/3.10/lib/python3.10/os.py", line 215, in makedirs
    makedirs(head, exist_ok=exist_ok)
  [Previous line repeated 3 more times]
  File "/Library/Frameworks/Python.framework/Versions/3.10/lib/python3.10/os.py", line 225, in makedirs
    mkdir(name, mode)
OSError: [Errno 30] Read-only file system: '/absolute'
"POST /admin/inventory/products/add/ HTTP/1.1" 500 145
test_path/absolute/path/to/media/root//bar_codes/base/white.png /absolute/path/to/media/root//bar_codes/base/out/out.png
test_path/absolute/path/to/media/root//bar_codes/base/white.png /absolute/path/to/media/root//bar_codes/base/out/out.png
Error in generate_product_barcode:  
 Traceback (most recent call last):
  File "/Users/macmini/Phitron/backup12_07/utility/utils/model_utils.py", line 117, in generate_product_barcode
    self.barcode.save(f"{self.name}.png", File(resized_buffer), save=False)
  File "/Users/macmini/Phitron/backup12_07/venv/lib/python3.10/site-packages/django/db/models/fields/files.py", line 92, in save
    self.name = self.storage.save(name, content, max_length=self.field.max_length)
  File "/Users/macmini/Phitron/backup12_07/venv/lib/python3.10/site-packages/django/core/files/storage.py", line 56, in save
    name = self._save(name, content)
  File "/Users/macmini/Phitron/backup12_07/venv/lib/python3.10/site-packages/django/core/files/storage.py", line 295, in _save
    os.makedirs(directory, exist_ok=True)
  File "/Library/Frameworks/Python.framework/Versions/3.10/lib/python3.10/os.py", line 215, in makedirs
    makedirs(head, exist_ok=exist_ok)
  File "/Library/Frameworks/Python.framework/Versions/3.10/lib/python3.10/os.py", line 215, in makedirs
    makedirs(head, exist_ok=exist_ok)
  File "/Library/Frameworks/Python.framework/Versions/3.10/lib/python3.10/os.py", line 215, in makedirs
    makedirs(head, exist_ok=exist_ok)
  [Previous line repeated 3 more times]
  File "/Library/Frameworks/Python.framework/Versions/3.10/lib/python3.10/os.py", line 225, in makedirs
    mkdir(name, mode)
OSError: [Errno 30] Read-only file system: '/absolute'

Internal Server Error: /admin/inventory/products/add/
Traceback (most recent call last):
  File "/Users/macmini/Phitron/backup12_07/venv/lib/python3.10/site-packages/django/core/handlers/exception.py", line 55, in inner
    response = get_response(request)
  File "/Users/macmini/Phitron/backup12_07/venv/lib/python3.10/site-packages/django/core/handlers/base.py", line 197, in _get_response
    response = wrapped_callback(request, *callback_args, **callback_kwargs)
  File "/Users/macmini/Phitron/backup12_07/venv/lib/python3.10/site-packages/django/contrib/admin/options.py", line 686, in wrapper
    return self.admin_site.admin_view(view)(*args, **kwargs)
  File "/Users/macmini/Phitron/backup12_07/venv/lib/python3.10/site-packages/django/utils/decorators.py", line 133, in _wrapped_view
    response = view_func(request, *args, **kwargs)
  File "/Users/macmini/Phitron/backup12_07/venv/lib/python3.10/site-packages/django/views/decorators/cache.py", line 62, in _wrapped_view_func
    response = view_func(request, *args, **kwargs)
  File "/Users/macmini/Phitron/backup12_07/venv/lib/python3.10/site-packages/django/contrib/admin/sites.py", line 242, in inner
    return view(request, *args, **kwargs)
  File "/Users/macmini/Phitron/backup12_07/venv/lib/python3.10/site-packages/django/contrib/admin/options.py", line 1890, in add_view
    return self.changeform_view(request, None, form_url, extra_context)
  File "/Users/macmini/Phitron/backup12_07/venv/lib/python3.10/site-packages/django/utils/decorators.py", line 46, in _wrapper
    return bound_method(*args, **kwargs)
  File "/Users/macmini/Phitron/backup12_07/venv/lib/python3.10/site-packages/django/utils/decorators.py", line 133, in _wrapped_view
    response = view_func(request, *args, **kwargs)
  File "/Users/macmini/Phitron/backup12_07/venv/lib/python3.10/site-packages/django/contrib/admin/options.py", line 1750, in changeform_view
    return self._changeform_view(request, object_id, form_url, extra_context)
  File "/Users/macmini/Phitron/backup12_07/venv/lib/python3.10/site-packages/django/contrib/admin/options.py", line 1802, in _changeform_view
    self.save_model(request, new_object, form, not add)
  File "/Users/macmini/Phitron/backup12_07/venv/lib/python3.10/site-packages/django/contrib/admin/options.py", line 1225, in save_model
    obj.save()
  File "/Users/macmini/Phitron/backup12_07/inventory/models.py", line 65, in save
    model_utils.generate_qrcode(self,text)
  File "/Users/macmini/Phitron/backup12_07/utility/utils/model_utils.py", line 168, in generate_qrcode
    self.qr_code.save(fname, File(buffer), save=False)
  File "/Users/macmini/Phitron/backup12_07/venv/lib/python3.10/site-packages/django/db/models/fields/files.py", line 92, in save
    self.name = self.storage.save(name, content, max_length=self.field.max_length)
  File "/Users/macmini/Phitron/backup12_07/venv/lib/python3.10/site-packages/django/core/files/storage.py", line 56, in save
    name = self._save(name, content)
  File "/Users/macmini/Phitron/backup12_07/venv/lib/python3.10/site-packages/django/core/files/storage.py", line 295, in _save
    os.makedirs(directory, exist_ok=True)
  File "/Library/Frameworks/Python.framework/Versions/3.10/lib/python3.10/os.py", line 215, in makedirs
    makedirs(head, exist_ok=exist_ok)
  File "/Library/Frameworks/Python.framework/Versions/3.10/lib/python3.10/os.py", line 215, in makedirs
    makedirs(head, exist_ok=exist_ok)
  File "/Library/Frameworks/Python.framework/Versions/3.10/lib/python3.10/os.py", line 215, in makedirs
    makedirs(head, exist_ok=exist_ok)
  [Previous line repeated 3 more times]
  File "/Library/Frameworks/Python.framework/Versions/3.10/lib/python3.10/os.py", line 225, in makedirs
    mkdir(name, mode)
OSError: [Errno 30] Read-only file system: '/absolute'
"POST /admin/inventory/products/add/ HTTP/1.1" 500 163161
Error in generate_product_barcode:  
 Traceback (most recent call last):
  File "/Users/macmini/Phitron/backup12_07/utility/utils/model_utils.py", line 117, in generate_product_barcode
    self.barcode.save(f"{self.name}.png", File(resized_buffer), save=False)
  File "/Users/macmini/Phitron/backup12_07/venv/lib/python3.10/site-packages/django/db/models/fields/files.py", line 92, in save
    self.name = self.storage.save(name, content, max_length=self.field.max_length)
  File "/Users/macmini/Phitron/backup12_07/venv/lib/python3.10/site-packages/django/core/files/storage.py", line 56, in save
    name = self._save(name, content)
  File "/Users/macmini/Phitron/backup12_07/venv/lib/python3.10/site-packages/django/core/files/storage.py", line 295, in _save
    os.makedirs(directory, exist_ok=True)
  File "/Library/Frameworks/Python.framework/Versions/3.10/lib/python3.10/os.py", line 215, in makedirs
    makedirs(head, exist_ok=exist_ok)
  File "/Library/Frameworks/Python.framework/Versions/3.10/lib/python3.10/os.py", line 215, in makedirs
    makedirs(head, exist_ok=exist_ok)
  File "/Library/Frameworks/Python.framework/Versions/3.10/lib/python3.10/os.py", line 215, in makedirs
    makedirs(head, exist_ok=exist_ok)
  [Previous line repeated 3 more times]
  File "/Library/Frameworks/Python.framework/Versions/3.10/lib/python3.10/os.py", line 225, in makedirs
    mkdir(name, mode)
OSError: [Errno 30] Read-only file system: '/absolute'

Internal Server Error: /admin/inventory/products/add/
Traceback (most recent call last):
  File "/Users/macmini/Phitron/backup12_07/venv/lib/python3.10/site-packages/django/core/handlers/exception.py", line 55, in inner
    response = get_response(request)
  File "/Users/macmini/Phitron/backup12_07/venv/lib/python3.10/site-packages/django/core/handlers/base.py", line 197, in _get_response
    response = wrapped_callback(request, *callback_args, **callback_kwargs)
  File "/Users/macmini/Phitron/backup12_07/venv/lib/python3.10/site-packages/django/contrib/admin/options.py", line 686, in wrapper
    return self.admin_site.admin_view(view)(*args, **kwargs)
  File "/Users/macmini/Phitron/backup12_07/venv/lib/python3.10/site-packages/django/utils/decorators.py", line 133, in _wrapped_view
    response = view_func(request, *args, **kwargs)
  File "/Users/macmini/Phitron/backup12_07/venv/lib/python3.10/site-packages/django/views/decorators/cache.py", line 62, in _wrapped_view_func
    response = view_func(request, *args, **kwargs)
  File "/Users/macmini/Phitron/backup12_07/venv/lib/python3.10/site-packages/django/contrib/admin/sites.py", line 242, in inner
    return view(request, *args, **kwargs)
  File "/Users/macmini/Phitron/backup12_07/venv/lib/python3.10/site-packages/django/contrib/admin/options.py", line 1890, in add_view
    return self.changeform_view(request, None, form_url, extra_context)
  File "/Users/macmini/Phitron/backup12_07/venv/lib/python3.10/site-packages/django/utils/decorators.py", line 46, in _wrapper
    return bound_method(*args, **kwargs)
  File "/Users/macmini/Phitron/backup12_07/venv/lib/python3.10/site-packages/django/utils/decorators.py", line 133, in _wrapped_view
    response = view_func(request, *args, **kwargs)
  File "/Users/macmini/Phitron/backup12_07/venv/lib/python3.10/site-packages/django/contrib/admin/options.py", line 1750, in changeform_view
    return self._changeform_view(request, object_id, form_url, extra_context)
  File "/Users/macmini/Phitron/backup12_07/venv/lib/python3.10/site-packages/django/contrib/admin/options.py", line 1802, in _changeform_view
    self.save_model(request, new_object, form, not add)
  File "/Users/macmini/Phitron/backup12_07/venv/lib/python3.10/site-packages/django/contrib/admin/options.py", line 1225, in save_model
    obj.save()
  File "/Users/macmini/Phitron/backup12_07/inventory/models.py", line 65, in save
    model_utils.generate_qrcode(self,text)
  File "/Users/macmini/Phitron/backup12_07/utility/utils/model_utils.py", line 168, in generate_qrcode
    self.qr_code.save(fname, File(buffer), save=False)
  File "/Users/macmini/Phitron/backup12_07/venv/lib/python3.10/site-packages/django/db/models/fields/files.py", line 92, in save
    self.name = self.storage.save(name, content, max_length=self.field.max_length)
  File "/Users/macmini/Phitron/backup12_07/venv/lib/python3.10/site-packages/django/core/files/storage.py", line 56, in save
    name = self._save(name, content)
  File "/Users/macmini/Phitron/backup12_07/venv/lib/python3.10/site-packages/django/core/files/storage.py", line 295, in _save
    os.makedirs(directory, exist_ok=True)
  File "/Library/Frameworks/Python.framework/Versions/3.10/lib/python3.10/os.py", line 215, in makedirs
    makedirs(head, exist_ok=exist_ok)
  File "/Library/Frameworks/Python.framework/Versions/3.10/lib/python3.10/os.py", line 215, in makedirs
    makedirs(head, exist_ok=exist_ok)
  File "/Library/Frameworks/Python.framework/Versions/3.10/lib/python3.10/os.py", line 215, in makedirs
    makedirs(head, exist_ok=exist_ok)
  [Previous line repeated 3 more times]
  File "/Library/Frameworks/Python.framework/Versions/3.10/lib/python3.10/os.py", line 225, in makedirs
    mkdir(name, mode)
OSError: [Errno 30] Read-only file system: '/absolute'
"POST /admin/inventory/products/add/ HTTP/1.1" 500 163164
test_path/media/root//bar_codes/base/white.png /media/root//bar_codes/base/out/out.png
test_path/bar_codes/base/white.png /bar_codes/base/out/out.png
test_path/bar_codes/base/white.png /bar_codes/base/out/out.png
Error in generate_product_barcode:  
 Traceback (most recent call last):
  File "/Users/macmini/Phitron/backup12_07/utility/utils/bar_image_utils.py", line 59, in add_images_and_text
    modified_image = insert_text(image_path, text, output_path, size=30, add_x=0, position_y=2,color='white')
  File "/Users/macmini/Phitron/backup12_07/utility/utils/bar_image_utils.py", line 6, in insert_text
    image = Image.open(image_path)
  File "/Users/macmini/Phitron/backup12_07/venv/lib/python3.10/site-packages/PIL/Image.py", line 3218, in open
    fp = builtins.open(filename, "rb")
FileNotFoundError: [Errno 2] No such file or directory: '/bar_codes/base/white.png'

Error in generate_product_barcode:  
 Traceback (most recent call last):
  File "/Users/macmini/Phitron/backup12_07/utility/utils/bar_image_utils.py", line 59, in add_images_and_text
    modified_image = insert_text(image_path, text, output_path, size=30, add_x=0, position_y=2,color='white')
  File "/Users/macmini/Phitron/backup12_07/utility/utils/bar_image_utils.py", line 6, in insert_text
    image = Image.open(image_path)
  File "/Users/macmini/Phitron/backup12_07/venv/lib/python3.10/site-packages/PIL/Image.py", line 3218, in open
    fp = builtins.open(filename, "rb")
FileNotFoundError: [Errno 2] No such file or directory: '/bar_codes/base/white.png'

Error in generate_product_barcode:  
 Traceback (most recent call last):
  File "/Users/macmini/Phitron/backup12_07/utility/utils/bar_image_utils.py", line 59, in add_images_and_text
    modified_image = insert_text(image_path, text, output_path, size=30, add_x=0, position_y=2,color='white')
  File "/Users/macmini/Phitron/backup12_07/utility/utils/bar_image_utils.py", line 6, in insert_text
    image = Image.open(image_path)
  File "/Users/macmini/Phitron/backup12_07/venv/lib/python3.10/site-packages/PIL/Image.py", line 3218, in open
    fp = builtins.open(filename, "rb")
FileNotFoundError: [Errno 2] No such file or directory: '/bar_codes/base/white.png'

test_path/bar_codes/base/white.png /bar_codes/base/out/out.png
test_path/bar_codes/base/white.png /bar_codes/base/out/out.png
test_path/bar_codes/base/white.png /bar_codes/base/out/out.png
test_path/bar_codes/base/white.png /bar_codes/base/out/out.png
test_path/bar_codes/base/white.png /bar_codes/base/out/out.png
test_path/bar_codes/base/white.png /bar_codes/base/out/out.png
Error in generate_product_barcode:  
 Traceback (most recent call last):
  File "/Users/macmini/Phitron/backup12_07/utility/utils/bar_image_utils.py", line 59, in add_images_and_text
    modified_image = insert_text(image_path, text, output_path, size=30, add_x=0, position_y=2,color='white')
  File "/Users/macmini/Phitron/backup12_07/utility/utils/bar_image_utils.py", line 6, in insert_text
    image = Image.open(image_path)
  File "/Users/macmini/Phitron/backup12_07/venv/lib/python3.10/site-packages/PIL/Image.py", line 3218, in open
    fp = builtins.open(filename, "rb")
FileNotFoundError: [Errno 2] No such file or directory: '/bar_codes/base/white.png'

test_path/bar_codes/base/white.png /bar_codes/base/out/out.png
test_path/bar_codes/base/white.png /bar_codes/base/out/out.png
test_path/bar_codes/base/white.png /bar_codes/base/out/out.png
test_path/bar_codes/base/white.png /bar_codes/base/out/out.png
test_path/bar_codes/base/white.png /bar_codes/base/out/out.png
Error in generate_product_barcode:  
 Traceback (most recent call last):
  File "/Users/macmini/Phitron/backup12_07/utility/utils/bar_image_utils.py", line 59, in add_images_and_text
    modified_image = insert_text(image_path, text, output_path, size=30, add_x=0, position_y=2,color='white')
  File "/Users/macmini/Phitron/backup12_07/utility/utils/bar_image_utils.py", line 6, in insert_text
    image = Image.open(image_path)
  File "/Users/macmini/Phitron/backup12_07/venv/lib/python3.10/site-packages/PIL/Image.py", line 3218, in open
    fp = builtins.open(filename, "rb")
FileNotFoundError: [Errno 2] No such file or directory: '/bar_codes/base/white.png'

test_path/bar_codes/base/white.png /bar_codes/base/out/out.png
test_path/bar_codes/base/white.png /bar_codes/base/out/out.png
test_path/bar_codes/base/white.png /bar_codes/base/out/out.png
test_path/bar_codes/base/white.png /bar_codes/base/out/out.png
test_path/bar_codes/base/white.png /bar_codes/base/out/out.png
test_path/bar_codes/base/white.png /bar_codes/base/out/out.png
test_path/bar_codes/base/white.png /bar_codes/base/out/out.png
test_path/bar_codes/base/white.png /bar_codes/base/out/out.png
test_path/bar_codes/base/white.png /bar_codes/base/out/out.png
test_path/bar_codes/base/white.png /bar_codes/base/out/out.png
---------Stock update issue---------
[ErrorDetail(string='Insufficient stock for product: pro 1', code='invalid')]
test_path/bar_codes/base/white.png /bar_codes/base/out/out.png
test_path/bar_codes/base/white.png /bar_codes/base/out/out.png
test_path/bar_codes/base/white.png /bar_codes/base/out/out.png
test_path/bar_codes/base/white.png /bar_codes/base/out/out.png
test_path/bar_codes/base/white.png /bar_codes/base/out/out.png
test_path/bar_codes/base/white.png /bar_codes/base/out/out.png
test_path/bar_codes/base/white.png /bar_codes/base/out/out.png
test_path/bar_codes/base/white.png /bar_codes/base/out/out.png
test_path/bar_codes/base/white.png /bar_codes/base/out/out.png
test_path/bar_codes/base/white.png /bar_codes/base/out/out.png
test_path/bar_codes/base/white.png /bar_codes/base/out/out.png
test_path/bar_codes/base/white.png /bar_codes/base/out/out.png
test_path/bar_codes/base/white.png /bar_codes/base/out/out.png
Internal Server Error: /admin/
Traceback (most recent call last):
  File "/Users/macmini/Phitron/backup12_07/venv/lib/python3.10/site-packages/django/contrib/sessions/backends/base.py", line 187, in _get_session
    return self._session_cache
AttributeError: 'SessionStore' object has no attribute '_session_cache'

During handling of the above exception, another exception occurred:

Traceback (most recent call last):
  File "/Users/macmini/Phitron/backup12_07/venv/lib/python3.10/site-packages/django/db/backends/utils.py", line 89, in _execute
    return self.cursor.execute(sql, params)
  File "/Users/macmini/Phitron/backup12_07/venv/lib/python3.10/site-packages/django/db/backends/sqlite3/base.py", line 357, in execute
    return Database.Cursor.execute(self, query, params)
sqlite3.OperationalError: no such table: django_session

The above exception was the direct cause of the following exception:

Traceback (most recent call last):
  File "/Users/macmini/Phitron/backup12_07/venv/lib/python3.10/site-packages/django/core/handlers/exception.py", line 55, in inner
    response = get_response(request)
  File "/Users/macmini/Phitron/backup12_07/venv/lib/python3.10/site-packages/django/core/handlers/base.py", line 197, in _get_response
    response = wrapped_callback(request, *callback_args, **callback_kwargs)
  File "/Users/macmini/Phitron/backup12_07/venv/lib/python3.10/site-packages/django/contrib/admin/sites.py", line 261, in wrapper
    return self.admin_view(view, cacheable)(*args, **kwargs)
  File "/Users/macmini/Phitron/backup12_07/venv/lib/python3.10/site-packages/django/utils/decorators.py", line 133, in _wrapped_view
    response = view_func(request, *args, **kwargs)
  File "/Users/macmini/Phitron/backup12_07/venv/lib/python3.10/site-packages/django/views/decorators/cache.py", line 62, in _wrapped_view_func
    response = view_func(request, *args, **kwargs)
  File "/Users/macmini/Phitron/backup12_07/venv/lib/python3.10/site-packages/django/contrib/admin/sites.py", line 230, in inner
    if not self.has_permission(request):
  File "/Users/macmini/Phitron/backup12_07/venv/lib/python3.10/site-packages/django/contrib/admin/sites.py", line 203, in has_permission
    return request.user.is_active and request.user.is_staff
  File "/Users/macmini/Phitron/backup12_07/venv/lib/python3.10/site-packages/django/utils/functional.py", line 266, in inner
    self._setup()
  File "/Users/macmini/Phitron/backup12_07/venv/lib/python3.10/site-packages/django/utils/functional.py", line 419, in _setup
    self._wrapped = self._setupfunc()
  File "/Users/macmini/Phitron/backup12_07/venv/lib/python3.10/site-packages/django/contrib/auth/middleware.py", line 25, in <lambda>
    request.user = SimpleLazyObject(lambda: get_user(request))
  File "/Users/macmini/Phitron/backup12_07/venv/lib/python3.10/site-packages/django/contrib/auth/middleware.py", line 11, in get_user
    request._cached_user = auth.get_user(request)
  File "/Users/macmini/Phitron/backup12_07/venv/lib/python3.10/site-packages/django/contrib/auth/__init__.py", line 191, in get_user
    user_id = _get_user_session_key(request)
  File "/Users/macmini/Phitron/backup12_07/venv/lib/python3.10/site-packages/django/contrib/auth/__init__.py", line 60, in _get_user_session_key
    return get_user_model()._meta.pk.to_python(request.session[SESSION_KEY])
  File "/Users/macmini/Phitron/backup12_07/venv/lib/python3.10/site-packages/django/contrib/sessions/backends/base.py", line 53, in __getitem__
    return self._session[key]
  File "/Users/macmini/Phitron/backup12_07/venv/lib/python3.10/site-packages/django/contrib/sessions/backends/base.py", line 192, in _get_session
    self._session_cache = self.load()
  File "/Users/macmini/Phitron/backup12_07/venv/lib/python3.10/site-packages/django/contrib/sessions/backends/db.py", line 42, in load
    s = self._get_session_from_db()
  File "/Users/macmini/Phitron/backup12_07/venv/lib/python3.10/site-packages/django/contrib/sessions/backends/db.py", line 32, in _get_session_from_db
    return self.model.objects.get(
  File "/Users/macmini/Phitron/backup12_07/venv/lib/python3.10/site-packages/django/db/models/manager.py", line 85, in manager_method
    return getattr(self.get_queryset(), name)(*args, **kwargs)
  File "/Users/macmini/Phitron/backup12_07/venv/lib/python3.10/site-packages/django/db/models/query.py", line 646, in get
    num = len(clone)
  File "/Users/macmini/Phitron/backup12_07/venv/lib/python3.10/site-packages/django/db/models/query.py", line 376, in __len__
    self._fetch_all()
  File "/Users/macmini/Phitron/backup12_07/venv/lib/python3.10/site-packages/django/db/models/query.py", line 1866, in _fetch_all
    self._result_cache = list(self._iterable_class(self))
  File "/Users/macmini/Phitron/backup12_07/venv/lib/python3.10/site-packages/django/db/models/query.py", line 87, in __iter__
    results = compiler.execute_sql(
  File "/Users/macmini/Phitron/backup12_07/venv/lib/python3.10/site-packages/django/db/models/sql/compiler.py", line 1395, in execute_sql
    cursor.execute(sql, params)
  File "/Users/macmini/Phitron/backup12_07/venv/lib/python3.10/site-packages/django/db/backends/utils.py", line 103, in execute
    return super().execute(sql, params)
  File "/Users/macmini/Phitron/backup12_07/venv/lib/python3.10/site-packages/django/db/backends/utils.py", line 67, in execute
    return self._execute_with_wrappers(
  File "/Users/macmini/Phitron/backup12_07/venv/lib/python3.10/site-packages/django/db/backends/utils.py", line 80, in _execute_with_wrappers
    return executor(sql, params, many, context)
  File "/Users/macmini/Phitron/backup12_07/venv/lib/python3.10/site-packages/django/db/backends/utils.py", line 84, in _execute
    with self.db.wrap_database_errors:
  File "/Users/macmini/Phitron/backup12_07/venv/lib/python3.10/site-packages/django/db/utils.py", line 91, in __exit__
    raise dj_exc_value.with_traceback(traceback) from exc_value
  File "/Users/macmini/Phitron/backup12_07/venv/lib/python3.10/site-packages/django/db/backends/utils.py", line 89, in _execute
    return self.cursor.execute(sql, params)
  File "/Users/macmini/Phitron/backup12_07/venv/lib/python3.10/site-packages/django/db/backends/sqlite3/base.py", line 357, in execute
    return Database.Cursor.execute(self, query, params)
django.db.utils.OperationalError: no such table: django_session
"GET /admin/ HTTP/1.1" 500 190530
test_path/bar_codes/base/white.png /bar_codes/base/out/out.png
test_path/bar_codes/base/white.png /bar_codes/base/out/out.png
test_path/bar_codes/base/white.png /bar_codes/base/out/out.png
test_path/bar_codes/base/white.png /bar_codes/base/out/out.png
test_path/bar_codes/base/white.png /bar_codes/base/out/out.png
test_path/bar_codes/base/white.png /bar_codes/base/out/out.png
test_path/bar_codes/base/white.png /bar_codes/base/out/out.png
test_path/bar_codes/base/white.png /bar_codes/base/out/out.png
test_path/bar_codes/base/white.png /bar_codes/base/out/out.png
test_path/bar_codes/base/white.png /bar_codes/base/out/out.png
Error in generate_product_barcode:  
 Traceback (most recent call last):
  File "/Users/macmini/Phitron/backup12_07/utility/utils/bar_image_utils.py", line 59, in add_images_and_text
    modified_image = insert_text(image_path, text, output_path, size=30, add_x=0, position_y=2,color='white')
  File "/Users/macmini/Phitron/backup12_07/utility/utils/bar_image_utils.py", line 6, in insert_text
    image = Image.open(image_path)
  File "/Users/macmini/Phitron/backup12_07/venv/lib/python3.10/site-packages/PIL/Image.py", line 3218, in open
    fp = builtins.open(filename, "rb")
FileNotFoundError: [Errno 2] No such file or directory: '/bar_codes/base/white.png'

Error in generate_product_barcode:  
 Traceback (most recent call last):
  File "/Users/macmini/Phitron/backup12_07/utility/utils/bar_image_utils.py", line 59, in add_images_and_text
    modified_image = insert_text(image_path, text, output_path, size=30, add_x=0, position_y=2,color='white')
  File "/Users/macmini/Phitron/backup12_07/utility/utils/bar_image_utils.py", line 6, in insert_text
    image = Image.open(image_path)
  File "/Users/macmini/Phitron/backup12_07/venv/lib/python3.10/site-packages/PIL/Image.py", line 3218, in open
    fp = builtins.open(filename, "rb")
FileNotFoundError: [Errno 2] No such file or directory: '/bar_codes/base/white.png'

Error in generate_product_barcode:  
 Traceback (most recent call last):
  File "/Users/macmini/Phitron/backup12_07/utility/utils/bar_image_utils.py", line 59, in add_images_and_text
    modified_image = insert_text(image_path, text, output_path, size=30, add_x=0, position_y=2,color='white')
  File "/Users/macmini/Phitron/backup12_07/utility/utils/bar_image_utils.py", line 6, in insert_text
    image = Image.open(image_path)
  File "/Users/macmini/Phitron/backup12_07/venv/lib/python3.10/site-packages/PIL/Image.py", line 3218, in open
    fp = builtins.open(filename, "rb")
FileNotFoundError: [Errno 2] No such file or directory: '/bar_codes/base/white.png'

Error in generate_product_barcode:  
 Traceback (most recent call last):
  File "/Users/macmini/Phitron/backup12_07/utility/utils/bar_image_utils.py", line 59, in add_images_and_text
    modified_image = insert_text(image_path, text, output_path, size=30, add_x=0, position_y=2,color='white')
  File "/Users/macmini/Phitron/backup12_07/utility/utils/bar_image_utils.py", line 6, in insert_text
    image = Image.open(image_path)
  File "/Users/macmini/Phitron/backup12_07/venv/lib/python3.10/site-packages/PIL/Image.py", line 3218, in open
    fp = builtins.open(filename, "rb")
FileNotFoundError: [Errno 2] No such file or directory: '/bar_codes/base/white.png'

Error in generate_product_barcode:  
 Traceback (most recent call last):
  File "/Users/macmini/Phitron/backup12_07/utility/utils/bar_image_utils.py", line 59, in add_images_and_text
    modified_image = insert_text(image_path, text, output_path, size=30, add_x=0, position_y=2,color='white')
  File "/Users/macmini/Phitron/backup12_07/utility/utils/bar_image_utils.py", line 6, in insert_text
    image = Image.open(image_path)
  File "/Users/macmini/Phitron/backup12_07/venv/lib/python3.10/site-packages/PIL/Image.py", line 3218, in open
    fp = builtins.open(filename, "rb")
FileNotFoundError: [Errno 2] No such file or directory: '/bar_codes/base/white.png'

Error in generate_product_barcode:  
 Traceback (most recent call last):
  File "/Users/macmini/Phitron/backup12_07/utility/utils/bar_image_utils.py", line 59, in add_images_and_text
    modified_image = insert_text(image_path, text, output_path, size=30, add_x=0, position_y=2,color='white')
  File "/Users/macmini/Phitron/backup12_07/utility/utils/bar_image_utils.py", line 6, in insert_text
    image = Image.open(image_path)
  File "/Users/macmini/Phitron/backup12_07/venv/lib/python3.10/site-packages/PIL/Image.py", line 3218, in open
    fp = builtins.open(filename, "rb")
FileNotFoundError: [Errno 2] No such file or directory: '/bar_codes/base/white.png'

Error in generate_product_barcode:  
 Traceback (most recent call last):
  File "/Users/macmini/Phitron/backup12_07/utility/utils/bar_image_utils.py", line 59, in add_images_and_text
    modified_image = insert_text(image_path, text, output_path, size=30, add_x=0, position_y=2,color='white')
  File "/Users/macmini/Phitron/backup12_07/utility/utils/bar_image_utils.py", line 6, in insert_text
    image = Image.open(image_path)
  File "/Users/macmini/Phitron/backup12_07/venv/lib/python3.10/site-packages/PIL/Image.py", line 3218, in open
    fp = builtins.open(filename, "rb")
FileNotFoundError: [Errno 2] No such file or directory: '/bar_codes/base/white.png'

Error in generate_product_barcode:  
 Traceback (most recent call last):
  File "/Users/macmini/Phitron/backup12_07/utility/utils/bar_image_utils.py", line 59, in add_images_and_text
    modified_image = insert_text(image_path, text, output_path, size=30, add_x=0, position_y=2,color='white')
  File "/Users/macmini/Phitron/backup12_07/utility/utils/bar_image_utils.py", line 6, in insert_text
    image = Image.open(image_path)
  File "/Users/macmini/Phitron/backup12_07/venv/lib/python3.10/site-packages/PIL/Image.py", line 3218, in open
    fp = builtins.open(filename, "rb")
FileNotFoundError: [Errno 2] No such file or directory: '/bar_codes/base/white.png'

test_path/bar_codes/base/white.png /bar_codes/base/out/out.png
test_path/bar_codes/base/white.png /bar_codes/base/out/out.png
test_path/bar_codes/base/white.png /bar_codes/base/out/out.png
Error in generate_product_barcode:  
 Traceback (most recent call last):
  File "/Users/macmini/Phitron/backup12_07/utility/utils/bar_image_utils.py", line 59, in add_images_and_text
    modified_image = insert_text(image_path, text, output_path, size=30, add_x=0, position_y=2,color='white')
  File "/Users/macmini/Phitron/backup12_07/utility/utils/bar_image_utils.py", line 6, in insert_text
    image = Image.open(image_path)
  File "/Users/macmini/Phitron/backup12_07/venv/lib/python3.10/site-packages/PIL/Image.py", line 3218, in open
    fp = builtins.open(filename, "rb")
FileNotFoundError: [Errno 2] No such file or directory: '/bar_codes/base/white.png'

Error in generate_product_barcode:  
 Traceback (most recent call last):
  File "/Users/macmini/Phitron/backup12_07/utility/utils/bar_image_utils.py", line 59, in add_images_and_text
    modified_image = insert_text(image_path, text, output_path, size=30, add_x=0, position_y=2,color='white')
  File "/Users/macmini/Phitron/backup12_07/utility/utils/bar_image_utils.py", line 6, in insert_text
    image = Image.open(image_path)
  File "/Users/macmini/Phitron/backup12_07/venv/lib/python3.10/site-packages/PIL/Image.py", line 3218, in open
    fp = builtins.open(filename, "rb")
FileNotFoundError: [Errno 2] No such file or directory: '/bar_codes/base/white.png'

test_path/bar_codes/base/white.png /bar_codes/base/out/out.png
Error in generate_product_barcode:  
 Traceback (most recent call last):
  File "/Users/macmini/Phitron/backup12_07/utility/utils/bar_image_utils.py", line 59, in add_images_and_text
    modified_image = insert_text(image_path, text, output_path, size=30, add_x=0, position_y=2,color='white')
  File "/Users/macmini/Phitron/backup12_07/utility/utils/bar_image_utils.py", line 6, in insert_text
    image = Image.open(image_path)
  File "/Users/macmini/Phitron/backup12_07/venv/lib/python3.10/site-packages/PIL/Image.py", line 3218, in open
    fp = builtins.open(filename, "rb")
FileNotFoundError: [Errno 2] No such file or directory: '/bar_codes/base/white.png'

Error in generate_product_barcode:  
 Traceback (most recent call last):
  File "/Users/macmini/Phitron/backup12_07/utility/utils/bar_image_utils.py", line 59, in add_images_and_text
    modified_image = insert_text(image_path, text, output_path, size=30, add_x=0, position_y=2,color='white')
  File "/Users/macmini/Phitron/backup12_07/utility/utils/bar_image_utils.py", line 6, in insert_text
    image = Image.open(image_path)
  File "/Users/macmini/Phitron/backup12_07/venv/lib/python3.10/site-packages/PIL/Image.py", line 3218, in open
    fp = builtins.open(filename, "rb")
FileNotFoundError: [Errno 2] No such file or directory: '/bar_codes/base/white.png'

test_path/bar_codes/base/white.png /bar_codes/base/out/out.png
test_path/bar_codes/base/white.png /bar_codes/base/out/out.png
test_path/bar_codes/base/white.png /bar_codes/base/out/out.png
test_path/bar_codes/base/white.png /bar_codes/base/out/out.png
test_path/bar_codes/base/white.png /bar_codes/base/out/out.png
test_path/bar_codes/base/white.png /bar_codes/base/out/out.png
test_path/bar_codes/base/white.png /bar_codes/base/out/out.png
test_path/bar_codes/base/white.png /bar_codes/base/out/out.png
test_path/bar_codes/base/white.png /bar_codes/base/out/out.png
test_path/bar_codes/base/white.png /bar_codes/base/out/out.png
test_path/bar_codes/base/white.png /bar_codes/base/out/out.png
test_path/bar_codes/base/white.png /bar_codes/base/out/out.png
test_path/bar_codes/base/white.png /bar_codes/base/out/out.png
test_path/bar_codes/base/white.png /bar_codes/base/out/out.png
test_path/bar_codes/base/white.png /bar_codes/base/out/out.png
test_path/bar_codes/base/white.png /bar_codes/base/out/out.png
test_path/bar_codes/base/white.png /bar_codes/base/out/out.png
test_path/bar_codes/base/white.png /bar_codes/base/out/out.png
Error in generate_product_barcode:  
 Traceback (most recent call last):
  File "/Users/macmini/Phitron/backup12_07/utility/utils/bar_image_utils.py", line 59, in add_images_and_text
    modified_image = insert_text(image_path, text, output_path, size=30, add_x=0, position_y=2,color='white')
  File "/Users/macmini/Phitron/backup12_07/utility/utils/bar_image_utils.py", line 6, in insert_text
    image = Image.open(image_path)
  File "/Users/macmini/Phitron/backup12_07/venv/lib/python3.10/site-packages/PIL/Image.py", line 3218, in open
    fp = builtins.open(filename, "rb")
FileNotFoundError: [Errno 2] No such file or directory: '/bar_codes/base/white.png'

Error in generate_product_barcode:  
 Traceback (most recent call last):
  File "/Users/macmini/Phitron/backup12_07/utility/utils/bar_image_utils.py", line 59, in add_images_and_text
    modified_image = insert_text(image_path, text, output_path, size=30, add_x=0, position_y=2,color='white')
  File "/Users/macmini/Phitron/backup12_07/utility/utils/bar_image_utils.py", line 6, in insert_text
    image = Image.open(image_path)
  File "/Users/macmini/Phitron/backup12_07/venv/lib/python3.10/site-packages/PIL/Image.py", line 3218, in open
    fp = builtins.open(filename, "rb")
FileNotFoundError: [Errno 2] No such file or directory: '/bar_codes/base/white.png'

test_path/bar_codes/base/white.png /bar_codes/base/out/out.png
test_path/bar_codes/base/white.png /bar_codes/base/out/out.png
test_path/bar_codes/base/white.png /bar_codes/base/out/out.png
test_path/bar_codes/base/white.png /bar_codes/base/out/out.png
test_path/bar_codes/base/white.png /bar_codes/base/out/out.png
Error in generate_product_barcode:  
 Traceback (most recent call last):
  File "/Users/macmini/Phitron/backup12_07/utility/utils/bar_image_utils.py", line 59, in add_images_and_text
    modified_image = insert_text(image_path, text, output_path, size=30, add_x=0, position_y=2,color='white')
  File "/Users/macmini/Phitron/backup12_07/utility/utils/bar_image_utils.py", line 6, in insert_text
    image = Image.open(image_path)
  File "/Users/macmini/Phitron/backup12_07/venv/lib/python3.10/site-packages/PIL/Image.py", line 3218, in open
    fp = builtins.open(filename, "rb")
FileNotFoundError: [Errno 2] No such file or directory: '/bar_codes/base/white.png'

Internal Server Error: /api/v1/sales/inventory/daily-sales-report
Traceback (most recent call last):
  File "/Users/macmini/Phitron/backup12_07/venv/lib/python3.10/site-packages/django/core/handlers/exception.py", line 55, in inner
    response = get_response(request)
  File "/Users/macmini/Phitron/backup12_07/venv/lib/python3.10/site-packages/django/core/handlers/base.py", line 220, in _get_response
    response = response.render()
  File "/Users/macmini/Phitron/backup12_07/venv/lib/python3.10/site-packages/django/template/response.py", line 114, in render
    self.content = self.rendered_content
  File "/Users/macmini/Phitron/backup12_07/venv/lib/python3.10/site-packages/rest_framework/response.py", line 70, in rendered_content
    ret = renderer.render(self.data, accepted_media_type, context)
  File "/Users/macmini/Phitron/backup12_07/coreapp/renderers.py", line 26, in render
    return super(CustomRenderer, self).render(response, accepted_media_type, renderer_context)
  File "/Users/macmini/Phitron/backup12_07/venv/lib/python3.10/site-packages/rest_framework/renderers.py", line 99, in render
    ret = json.dumps(
  File "/Users/macmini/Phitron/backup12_07/venv/lib/python3.10/site-packages/rest_framework/utils/json.py", line 25, in dumps
    return json.dumps(*args, **kwargs)
  File "/Library/Frameworks/Python.framework/Versions/3.10/lib/python3.10/json/__init__.py", line 238, in dumps
    **kw).encode(obj)
  File "/Library/Frameworks/Python.framework/Versions/3.10/lib/python3.10/json/encoder.py", line 199, in encode
    chunks = self.iterencode(o, _one_shot=True)
  File "/Library/Frameworks/Python.framework/Versions/3.10/lib/python3.10/json/encoder.py", line 257, in iterencode
    return _iterencode(o, 0)
TypeError: keys must be str, int, float, bool or None, not Products
"GET /api/v1/sales/inventory/daily-sales-report HTTP/1.1" 500 99617
Internal Server Error: /api/v1/sales/inventory/daily-sales-report
Traceback (most recent call last):
  File "/Users/macmini/Phitron/backup12_07/venv/lib/python3.10/site-packages/django/core/handlers/exception.py", line 55, in inner
    response = get_response(request)
  File "/Users/macmini/Phitron/backup12_07/venv/lib/python3.10/site-packages/django/core/handlers/base.py", line 220, in _get_response
    response = response.render()
  File "/Users/macmini/Phitron/backup12_07/venv/lib/python3.10/site-packages/django/template/response.py", line 114, in render
    self.content = self.rendered_content
  File "/Users/macmini/Phitron/backup12_07/venv/lib/python3.10/site-packages/rest_framework/response.py", line 70, in rendered_content
    ret = renderer.render(self.data, accepted_media_type, context)
  File "/Users/macmini/Phitron/backup12_07/coreapp/renderers.py", line 26, in render
    return super(CustomRenderer, self).render(response, accepted_media_type, renderer_context)
  File "/Users/macmini/Phitron/backup12_07/venv/lib/python3.10/site-packages/rest_framework/renderers.py", line 99, in render
    ret = json.dumps(
  File "/Users/macmini/Phitron/backup12_07/venv/lib/python3.10/site-packages/rest_framework/utils/json.py", line 25, in dumps
    return json.dumps(*args, **kwargs)
  File "/Library/Frameworks/Python.framework/Versions/3.10/lib/python3.10/json/__init__.py", line 238, in dumps
    **kw).encode(obj)
  File "/Library/Frameworks/Python.framework/Versions/3.10/lib/python3.10/json/encoder.py", line 199, in encode
    chunks = self.iterencode(o, _one_shot=True)
  File "/Library/Frameworks/Python.framework/Versions/3.10/lib/python3.10/json/encoder.py", line 257, in iterencode
    return _iterencode(o, 0)
TypeError: keys must be str, int, float, bool or None, not Products
"GET /api/v1/sales/inventory/daily-sales-report HTTP/1.1" 500 99617
Internal Server Error: /api/v1/sales/inventory/daily-sales-report
Traceback (most recent call last):
  File "/Users/macmini/Phitron/backup12_07/venv/lib/python3.10/site-packages/django/core/handlers/exception.py", line 55, in inner
    response = get_response(request)
  File "/Users/macmini/Phitron/backup12_07/venv/lib/python3.10/site-packages/django/core/handlers/base.py", line 220, in _get_response
    response = response.render()
  File "/Users/macmini/Phitron/backup12_07/venv/lib/python3.10/site-packages/django/template/response.py", line 114, in render
    self.content = self.rendered_content
  File "/Users/macmini/Phitron/backup12_07/venv/lib/python3.10/site-packages/rest_framework/response.py", line 70, in rendered_content
    ret = renderer.render(self.data, accepted_media_type, context)
  File "/Users/macmini/Phitron/backup12_07/coreapp/renderers.py", line 26, in render
    return super(CustomRenderer, self).render(response, accepted_media_type, renderer_context)
  File "/Users/macmini/Phitron/backup12_07/venv/lib/python3.10/site-packages/rest_framework/renderers.py", line 99, in render
    ret = json.dumps(
  File "/Users/macmini/Phitron/backup12_07/venv/lib/python3.10/site-packages/rest_framework/utils/json.py", line 25, in dumps
    return json.dumps(*args, **kwargs)
  File "/Library/Frameworks/Python.framework/Versions/3.10/lib/python3.10/json/__init__.py", line 238, in dumps
    **kw).encode(obj)
  File "/Library/Frameworks/Python.framework/Versions/3.10/lib/python3.10/json/encoder.py", line 199, in encode
    chunks = self.iterencode(o, _one_shot=True)
  File "/Library/Frameworks/Python.framework/Versions/3.10/lib/python3.10/json/encoder.py", line 257, in iterencode
    return _iterencode(o, 0)
TypeError: keys must be str, int, float, bool or None, not Products
"GET /api/v1/sales/inventory/daily-sales-report HTTP/1.1" 500 99617
Internal Server Error: /api/v1/sales/inventory/daily-sales-report
Traceback (most recent call last):
  File "/Users/macmini/Phitron/backup12_07/venv/lib/python3.10/site-packages/django/core/handlers/exception.py", line 55, in inner
    response = get_response(request)
  File "/Users/macmini/Phitron/backup12_07/venv/lib/python3.10/site-packages/django/core/handlers/base.py", line 220, in _get_response
    response = response.render()
  File "/Users/macmini/Phitron/backup12_07/venv/lib/python3.10/site-packages/django/template/response.py", line 114, in render
    self.content = self.rendered_content
  File "/Users/macmini/Phitron/backup12_07/venv/lib/python3.10/site-packages/rest_framework/response.py", line 70, in rendered_content
    ret = renderer.render(self.data, accepted_media_type, context)
  File "/Users/macmini/Phitron/backup12_07/coreapp/renderers.py", line 26, in render
    return super(CustomRenderer, self).render(response, accepted_media_type, renderer_context)
  File "/Users/macmini/Phitron/backup12_07/venv/lib/python3.10/site-packages/rest_framework/renderers.py", line 99, in render
    ret = json.dumps(
  File "/Users/macmini/Phitron/backup12_07/venv/lib/python3.10/site-packages/rest_framework/utils/json.py", line 25, in dumps
    return json.dumps(*args, **kwargs)
  File "/Library/Frameworks/Python.framework/Versions/3.10/lib/python3.10/json/__init__.py", line 238, in dumps
    **kw).encode(obj)
  File "/Library/Frameworks/Python.framework/Versions/3.10/lib/python3.10/json/encoder.py", line 199, in encode
    chunks = self.iterencode(o, _one_shot=True)
  File "/Library/Frameworks/Python.framework/Versions/3.10/lib/python3.10/json/encoder.py", line 257, in iterencode
    return _iterencode(o, 0)
TypeError: keys must be str, int, float, bool or None, not Products
"GET /api/v1/sales/inventory/daily-sales-report HTTP/1.1" 500 99617
Internal Server Error: /api/v1/sales/inventory/daily-sales-report
Traceback (most recent call last):
  File "/Users/macmini/Phitron/backup12_07/venv/lib/python3.10/site-packages/django/core/handlers/exception.py", line 55, in inner
    response = get_response(request)
  File "/Users/macmini/Phitron/backup12_07/venv/lib/python3.10/site-packages/django/core/handlers/base.py", line 220, in _get_response
    response = response.render()
  File "/Users/macmini/Phitron/backup12_07/venv/lib/python3.10/site-packages/django/template/response.py", line 114, in render
    self.content = self.rendered_content
  File "/Users/macmini/Phitron/backup12_07/venv/lib/python3.10/site-packages/rest_framework/response.py", line 70, in rendered_content
    ret = renderer.render(self.data, accepted_media_type, context)
  File "/Users/macmini/Phitron/backup12_07/coreapp/renderers.py", line 26, in render
    return super(CustomRenderer, self).render(response, accepted_media_type, renderer_context)
  File "/Users/macmini/Phitron/backup12_07/venv/lib/python3.10/site-packages/rest_framework/renderers.py", line 99, in render
    ret = json.dumps(
  File "/Users/macmini/Phitron/backup12_07/venv/lib/python3.10/site-packages/rest_framework/utils/json.py", line 25, in dumps
    return json.dumps(*args, **kwargs)
  File "/Library/Frameworks/Python.framework/Versions/3.10/lib/python3.10/json/__init__.py", line 238, in dumps
    **kw).encode(obj)
  File "/Library/Frameworks/Python.framework/Versions/3.10/lib/python3.10/json/encoder.py", line 199, in encode
    chunks = self.iterencode(o, _one_shot=True)
  File "/Library/Frameworks/Python.framework/Versions/3.10/lib/python3.10/json/encoder.py", line 257, in iterencode
    return _iterencode(o, 0)
TypeError: keys must be str, int, float, bool or None, not Products
"GET /api/v1/sales/inventory/daily-sales-report HTTP/1.1" 500 99617
test_path/bar_codes/base/white.png /bar_codes/base/out/out.png
Error in generate_product_barcode:  
 Traceback (most recent call last):
  File "/Users/macmini/Phitron/backup12_07/utility/utils/bar_image_utils.py", line 59, in add_images_and_text
    modified_image = insert_text(image_path, text, output_path, size=30, add_x=0, position_y=2,color='white')
  File "/Users/macmini/Phitron/backup12_07/utility/utils/bar_image_utils.py", line 6, in insert_text
    image = Image.open(image_path)
  File "/Users/macmini/Phitron/backup12_07/venv/lib/python3.10/site-packages/PIL/Image.py", line 3218, in open
    fp = builtins.open(filename, "rb")
FileNotFoundError: [Errno 2] No such file or directory: '/bar_codes/base/white.png'

---------Stock update issue---------
[ErrorDetail(string='Insufficient stock for product: test1', code='invalid')]
Error in generate_product_barcode:  
 Traceback (most recent call last):
  File "/Users/macmini/Phitron/backup12_07/utility/utils/bar_image_utils.py", line 59, in add_images_and_text
    modified_image = insert_text(image_path, text, output_path, size=30, add_x=0, position_y=2,color='white')
  File "/Users/macmini/Phitron/backup12_07/utility/utils/bar_image_utils.py", line 6, in insert_text
    image = Image.open(image_path)
  File "/Users/macmini/Phitron/backup12_07/venv/lib/python3.10/site-packages/PIL/Image.py", line 3218, in open
    fp = builtins.open(filename, "rb")
FileNotFoundError: [Errno 2] No such file or directory: '/bar_codes/base/white.png'

test_path/bar_codes/base/white.png /bar_codes/base/out/out.png
test_path/bar_codes/base/white.png /bar_codes/base/out/out.png
test_path/bar_codes/base/white.png /bar_codes/base/out/out.png
test_path/bar_codes/base/white.png /bar_codes/base/out/out.png
test_path/bar_codes/base/white.png /bar_codes/base/out/out.png
test_path/bar_codes/base/white.png /bar_codes/base/out/out.png
test_path/bar_codes/base/white.png /bar_codes/base/out/out.png
Error in generate_product_barcode:  
 Traceback (most recent call last):
  File "/Users/macmini/Phitron/backup12_07/utility/utils/bar_image_utils.py", line 59, in add_images_and_text
    modified_image = insert_text(image_path, text, output_path, size=30, add_x=0, position_y=2,color='white')
  File "/Users/macmini/Phitron/backup12_07/utility/utils/bar_image_utils.py", line 6, in insert_text
    image = Image.open(image_path)
  File "/Users/macmini/Phitron/backup12_07/venv/lib/python3.10/site-packages/PIL/Image.py", line 3218, in open
    fp = builtins.open(filename, "rb")
FileNotFoundError: [Errno 2] No such file or directory: '/bar_codes/base/white.png'

test_path/bar_codes/base/white.png /bar_codes/base/out/out.png
test_path/bar_codes/base/white.png /bar_codes/base/out/out.png
---------Stock update issue---------
[ErrorDetail(string='Insufficient stock for product: test1', code='invalid')]
test_path/bar_codes/base/white.png /bar_codes/base/out/out.png
test_path/bar_codes/base/white.png /bar_codes/base/out/out.png
test_path/bar_codes/base/white.png /bar_codes/base/out/out.png
test_path/bar_codes/base/white.png /bar_codes/base/out/out.png
test_path/bar_codes/base/white.png /bar_codes/base/out/out.png
test_path/bar_codes/base/white.png /bar_codes/base/out/out.png
test_path/bar_codes/base/white.png /bar_codes/base/out/out.png
test_path/bar_codes/base/white.png /bar_codes/base/out/out.png
test_path/bar_codes/base/white.png /bar_codes/base/out/out.png
Error in generate_product_barcode:  
 Traceback (most recent call last):
  File "/Users/macmini/Machine Learning/backup12_07/utility/utils/bar_image_utils.py", line 59, in add_images_and_text
    modified_image = insert_text(image_path, text, output_path, size=30, add_x=0, position_y=2,color='white')
  File "/Users/macmini/Machine Learning/backup12_07/utility/utils/bar_image_utils.py", line 6, in insert_text
    image = Image.open(image_path)
  File "/Library/Frameworks/Python.framework/Versions/3.10/lib/python3.10/site-packages/PIL/Image.py", line 3236, in open
    fp = builtins.open(filename, "rb")
FileNotFoundError: [Errno 2] No such file or directory: '/bar_codes/base/white.png'

Error in generate_product_barcode:  
 Traceback (most recent call last):
  File "/Users/macmini/Machine Learning/backup12_07/utility/utils/bar_image_utils.py", line 59, in add_images_and_text
    modified_image = insert_text(image_path, text, output_path, size=30, add_x=0, position_y=2,color='white')
  File "/Users/macmini/Machine Learning/backup12_07/utility/utils/bar_image_utils.py", line 6, in insert_text
    image = Image.open(image_path)
  File "/Library/Frameworks/Python.framework/Versions/3.10/lib/python3.10/site-packages/PIL/Image.py", line 3236, in open
    fp = builtins.open(filename, "rb")
FileNotFoundError: [Errno 2] No such file or directory: '/bar_codes/base/white.png'

Error in generate_product_barcode:  
 Traceback (most recent call last):
  File "/Users/macmini/Machine Learning/backup12_07/utility/utils/bar_image_utils.py", line 59, in add_images_and_text
    modified_image = insert_text(image_path, text, output_path, size=30, add_x=0, position_y=2,color='white')
  File "/Users/macmini/Machine Learning/backup12_07/utility/utils/bar_image_utils.py", line 6, in insert_text
    image = Image.open(image_path)
  File "/Library/Frameworks/Python.framework/Versions/3.10/lib/python3.10/site-packages/PIL/Image.py", line 3236, in open
    fp = builtins.open(filename, "rb")
FileNotFoundError: [Errno 2] No such file or directory: '/bar_codes/base/white.png'

