test_path/bar_codes/base/white.png /bar_codes/base/out/out.png
test_path/bar_codes/base/white.png /bar_codes/base/out/out.png
test_path/bar_codes/base/white.png /bar_codes/base/out/out.png
test_path/bar_codes/base/white.png /bar_codes/base/out/out.png
Internal Server Error: /api/v1/sales/inventory/inventory/notifications
Traceback (most recent call last):
  File "/Library/Frameworks/Python.framework/Versions/3.10/lib/python3.10/site-packages/django/core/handlers/exception.py", line 55, in inner
    response = get_response(request)
  File "/Library/Frameworks/Python.framework/Versions/3.10/lib/python3.10/site-packages/django/core/handlers/base.py", line 197, in _get_response
    response = wrapped_callback(request, *callback_args, **callback_kwargs)
  File "/Library/Frameworks/Python.framework/Versions/3.10/lib/python3.10/site-packages/django/views/decorators/csrf.py", line 54, in wrapped_view
    return view_func(*args, **kwargs)
  File "/Library/Frameworks/Python.framework/Versions/3.10/lib/python3.10/site-packages/django/views/generic/base.py", line 103, in view
    return self.dispatch(request, *args, **kwargs)
  File "/Library/Frameworks/Python.framework/Versions/3.10/lib/python3.10/site-packages/rest_framework/views.py", line 509, in dispatch
    response = self.handle_exception(exc)
  File "/Library/Frameworks/Python.framework/Versions/3.10/lib/python3.10/site-packages/rest_framework/views.py", line 469, in handle_exception
    self.raise_uncaught_exception(exc)
  File "/Library/Frameworks/Python.framework/Versions/3.10/lib/python3.10/site-packages/rest_framework/views.py", line 480, in raise_uncaught_exception
    raise exc
  File "/Library/Frameworks/Python.framework/Versions/3.10/lib/python3.10/site-packages/rest_framework/views.py", line 506, in dispatch
    response = handler(request, *args, **kwargs)
  File "/Users/macmini/Machine Learning/backup12_07/sales/api/inventory/views.py", line 816, in get
    notification = Notification.objects.get(user=user)
  File "/Library/Frameworks/Python.framework/Versions/3.10/lib/python3.10/site-packages/django/db/models/manager.py", line 85, in manager_method
    return getattr(self.get_queryset(), name)(*args, **kwargs)
  File "/Library/Frameworks/Python.framework/Versions/3.10/lib/python3.10/site-packages/django/db/models/query.py", line 650, in get
    raise self.model.DoesNotExist(
sales.models.Notification.DoesNotExist: Notification matching query does not exist.
"GET /api/v1/sales/inventory/inventory/notifications HTTP/1.1" 500 99656
test_path/bar_codes/base/white.png /bar_codes/base/out/out.png
test_path/bar_codes/base/white.png /bar_codes/base/out/out.png
Internal Server Error: /api/v1/sales/inventory/inventory/notifications
Traceback (most recent call last):
  File "/Library/Frameworks/Python.framework/Versions/3.10/lib/python3.10/site-packages/django/core/handlers/exception.py", line 55, in inner
    response = get_response(request)
  File "/Library/Frameworks/Python.framework/Versions/3.10/lib/python3.10/site-packages/django/core/handlers/base.py", line 197, in _get_response
    response = wrapped_callback(request, *callback_args, **callback_kwargs)
  File "/Library/Frameworks/Python.framework/Versions/3.10/lib/python3.10/site-packages/django/views/decorators/csrf.py", line 54, in wrapped_view
    return view_func(*args, **kwargs)
  File "/Library/Frameworks/Python.framework/Versions/3.10/lib/python3.10/site-packages/django/views/generic/base.py", line 103, in view
    return self.dispatch(request, *args, **kwargs)
  File "/Library/Frameworks/Python.framework/Versions/3.10/lib/python3.10/site-packages/rest_framework/views.py", line 509, in dispatch
    response = self.handle_exception(exc)
  File "/Library/Frameworks/Python.framework/Versions/3.10/lib/python3.10/site-packages/rest_framework/views.py", line 469, in handle_exception
    self.raise_uncaught_exception(exc)
  File "/Library/Frameworks/Python.framework/Versions/3.10/lib/python3.10/site-packages/rest_framework/views.py", line 480, in raise_uncaught_exception
    raise exc
  File "/Library/Frameworks/Python.framework/Versions/3.10/lib/python3.10/site-packages/rest_framework/views.py", line 506, in dispatch
    response = handler(request, *args, **kwargs)
  File "/Users/macmini/Machine Learning/backup12_07/sales/api/inventory/views.py", line 816, in get
    notification = Notification.objects.get(user=user)
  File "/Library/Frameworks/Python.framework/Versions/3.10/lib/python3.10/site-packages/django/db/models/manager.py", line 85, in manager_method
    return getattr(self.get_queryset(), name)(*args, **kwargs)
  File "/Library/Frameworks/Python.framework/Versions/3.10/lib/python3.10/site-packages/django/db/models/query.py", line 650, in get
    raise self.model.DoesNotExist(
sales.models.Notification.DoesNotExist: Notification matching query does not exist.
"GET /api/v1/sales/inventory/inventory/notifications HTTP/1.1" 500 99656
test_path/bar_codes/base/white.png /bar_codes/base/out/out.png
Internal Server Error: /api/v1/sales/inventory/inventory/notifications
Traceback (most recent call last):
  File "/Library/Frameworks/Python.framework/Versions/3.10/lib/python3.10/site-packages/django/core/handlers/exception.py", line 55, in inner
    response = get_response(request)
  File "/Library/Frameworks/Python.framework/Versions/3.10/lib/python3.10/site-packages/django/core/handlers/base.py", line 197, in _get_response
    response = wrapped_callback(request, *callback_args, **callback_kwargs)
  File "/Library/Frameworks/Python.framework/Versions/3.10/lib/python3.10/site-packages/django/views/decorators/csrf.py", line 54, in wrapped_view
    return view_func(*args, **kwargs)
  File "/Library/Frameworks/Python.framework/Versions/3.10/lib/python3.10/site-packages/django/views/generic/base.py", line 103, in view
    return self.dispatch(request, *args, **kwargs)
  File "/Library/Frameworks/Python.framework/Versions/3.10/lib/python3.10/site-packages/rest_framework/views.py", line 509, in dispatch
    response = self.handle_exception(exc)
  File "/Library/Frameworks/Python.framework/Versions/3.10/lib/python3.10/site-packages/rest_framework/views.py", line 469, in handle_exception
    self.raise_uncaught_exception(exc)
  File "/Library/Frameworks/Python.framework/Versions/3.10/lib/python3.10/site-packages/rest_framework/views.py", line 480, in raise_uncaught_exception
    raise exc
  File "/Library/Frameworks/Python.framework/Versions/3.10/lib/python3.10/site-packages/rest_framework/views.py", line 506, in dispatch
    response = handler(request, *args, **kwargs)
  File "/Users/macmini/Machine Learning/backup12_07/sales/api/inventory/views.py", line 816, in get
    notification = Notification.objects.get(user=user)
  File "/Library/Frameworks/Python.framework/Versions/3.10/lib/python3.10/site-packages/django/db/models/manager.py", line 85, in manager_method
    return getattr(self.get_queryset(), name)(*args, **kwargs)
  File "/Library/Frameworks/Python.framework/Versions/3.10/lib/python3.10/site-packages/django/db/models/query.py", line 650, in get
    raise self.model.DoesNotExist(
sales.models.Notification.DoesNotExist: Notification matching query does not exist.
"GET /api/v1/sales/inventory/inventory/notifications HTTP/1.1" 500 99656
test_path/bar_codes/base/white.png /bar_codes/base/out/out.png
test_path/bar_codes/base/white.png /bar_codes/base/out/out.png
Internal Server Error: /api/v1/sales/inventory/inventory/notifications
Traceback (most recent call last):
  File "/Library/Frameworks/Python.framework/Versions/3.10/lib/python3.10/site-packages/django/core/handlers/exception.py", line 55, in inner
    response = get_response(request)
  File "/Library/Frameworks/Python.framework/Versions/3.10/lib/python3.10/site-packages/django/core/handlers/base.py", line 220, in _get_response
    response = response.render()
  File "/Library/Frameworks/Python.framework/Versions/3.10/lib/python3.10/site-packages/django/template/response.py", line 114, in render
    self.content = self.rendered_content
  File "/Library/Frameworks/Python.framework/Versions/3.10/lib/python3.10/site-packages/rest_framework/response.py", line 70, in rendered_content
    ret = renderer.render(self.data, accepted_media_type, context)
  File "/Users/macmini/Machine Learning/backup12_07/coreapp/renderers.py", line 26, in render
    return super(CustomRenderer, self).render(response, accepted_media_type, renderer_context)
  File "/Library/Frameworks/Python.framework/Versions/3.10/lib/python3.10/site-packages/rest_framework/renderers.py", line 99, in render
    ret = json.dumps(
  File "/Library/Frameworks/Python.framework/Versions/3.10/lib/python3.10/site-packages/rest_framework/utils/json.py", line 25, in dumps
    return json.dumps(*args, **kwargs)
  File "/Library/Frameworks/Python.framework/Versions/3.10/lib/python3.10/json/__init__.py", line 238, in dumps
    **kw).encode(obj)
  File "/Library/Frameworks/Python.framework/Versions/3.10/lib/python3.10/json/encoder.py", line 199, in encode
    chunks = self.iterencode(o, _one_shot=True)
  File "/Library/Frameworks/Python.framework/Versions/3.10/lib/python3.10/json/encoder.py", line 257, in iterencode
    return _iterencode(o, 0)
  File "/Library/Frameworks/Python.framework/Versions/3.10/lib/python3.10/site-packages/rest_framework/utils/encoders.py", line 67, in default
    return super().default(obj)
  File "/Library/Frameworks/Python.framework/Versions/3.10/lib/python3.10/json/encoder.py", line 179, in default
    raise TypeError(f'Object of type {o.__class__.__name__} '
TypeError: Object of type User is not JSON serializable
"GET /api/v1/sales/inventory/inventory/notifications HTTP/1.1" 500 104572
Internal Server Error: /api/v1/sales/inventory/inventory/notifications
Traceback (most recent call last):
  File "/Library/Frameworks/Python.framework/Versions/3.10/lib/python3.10/site-packages/django/core/handlers/exception.py", line 55, in inner
    response = get_response(request)
  File "/Library/Frameworks/Python.framework/Versions/3.10/lib/python3.10/site-packages/django/core/handlers/base.py", line 220, in _get_response
    response = response.render()
  File "/Library/Frameworks/Python.framework/Versions/3.10/lib/python3.10/site-packages/django/template/response.py", line 114, in render
    self.content = self.rendered_content
  File "/Library/Frameworks/Python.framework/Versions/3.10/lib/python3.10/site-packages/rest_framework/response.py", line 70, in rendered_content
    ret = renderer.render(self.data, accepted_media_type, context)
  File "/Users/macmini/Machine Learning/backup12_07/coreapp/renderers.py", line 26, in render
    return super(CustomRenderer, self).render(response, accepted_media_type, renderer_context)
  File "/Library/Frameworks/Python.framework/Versions/3.10/lib/python3.10/site-packages/rest_framework/renderers.py", line 99, in render
    ret = json.dumps(
  File "/Library/Frameworks/Python.framework/Versions/3.10/lib/python3.10/site-packages/rest_framework/utils/json.py", line 25, in dumps
    return json.dumps(*args, **kwargs)
  File "/Library/Frameworks/Python.framework/Versions/3.10/lib/python3.10/json/__init__.py", line 238, in dumps
    **kw).encode(obj)
  File "/Library/Frameworks/Python.framework/Versions/3.10/lib/python3.10/json/encoder.py", line 199, in encode
    chunks = self.iterencode(o, _one_shot=True)
  File "/Library/Frameworks/Python.framework/Versions/3.10/lib/python3.10/json/encoder.py", line 257, in iterencode
    return _iterencode(o, 0)
  File "/Library/Frameworks/Python.framework/Versions/3.10/lib/python3.10/site-packages/rest_framework/utils/encoders.py", line 67, in default
    return super().default(obj)
  File "/Library/Frameworks/Python.framework/Versions/3.10/lib/python3.10/json/encoder.py", line 179, in default
    raise TypeError(f'Object of type {o.__class__.__name__} '
TypeError: Object of type User is not JSON serializable
"GET /api/v1/sales/inventory/inventory/notifications HTTP/1.1" 500 104572
Internal Server Error: /api/v1/sales/inventory/inventory/notifications
Traceback (most recent call last):
  File "/Library/Frameworks/Python.framework/Versions/3.10/lib/python3.10/site-packages/django/core/handlers/exception.py", line 55, in inner
    response = get_response(request)
  File "/Library/Frameworks/Python.framework/Versions/3.10/lib/python3.10/site-packages/django/core/handlers/base.py", line 220, in _get_response
    response = response.render()
  File "/Library/Frameworks/Python.framework/Versions/3.10/lib/python3.10/site-packages/django/template/response.py", line 114, in render
    self.content = self.rendered_content
  File "/Library/Frameworks/Python.framework/Versions/3.10/lib/python3.10/site-packages/rest_framework/response.py", line 70, in rendered_content
    ret = renderer.render(self.data, accepted_media_type, context)
  File "/Users/macmini/Machine Learning/backup12_07/coreapp/renderers.py", line 26, in render
    return super(CustomRenderer, self).render(response, accepted_media_type, renderer_context)
  File "/Library/Frameworks/Python.framework/Versions/3.10/lib/python3.10/site-packages/rest_framework/renderers.py", line 99, in render
    ret = json.dumps(
  File "/Library/Frameworks/Python.framework/Versions/3.10/lib/python3.10/site-packages/rest_framework/utils/json.py", line 25, in dumps
    return json.dumps(*args, **kwargs)
  File "/Library/Frameworks/Python.framework/Versions/3.10/lib/python3.10/json/__init__.py", line 238, in dumps
    **kw).encode(obj)
  File "/Library/Frameworks/Python.framework/Versions/3.10/lib/python3.10/json/encoder.py", line 199, in encode
    chunks = self.iterencode(o, _one_shot=True)
  File "/Library/Frameworks/Python.framework/Versions/3.10/lib/python3.10/json/encoder.py", line 257, in iterencode
    return _iterencode(o, 0)
  File "/Library/Frameworks/Python.framework/Versions/3.10/lib/python3.10/site-packages/rest_framework/utils/encoders.py", line 67, in default
    return super().default(obj)
  File "/Library/Frameworks/Python.framework/Versions/3.10/lib/python3.10/json/encoder.py", line 179, in default
    raise TypeError(f'Object of type {o.__class__.__name__} '
TypeError: Object of type User is not JSON serializable
"GET /api/v1/sales/inventory/inventory/notifications HTTP/1.1" 500 104572
Internal Server Error: /api/v1/sales/inventory/inventory/notifications
Traceback (most recent call last):
  File "/Library/Frameworks/Python.framework/Versions/3.10/lib/python3.10/site-packages/django/core/handlers/exception.py", line 55, in inner
    response = get_response(request)
  File "/Library/Frameworks/Python.framework/Versions/3.10/lib/python3.10/site-packages/django/core/handlers/base.py", line 220, in _get_response
    response = response.render()
  File "/Library/Frameworks/Python.framework/Versions/3.10/lib/python3.10/site-packages/django/template/response.py", line 114, in render
    self.content = self.rendered_content
  File "/Library/Frameworks/Python.framework/Versions/3.10/lib/python3.10/site-packages/rest_framework/response.py", line 70, in rendered_content
    ret = renderer.render(self.data, accepted_media_type, context)
  File "/Users/macmini/Machine Learning/backup12_07/coreapp/renderers.py", line 26, in render
    return super(CustomRenderer, self).render(response, accepted_media_type, renderer_context)
  File "/Library/Frameworks/Python.framework/Versions/3.10/lib/python3.10/site-packages/rest_framework/renderers.py", line 99, in render
    ret = json.dumps(
  File "/Library/Frameworks/Python.framework/Versions/3.10/lib/python3.10/site-packages/rest_framework/utils/json.py", line 25, in dumps
    return json.dumps(*args, **kwargs)
  File "/Library/Frameworks/Python.framework/Versions/3.10/lib/python3.10/json/__init__.py", line 238, in dumps
    **kw).encode(obj)
  File "/Library/Frameworks/Python.framework/Versions/3.10/lib/python3.10/json/encoder.py", line 199, in encode
    chunks = self.iterencode(o, _one_shot=True)
  File "/Library/Frameworks/Python.framework/Versions/3.10/lib/python3.10/json/encoder.py", line 257, in iterencode
    return _iterencode(o, 0)
  File "/Library/Frameworks/Python.framework/Versions/3.10/lib/python3.10/site-packages/rest_framework/utils/encoders.py", line 67, in default
    return super().default(obj)
  File "/Library/Frameworks/Python.framework/Versions/3.10/lib/python3.10/json/encoder.py", line 179, in default
    raise TypeError(f'Object of type {o.__class__.__name__} '
TypeError: Object of type User is not JSON serializable
"GET /api/v1/sales/inventory/inventory/notifications HTTP/1.1" 500 104572
test_path/bar_codes/base/white.png /bar_codes/base/out/out.png
test_path/bar_codes/base/white.png /bar_codes/base/out/out.png
Internal Server Error: /api/v1/sales/inventory/inventory/notifications
Traceback (most recent call last):
  File "/Library/Frameworks/Python.framework/Versions/3.10/lib/python3.10/site-packages/django/core/handlers/exception.py", line 55, in inner
    response = get_response(request)
  File "/Library/Frameworks/Python.framework/Versions/3.10/lib/python3.10/site-packages/django/core/handlers/base.py", line 220, in _get_response
    response = response.render()
  File "/Library/Frameworks/Python.framework/Versions/3.10/lib/python3.10/site-packages/django/template/response.py", line 114, in render
    self.content = self.rendered_content
  File "/Library/Frameworks/Python.framework/Versions/3.10/lib/python3.10/site-packages/rest_framework/response.py", line 70, in rendered_content
    ret = renderer.render(self.data, accepted_media_type, context)
  File "/Users/macmini/Machine Learning/backup12_07/coreapp/renderers.py", line 26, in render
    return super(CustomRenderer, self).render(response, accepted_media_type, renderer_context)
  File "/Library/Frameworks/Python.framework/Versions/3.10/lib/python3.10/site-packages/rest_framework/renderers.py", line 99, in render
    ret = json.dumps(
  File "/Library/Frameworks/Python.framework/Versions/3.10/lib/python3.10/site-packages/rest_framework/utils/json.py", line 25, in dumps
    return json.dumps(*args, **kwargs)
  File "/Library/Frameworks/Python.framework/Versions/3.10/lib/python3.10/json/__init__.py", line 238, in dumps
    **kw).encode(obj)
  File "/Library/Frameworks/Python.framework/Versions/3.10/lib/python3.10/json/encoder.py", line 199, in encode
    chunks = self.iterencode(o, _one_shot=True)
  File "/Library/Frameworks/Python.framework/Versions/3.10/lib/python3.10/json/encoder.py", line 257, in iterencode
    return _iterencode(o, 0)
  File "/Library/Frameworks/Python.framework/Versions/3.10/lib/python3.10/site-packages/rest_framework/utils/encoders.py", line 67, in default
    return super().default(obj)
  File "/Library/Frameworks/Python.framework/Versions/3.10/lib/python3.10/json/encoder.py", line 179, in default
    raise TypeError(f'Object of type {o.__class__.__name__} '
TypeError: Object of type User is not JSON serializable
"GET /api/v1/sales/inventory/inventory/notifications HTTP/1.1" 500 104572
Internal Server Error: /api/v1/sales/inventory/inventory/notifications
Traceback (most recent call last):
  File "/Library/Frameworks/Python.framework/Versions/3.10/lib/python3.10/site-packages/django/core/handlers/exception.py", line 55, in inner
    response = get_response(request)
  File "/Library/Frameworks/Python.framework/Versions/3.10/lib/python3.10/site-packages/django/core/handlers/base.py", line 220, in _get_response
    response = response.render()
  File "/Library/Frameworks/Python.framework/Versions/3.10/lib/python3.10/site-packages/django/template/response.py", line 114, in render
    self.content = self.rendered_content
  File "/Library/Frameworks/Python.framework/Versions/3.10/lib/python3.10/site-packages/rest_framework/response.py", line 70, in rendered_content
    ret = renderer.render(self.data, accepted_media_type, context)
  File "/Users/macmini/Machine Learning/backup12_07/coreapp/renderers.py", line 26, in render
    return super(CustomRenderer, self).render(response, accepted_media_type, renderer_context)
  File "/Library/Frameworks/Python.framework/Versions/3.10/lib/python3.10/site-packages/rest_framework/renderers.py", line 99, in render
    ret = json.dumps(
  File "/Library/Frameworks/Python.framework/Versions/3.10/lib/python3.10/site-packages/rest_framework/utils/json.py", line 25, in dumps
    return json.dumps(*args, **kwargs)
  File "/Library/Frameworks/Python.framework/Versions/3.10/lib/python3.10/json/__init__.py", line 238, in dumps
    **kw).encode(obj)
  File "/Library/Frameworks/Python.framework/Versions/3.10/lib/python3.10/json/encoder.py", line 199, in encode
    chunks = self.iterencode(o, _one_shot=True)
  File "/Library/Frameworks/Python.framework/Versions/3.10/lib/python3.10/json/encoder.py", line 257, in iterencode
    return _iterencode(o, 0)
  File "/Library/Frameworks/Python.framework/Versions/3.10/lib/python3.10/site-packages/rest_framework/utils/encoders.py", line 67, in default
    return super().default(obj)
  File "/Library/Frameworks/Python.framework/Versions/3.10/lib/python3.10/json/encoder.py", line 179, in default
    raise TypeError(f'Object of type {o.__class__.__name__} '
TypeError: Object of type User is not JSON serializable
"GET /api/v1/sales/inventory/inventory/notifications HTTP/1.1" 500 104572
Internal Server Error: /api/v1/sales/inventory/inventory/notifications
Traceback (most recent call last):
  File "/Library/Frameworks/Python.framework/Versions/3.10/lib/python3.10/site-packages/django/core/handlers/exception.py", line 55, in inner
    response = get_response(request)
  File "/Library/Frameworks/Python.framework/Versions/3.10/lib/python3.10/site-packages/django/core/handlers/base.py", line 220, in _get_response
    response = response.render()
  File "/Library/Frameworks/Python.framework/Versions/3.10/lib/python3.10/site-packages/django/template/response.py", line 114, in render
    self.content = self.rendered_content
  File "/Library/Frameworks/Python.framework/Versions/3.10/lib/python3.10/site-packages/rest_framework/response.py", line 70, in rendered_content
    ret = renderer.render(self.data, accepted_media_type, context)
  File "/Users/macmini/Machine Learning/backup12_07/coreapp/renderers.py", line 26, in render
    return super(CustomRenderer, self).render(response, accepted_media_type, renderer_context)
  File "/Library/Frameworks/Python.framework/Versions/3.10/lib/python3.10/site-packages/rest_framework/renderers.py", line 99, in render
    ret = json.dumps(
  File "/Library/Frameworks/Python.framework/Versions/3.10/lib/python3.10/site-packages/rest_framework/utils/json.py", line 25, in dumps
    return json.dumps(*args, **kwargs)
  File "/Library/Frameworks/Python.framework/Versions/3.10/lib/python3.10/json/__init__.py", line 238, in dumps
    **kw).encode(obj)
  File "/Library/Frameworks/Python.framework/Versions/3.10/lib/python3.10/json/encoder.py", line 199, in encode
    chunks = self.iterencode(o, _one_shot=True)
  File "/Library/Frameworks/Python.framework/Versions/3.10/lib/python3.10/json/encoder.py", line 257, in iterencode
    return _iterencode(o, 0)
  File "/Library/Frameworks/Python.framework/Versions/3.10/lib/python3.10/site-packages/rest_framework/utils/encoders.py", line 67, in default
    return super().default(obj)
  File "/Library/Frameworks/Python.framework/Versions/3.10/lib/python3.10/json/encoder.py", line 179, in default
    raise TypeError(f'Object of type {o.__class__.__name__} '
TypeError: Object of type User is not JSON serializable
"GET /api/v1/sales/inventory/inventory/notifications HTTP/1.1" 500 104572
Internal Server Error: /api/v1/sales/inventory/inventory/notifications
Traceback (most recent call last):
  File "/Library/Frameworks/Python.framework/Versions/3.10/lib/python3.10/site-packages/django/core/handlers/exception.py", line 55, in inner
    response = get_response(request)
  File "/Library/Frameworks/Python.framework/Versions/3.10/lib/python3.10/site-packages/django/core/handlers/base.py", line 220, in _get_response
    response = response.render()
  File "/Library/Frameworks/Python.framework/Versions/3.10/lib/python3.10/site-packages/django/template/response.py", line 114, in render
    self.content = self.rendered_content
  File "/Library/Frameworks/Python.framework/Versions/3.10/lib/python3.10/site-packages/rest_framework/response.py", line 70, in rendered_content
    ret = renderer.render(self.data, accepted_media_type, context)
  File "/Users/macmini/Machine Learning/backup12_07/coreapp/renderers.py", line 26, in render
    return super(CustomRenderer, self).render(response, accepted_media_type, renderer_context)
  File "/Library/Frameworks/Python.framework/Versions/3.10/lib/python3.10/site-packages/rest_framework/renderers.py", line 99, in render
    ret = json.dumps(
  File "/Library/Frameworks/Python.framework/Versions/3.10/lib/python3.10/site-packages/rest_framework/utils/json.py", line 25, in dumps
    return json.dumps(*args, **kwargs)
  File "/Library/Frameworks/Python.framework/Versions/3.10/lib/python3.10/json/__init__.py", line 238, in dumps
    **kw).encode(obj)
  File "/Library/Frameworks/Python.framework/Versions/3.10/lib/python3.10/json/encoder.py", line 199, in encode
    chunks = self.iterencode(o, _one_shot=True)
  File "/Library/Frameworks/Python.framework/Versions/3.10/lib/python3.10/json/encoder.py", line 257, in iterencode
    return _iterencode(o, 0)
  File "/Library/Frameworks/Python.framework/Versions/3.10/lib/python3.10/site-packages/rest_framework/utils/encoders.py", line 67, in default
    return super().default(obj)
  File "/Library/Frameworks/Python.framework/Versions/3.10/lib/python3.10/json/encoder.py", line 179, in default
    raise TypeError(f'Object of type {o.__class__.__name__} '
TypeError: Object of type User is not JSON serializable
"GET /api/v1/sales/inventory/inventory/notifications HTTP/1.1" 500 104572
Internal Server Error: /api/v1/sales/inventory/inventory/notifications
Traceback (most recent call last):
  File "/Library/Frameworks/Python.framework/Versions/3.10/lib/python3.10/site-packages/django/core/handlers/exception.py", line 55, in inner
    response = get_response(request)
  File "/Library/Frameworks/Python.framework/Versions/3.10/lib/python3.10/site-packages/django/core/handlers/base.py", line 220, in _get_response
    response = response.render()
  File "/Library/Frameworks/Python.framework/Versions/3.10/lib/python3.10/site-packages/django/template/response.py", line 114, in render
    self.content = self.rendered_content
  File "/Library/Frameworks/Python.framework/Versions/3.10/lib/python3.10/site-packages/rest_framework/response.py", line 70, in rendered_content
    ret = renderer.render(self.data, accepted_media_type, context)
  File "/Users/macmini/Machine Learning/backup12_07/coreapp/renderers.py", line 26, in render
    return super(CustomRenderer, self).render(response, accepted_media_type, renderer_context)
  File "/Library/Frameworks/Python.framework/Versions/3.10/lib/python3.10/site-packages/rest_framework/renderers.py", line 99, in render
    ret = json.dumps(
  File "/Library/Frameworks/Python.framework/Versions/3.10/lib/python3.10/site-packages/rest_framework/utils/json.py", line 25, in dumps
    return json.dumps(*args, **kwargs)
  File "/Library/Frameworks/Python.framework/Versions/3.10/lib/python3.10/json/__init__.py", line 238, in dumps
    **kw).encode(obj)
  File "/Library/Frameworks/Python.framework/Versions/3.10/lib/python3.10/json/encoder.py", line 199, in encode
    chunks = self.iterencode(o, _one_shot=True)
  File "/Library/Frameworks/Python.framework/Versions/3.10/lib/python3.10/json/encoder.py", line 257, in iterencode
    return _iterencode(o, 0)
  File "/Library/Frameworks/Python.framework/Versions/3.10/lib/python3.10/site-packages/rest_framework/utils/encoders.py", line 67, in default
    return super().default(obj)
  File "/Library/Frameworks/Python.framework/Versions/3.10/lib/python3.10/json/encoder.py", line 179, in default
    raise TypeError(f'Object of type {o.__class__.__name__} '
TypeError: Object of type User is not JSON serializable
"GET /api/v1/sales/inventory/inventory/notifications HTTP/1.1" 500 104572
test_path/bar_codes/base/white.png /bar_codes/base/out/out.png
test_path/bar_codes/base/white.png /bar_codes/base/out/out.png
Internal Server Error: /api/v1/sales/inventory/inventory/notifications
Traceback (most recent call last):
  File "/Library/Frameworks/Python.framework/Versions/3.10/lib/python3.10/site-packages/django/core/handlers/exception.py", line 55, in inner
    response = get_response(request)
  File "/Library/Frameworks/Python.framework/Versions/3.10/lib/python3.10/site-packages/django/core/handlers/base.py", line 220, in _get_response
    response = response.render()
  File "/Library/Frameworks/Python.framework/Versions/3.10/lib/python3.10/site-packages/django/template/response.py", line 114, in render
    self.content = self.rendered_content
  File "/Library/Frameworks/Python.framework/Versions/3.10/lib/python3.10/site-packages/rest_framework/response.py", line 70, in rendered_content
    ret = renderer.render(self.data, accepted_media_type, context)
  File "/Users/macmini/Machine Learning/backup12_07/coreapp/renderers.py", line 26, in render
    return super(CustomRenderer, self).render(response, accepted_media_type, renderer_context)
  File "/Library/Frameworks/Python.framework/Versions/3.10/lib/python3.10/site-packages/rest_framework/renderers.py", line 99, in render
    ret = json.dumps(
  File "/Library/Frameworks/Python.framework/Versions/3.10/lib/python3.10/site-packages/rest_framework/utils/json.py", line 25, in dumps
    return json.dumps(*args, **kwargs)
  File "/Library/Frameworks/Python.framework/Versions/3.10/lib/python3.10/json/__init__.py", line 238, in dumps
    **kw).encode(obj)
  File "/Library/Frameworks/Python.framework/Versions/3.10/lib/python3.10/json/encoder.py", line 199, in encode
    chunks = self.iterencode(o, _one_shot=True)
  File "/Library/Frameworks/Python.framework/Versions/3.10/lib/python3.10/json/encoder.py", line 257, in iterencode
    return _iterencode(o, 0)
  File "/Library/Frameworks/Python.framework/Versions/3.10/lib/python3.10/site-packages/rest_framework/utils/encoders.py", line 67, in default
    return super().default(obj)
  File "/Library/Frameworks/Python.framework/Versions/3.10/lib/python3.10/json/encoder.py", line 179, in default
    raise TypeError(f'Object of type {o.__class__.__name__} '
TypeError: Object of type User is not JSON serializable
"GET /api/v1/sales/inventory/inventory/notifications HTTP/1.1" 500 104572
test_path/bar_codes/base/white.png /bar_codes/base/out/out.png
Internal Server Error: /admin/sales/invoice/14/change/
Traceback (most recent call last):
  File "/Library/Frameworks/Python.framework/Versions/3.10/lib/python3.10/site-packages/django/core/handlers/exception.py", line 55, in inner
    response = get_response(request)
  File "/Library/Frameworks/Python.framework/Versions/3.10/lib/python3.10/site-packages/django/core/handlers/base.py", line 197, in _get_response
    response = wrapped_callback(request, *callback_args, **callback_kwargs)
  File "/Library/Frameworks/Python.framework/Versions/3.10/lib/python3.10/site-packages/django/contrib/admin/options.py", line 686, in wrapper
    return self.admin_site.admin_view(view)(*args, **kwargs)
  File "/Library/Frameworks/Python.framework/Versions/3.10/lib/python3.10/site-packages/django/utils/decorators.py", line 133, in _wrapped_view
    response = view_func(request, *args, **kwargs)
  File "/Library/Frameworks/Python.framework/Versions/3.10/lib/python3.10/site-packages/django/views/decorators/cache.py", line 62, in _wrapped_view_func
    response = view_func(request, *args, **kwargs)
  File "/Library/Frameworks/Python.framework/Versions/3.10/lib/python3.10/site-packages/django/contrib/admin/sites.py", line 242, in inner
    return view(request, *args, **kwargs)
  File "/Library/Frameworks/Python.framework/Versions/3.10/lib/python3.10/site-packages/django/contrib/admin/options.py", line 1893, in change_view
    return self.changeform_view(request, object_id, form_url, extra_context)
  File "/Library/Frameworks/Python.framework/Versions/3.10/lib/python3.10/site-packages/django/utils/decorators.py", line 46, in _wrapper
    return bound_method(*args, **kwargs)
  File "/Library/Frameworks/Python.framework/Versions/3.10/lib/python3.10/site-packages/django/utils/decorators.py", line 133, in _wrapped_view
    response = view_func(request, *args, **kwargs)
  File "/Library/Frameworks/Python.framework/Versions/3.10/lib/python3.10/site-packages/django/contrib/admin/options.py", line 1750, in changeform_view
    return self._changeform_view(request, object_id, form_url, extra_context)
  File "/Library/Frameworks/Python.framework/Versions/3.10/lib/python3.10/site-packages/django/contrib/admin/options.py", line 1802, in _changeform_view
    self.save_model(request, new_object, form, not add)
  File "/Users/macmini/Machine Learning/backup12_07/sales/admin.py", line 13, in save_model
    obj.save()
  File "/Users/macmini/Machine Learning/backup12_07/sales/models.py", line 138, in save
    notification, created = Notification.objects.get_or_create(user=self.user)
AttributeError: 'Invoice' object has no attribute 'user'
"POST /admin/sales/invoice/14/change/ HTTP/1.1" 500 122797
Error in generate_product_barcode:  
 Traceback (most recent call last):
  File "/Users/macmini/Machine Learning/backup12_07/utility/utils/bar_image_utils.py", line 59, in add_images_and_text
    modified_image = insert_text(image_path, text, output_path, size=30, add_x=0, position_y=2,color='white')
  File "/Users/macmini/Machine Learning/backup12_07/utility/utils/bar_image_utils.py", line 6, in insert_text
    image = Image.open(image_path)
  File "/Library/Frameworks/Python.framework/Versions/3.10/lib/python3.10/site-packages/PIL/Image.py", line 3236, in open
    fp = builtins.open(filename, "rb")
FileNotFoundError: [Errno 2] No such file or directory: '/bar_codes/base/white.png'

test_path/bar_codes/base/white.png /bar_codes/base/out/out.png
test_path/bar_codes/base/white.png /bar_codes/base/out/out.png
test_path/bar_codes/base/white.png /bar_codes/base/out/out.png
test_path/bar_codes/base/white.png /bar_codes/base/out/out.png
test_path/bar_codes/base/white.png /bar_codes/base/out/out.png
Internal Server Error: /admin/sales/invoice/add/
Traceback (most recent call last):
  File "/Library/Frameworks/Python.framework/Versions/3.10/lib/python3.10/site-packages/django/core/handlers/exception.py", line 55, in inner
    response = get_response(request)
  File "/Library/Frameworks/Python.framework/Versions/3.10/lib/python3.10/site-packages/django/core/handlers/base.py", line 197, in _get_response
    response = wrapped_callback(request, *callback_args, **callback_kwargs)
  File "/Library/Frameworks/Python.framework/Versions/3.10/lib/python3.10/site-packages/django/contrib/admin/options.py", line 686, in wrapper
    return self.admin_site.admin_view(view)(*args, **kwargs)
  File "/Library/Frameworks/Python.framework/Versions/3.10/lib/python3.10/site-packages/django/utils/decorators.py", line 133, in _wrapped_view
    response = view_func(request, *args, **kwargs)
  File "/Library/Frameworks/Python.framework/Versions/3.10/lib/python3.10/site-packages/django/views/decorators/cache.py", line 62, in _wrapped_view_func
    response = view_func(request, *args, **kwargs)
  File "/Library/Frameworks/Python.framework/Versions/3.10/lib/python3.10/site-packages/django/contrib/admin/sites.py", line 242, in inner
    return view(request, *args, **kwargs)
  File "/Library/Frameworks/Python.framework/Versions/3.10/lib/python3.10/site-packages/django/contrib/admin/options.py", line 1890, in add_view
    return self.changeform_view(request, None, form_url, extra_context)
  File "/Library/Frameworks/Python.framework/Versions/3.10/lib/python3.10/site-packages/django/utils/decorators.py", line 46, in _wrapper
    return bound_method(*args, **kwargs)
  File "/Library/Frameworks/Python.framework/Versions/3.10/lib/python3.10/site-packages/django/utils/decorators.py", line 133, in _wrapped_view
    response = view_func(request, *args, **kwargs)
  File "/Library/Frameworks/Python.framework/Versions/3.10/lib/python3.10/site-packages/django/contrib/admin/options.py", line 1750, in changeform_view
    return self._changeform_view(request, object_id, form_url, extra_context)
  File "/Library/Frameworks/Python.framework/Versions/3.10/lib/python3.10/site-packages/django/contrib/admin/options.py", line 1802, in _changeform_view
    self.save_model(request, new_object, form, not add)
  File "/Users/macmini/Machine Learning/backup12_07/sales/admin.py", line 13, in save_model
    obj.save()
  File "/Users/macmini/Machine Learning/backup12_07/sales/models.py", line 138, in save
    notification, created = Notification.objects.get_or_create(user=self.user)
AttributeError: 'Invoice' object has no attribute 'user'
"POST /admin/sales/invoice/add/ HTTP/1.1" 500 122148
Internal Server Error: /admin/sales/invoice/add/
Traceback (most recent call last):
  File "/Library/Frameworks/Python.framework/Versions/3.10/lib/python3.10/site-packages/django/core/handlers/exception.py", line 55, in inner
    response = get_response(request)
  File "/Library/Frameworks/Python.framework/Versions/3.10/lib/python3.10/site-packages/django/core/handlers/base.py", line 197, in _get_response
    response = wrapped_callback(request, *callback_args, **callback_kwargs)
  File "/Library/Frameworks/Python.framework/Versions/3.10/lib/python3.10/site-packages/django/contrib/admin/options.py", line 686, in wrapper
    return self.admin_site.admin_view(view)(*args, **kwargs)
  File "/Library/Frameworks/Python.framework/Versions/3.10/lib/python3.10/site-packages/django/utils/decorators.py", line 133, in _wrapped_view
    response = view_func(request, *args, **kwargs)
  File "/Library/Frameworks/Python.framework/Versions/3.10/lib/python3.10/site-packages/django/views/decorators/cache.py", line 62, in _wrapped_view_func
    response = view_func(request, *args, **kwargs)
  File "/Library/Frameworks/Python.framework/Versions/3.10/lib/python3.10/site-packages/django/contrib/admin/sites.py", line 242, in inner
    return view(request, *args, **kwargs)
  File "/Library/Frameworks/Python.framework/Versions/3.10/lib/python3.10/site-packages/django/contrib/admin/options.py", line 1890, in add_view
    return self.changeform_view(request, None, form_url, extra_context)
  File "/Library/Frameworks/Python.framework/Versions/3.10/lib/python3.10/site-packages/django/utils/decorators.py", line 46, in _wrapper
    return bound_method(*args, **kwargs)
  File "/Library/Frameworks/Python.framework/Versions/3.10/lib/python3.10/site-packages/django/utils/decorators.py", line 133, in _wrapped_view
    response = view_func(request, *args, **kwargs)
  File "/Library/Frameworks/Python.framework/Versions/3.10/lib/python3.10/site-packages/django/contrib/admin/options.py", line 1750, in changeform_view
    return self._changeform_view(request, object_id, form_url, extra_context)
  File "/Library/Frameworks/Python.framework/Versions/3.10/lib/python3.10/site-packages/django/contrib/admin/options.py", line 1802, in _changeform_view
    self.save_model(request, new_object, form, not add)
  File "/Users/macmini/Machine Learning/backup12_07/sales/admin.py", line 13, in save_model
    obj.save()
  File "/Users/macmini/Machine Learning/backup12_07/sales/models.py", line 138, in save
    notification, created = Notification.objects.get_or_create(user=self.user)
AttributeError: 'Invoice' object has no attribute 'user'
"POST /admin/sales/invoice/add/ HTTP/1.1" 500 122148
test_path/bar_codes/base/white.png /bar_codes/base/out/out.png
test_path/bar_codes/base/white.png /bar_codes/base/out/out.png
test_path/bar_codes/base/white.png /bar_codes/base/out/out.png
test_path/bar_codes/base/white.png /bar_codes/base/out/out.png
test_path/bar_codes/base/white.png /bar_codes/base/out/out.png
test_path/bar_codes/base/white.png /bar_codes/base/out/out.png
test_path/bar_codes/base/white.png /bar_codes/base/out/out.png
test_path/bar_codes/base/white.png /bar_codes/base/out/out.png
Internal Server Error: /admin/sales/invoice/add/
Traceback (most recent call last):
  File "/Library/Frameworks/Python.framework/Versions/3.10/lib/python3.10/site-packages/django/core/handlers/exception.py", line 55, in inner
    response = get_response(request)
  File "/Library/Frameworks/Python.framework/Versions/3.10/lib/python3.10/site-packages/django/core/handlers/base.py", line 197, in _get_response
    response = wrapped_callback(request, *callback_args, **callback_kwargs)
  File "/Library/Frameworks/Python.framework/Versions/3.10/lib/python3.10/site-packages/django/contrib/admin/options.py", line 686, in wrapper
    return self.admin_site.admin_view(view)(*args, **kwargs)
  File "/Library/Frameworks/Python.framework/Versions/3.10/lib/python3.10/site-packages/django/utils/decorators.py", line 133, in _wrapped_view
    response = view_func(request, *args, **kwargs)
  File "/Library/Frameworks/Python.framework/Versions/3.10/lib/python3.10/site-packages/django/views/decorators/cache.py", line 62, in _wrapped_view_func
    response = view_func(request, *args, **kwargs)
  File "/Library/Frameworks/Python.framework/Versions/3.10/lib/python3.10/site-packages/django/contrib/admin/sites.py", line 242, in inner
    return view(request, *args, **kwargs)
  File "/Library/Frameworks/Python.framework/Versions/3.10/lib/python3.10/site-packages/django/contrib/admin/options.py", line 1890, in add_view
    return self.changeform_view(request, None, form_url, extra_context)
  File "/Library/Frameworks/Python.framework/Versions/3.10/lib/python3.10/site-packages/django/utils/decorators.py", line 46, in _wrapper
    return bound_method(*args, **kwargs)
  File "/Library/Frameworks/Python.framework/Versions/3.10/lib/python3.10/site-packages/django/utils/decorators.py", line 133, in _wrapped_view
    response = view_func(request, *args, **kwargs)
  File "/Library/Frameworks/Python.framework/Versions/3.10/lib/python3.10/site-packages/django/contrib/admin/options.py", line 1750, in changeform_view
    return self._changeform_view(request, object_id, form_url, extra_context)
  File "/Library/Frameworks/Python.framework/Versions/3.10/lib/python3.10/site-packages/django/contrib/admin/options.py", line 1802, in _changeform_view
    self.save_model(request, new_object, form, not add)
  File "/Users/macmini/Machine Learning/backup12_07/sales/admin.py", line 13, in save_model
    obj.save()
  File "/Users/macmini/Machine Learning/backup12_07/sales/models.py", line 138, in save
    notification, created = Notification.objects.get_or_create(user=self.user)
AttributeError: 'Invoice' object has no attribute 'user'
"POST /admin/sales/invoice/add/ HTTP/1.1" 500 122016
test_path/bar_codes/base/white.png /bar_codes/base/out/out.png
test_path/bar_codes/base/white.png /bar_codes/base/out/out.png
test_path/bar_codes/base/white.png /bar_codes/base/out/out.png
test_path/bar_codes/base/white.png /bar_codes/base/out/out.png
Internal Server Error: /admin/sales/invoice/17/change/
Traceback (most recent call last):
  File "/Library/Frameworks/Python.framework/Versions/3.10/lib/python3.10/site-packages/django/core/handlers/exception.py", line 55, in inner
    response = get_response(request)
  File "/Library/Frameworks/Python.framework/Versions/3.10/lib/python3.10/site-packages/django/core/handlers/base.py", line 197, in _get_response
    response = wrapped_callback(request, *callback_args, **callback_kwargs)
  File "/Library/Frameworks/Python.framework/Versions/3.10/lib/python3.10/site-packages/django/contrib/admin/options.py", line 686, in wrapper
    return self.admin_site.admin_view(view)(*args, **kwargs)
  File "/Library/Frameworks/Python.framework/Versions/3.10/lib/python3.10/site-packages/django/utils/decorators.py", line 133, in _wrapped_view
    response = view_func(request, *args, **kwargs)
  File "/Library/Frameworks/Python.framework/Versions/3.10/lib/python3.10/site-packages/django/views/decorators/cache.py", line 62, in _wrapped_view_func
    response = view_func(request, *args, **kwargs)
  File "/Library/Frameworks/Python.framework/Versions/3.10/lib/python3.10/site-packages/django/contrib/admin/sites.py", line 242, in inner
    return view(request, *args, **kwargs)
  File "/Library/Frameworks/Python.framework/Versions/3.10/lib/python3.10/site-packages/django/contrib/admin/options.py", line 1893, in change_view
    return self.changeform_view(request, object_id, form_url, extra_context)
  File "/Library/Frameworks/Python.framework/Versions/3.10/lib/python3.10/site-packages/django/utils/decorators.py", line 46, in _wrapper
    return bound_method(*args, **kwargs)
  File "/Library/Frameworks/Python.framework/Versions/3.10/lib/python3.10/site-packages/django/utils/decorators.py", line 133, in _wrapped_view
    response = view_func(request, *args, **kwargs)
  File "/Library/Frameworks/Python.framework/Versions/3.10/lib/python3.10/site-packages/django/contrib/admin/options.py", line 1750, in changeform_view
    return self._changeform_view(request, object_id, form_url, extra_context)
  File "/Library/Frameworks/Python.framework/Versions/3.10/lib/python3.10/site-packages/django/contrib/admin/options.py", line 1802, in _changeform_view
    self.save_model(request, new_object, form, not add)
  File "/Users/macmini/Machine Learning/backup12_07/sales/admin.py", line 13, in save_model
    obj.save()
  File "/Users/macmini/Machine Learning/backup12_07/sales/models.py", line 135, in save
    super().save(*args, **kwargs)
  File "/Library/Frameworks/Python.framework/Versions/3.10/lib/python3.10/site-packages/django/db/models/base.py", line 831, in save
    self.save_base(
  File "/Library/Frameworks/Python.framework/Versions/3.10/lib/python3.10/site-packages/django/db/models/base.py", line 897, in save_base
    post_save.send(
  File "/Library/Frameworks/Python.framework/Versions/3.10/lib/python3.10/site-packages/django/dispatch/dispatcher.py", line 176, in send
    return [
  File "/Library/Frameworks/Python.framework/Versions/3.10/lib/python3.10/site-packages/django/dispatch/dispatcher.py", line 177, in <listcomp>
    (receiver, receiver(signal=self, sender=sender, **named))
  File "/Users/macmini/Machine Learning/backup12_07/sales/models.py", line 157, in increment_notification_count
    notification, _ = Notification.objects.get_or_create(user=instance.user)
AttributeError: 'Invoice' object has no attribute 'user'
"POST /admin/sales/invoice/17/change/ HTTP/1.1" 500 145061
test_path/bar_codes/base/white.png /bar_codes/base/out/out.png
test_path/bar_codes/base/white.png /bar_codes/base/out/out.png
test_path/bar_codes/base/white.png /bar_codes/base/out/out.png
test_path/bar_codes/base/white.png /bar_codes/base/out/out.png
test_path/bar_codes/base/white.png /bar_codes/base/out/out.png
test_path/bar_codes/base/white.png /bar_codes/base/out/out.png
test_path/bar_codes/base/white.png /bar_codes/base/out/out.png
test_path/bar_codes/base/white.png /bar_codes/base/out/out.png
test_path/bar_codes/base/white.png /bar_codes/base/out/out.png
test_path/bar_codes/base/white.png /bar_codes/base/out/out.png
test_path/bar_codes/base/white.png /bar_codes/base/out/out.png
test_path/bar_codes/base/white.png /bar_codes/base/out/out.png
test_path/bar_codes/base/white.png /bar_codes/base/out/out.png
test_path/bar_codes/base/white.png /bar_codes/base/out/out.png
test_path/bar_codes/base/white.png /bar_codes/base/out/out.png
test_path/bar_codes/base/white.png /bar_codes/base/out/out.png
test_path/bar_codes/base/white.png /bar_codes/base/out/out.png
test_path/bar_codes/base/white.png /bar_codes/base/out/out.png
test_path/bar_codes/base/white.png /bar_codes/base/out/out.png
test_path/bar_codes/base/white.png /bar_codes/base/out/out.png
test_path/bar_codes/base/white.png /bar_codes/base/out/out.png
test_path/bar_codes/base/white.png /bar_codes/base/out/out.png
test_path/bar_codes/base/white.png /bar_codes/base/out/out.png
test_path/bar_codes/base/white.png /bar_codes/base/out/out.png
test_path/bar_codes/base/white.png /bar_codes/base/out/out.png
test_path/bar_codes/base/white.png /bar_codes/base/out/out.png
test_path/bar_codes/base/white.png /bar_codes/base/out/out.png
test_path/bar_codes/base/white.png /bar_codes/base/out/out.png
test_path/bar_codes/base/white.png /bar_codes/base/out/out.png
test_path/bar_codes/base/white.png /bar_codes/base/out/out.png
test_path/bar_codes/base/white.png /bar_codes/base/out/out.png
test_path/bar_codes/base/white.png /bar_codes/base/out/out.png
test_path/bar_codes/base/white.png /bar_codes/base/out/out.png
test_path/bar_codes/base/white.png /bar_codes/base/out/out.png
test_path/bar_codes/base/white.png /bar_codes/base/out/out.png
test_path/bar_codes/base/white.png /bar_codes/base/out/out.png
Internal Server Error: /api/v1/sales/inventory/inventory/notifications
Traceback (most recent call last):
  File "/Library/Frameworks/Python.framework/Versions/3.10/lib/python3.10/site-packages/django/core/handlers/exception.py", line 55, in inner
    response = get_response(request)
  File "/Library/Frameworks/Python.framework/Versions/3.10/lib/python3.10/site-packages/django/core/handlers/base.py", line 197, in _get_response
    response = wrapped_callback(request, *callback_args, **callback_kwargs)
  File "/Library/Frameworks/Python.framework/Versions/3.10/lib/python3.10/site-packages/django/views/decorators/csrf.py", line 54, in wrapped_view
    return view_func(*args, **kwargs)
  File "/Library/Frameworks/Python.framework/Versions/3.10/lib/python3.10/site-packages/django/views/generic/base.py", line 103, in view
    return self.dispatch(request, *args, **kwargs)
  File "/Library/Frameworks/Python.framework/Versions/3.10/lib/python3.10/site-packages/rest_framework/views.py", line 509, in dispatch
    response = self.handle_exception(exc)
  File "/Library/Frameworks/Python.framework/Versions/3.10/lib/python3.10/site-packages/rest_framework/views.py", line 469, in handle_exception
    self.raise_uncaught_exception(exc)
  File "/Library/Frameworks/Python.framework/Versions/3.10/lib/python3.10/site-packages/rest_framework/views.py", line 480, in raise_uncaught_exception
    raise exc
  File "/Library/Frameworks/Python.framework/Versions/3.10/lib/python3.10/site-packages/rest_framework/views.py", line 506, in dispatch
    response = handler(request, *args, **kwargs)
  File "/Users/macmini/Machine Learning/kaarujbe/kaaruj/sales/api/inventory/views.py", line 816, in get
    notifications = Notification.objects.filter(user=user)
  File "/Library/Frameworks/Python.framework/Versions/3.10/lib/python3.10/site-packages/django/db/models/manager.py", line 85, in manager_method
    return getattr(self.get_queryset(), name)(*args, **kwargs)
  File "/Library/Frameworks/Python.framework/Versions/3.10/lib/python3.10/site-packages/django/db/models/query.py", line 1420, in filter
    return self._filter_or_exclude(False, args, kwargs)
  File "/Library/Frameworks/Python.framework/Versions/3.10/lib/python3.10/site-packages/django/db/models/query.py", line 1438, in _filter_or_exclude
    clone._filter_or_exclude_inplace(negate, args, kwargs)
  File "/Library/Frameworks/Python.framework/Versions/3.10/lib/python3.10/site-packages/django/db/models/query.py", line 1445, in _filter_or_exclude_inplace
    self._query.add_q(Q(*args, **kwargs))
  File "/Library/Frameworks/Python.framework/Versions/3.10/lib/python3.10/site-packages/django/db/models/sql/query.py", line 1532, in add_q
    clause, _ = self._add_q(q_object, self.used_aliases)
  File "/Library/Frameworks/Python.framework/Versions/3.10/lib/python3.10/site-packages/django/db/models/sql/query.py", line 1562, in _add_q
    child_clause, needed_inner = self.build_filter(
  File "/Library/Frameworks/Python.framework/Versions/3.10/lib/python3.10/site-packages/django/db/models/sql/query.py", line 1407, in build_filter
    lookups, parts, reffed_expression = self.solve_lookup_type(arg)
  File "/Library/Frameworks/Python.framework/Versions/3.10/lib/python3.10/site-packages/django/db/models/sql/query.py", line 1217, in solve_lookup_type
    _, field, _, lookup_parts = self.names_to_path(lookup_splitted, self.get_meta())
  File "/Library/Frameworks/Python.framework/Versions/3.10/lib/python3.10/site-packages/django/db/models/sql/query.py", line 1709, in names_to_path
    raise FieldError(
django.core.exceptions.FieldError: Cannot resolve keyword 'user' into field. Choices are: category, costumer, id, invoice, offer, product, reviews
"GET /api/v1/sales/inventory/inventory/notifications HTTP/1.1" 500 133364
Internal Server Error: /api/v1/sales/inventory/inventory/notifications
Traceback (most recent call last):
  File "/Library/Frameworks/Python.framework/Versions/3.10/lib/python3.10/site-packages/django/core/handlers/exception.py", line 55, in inner
    response = get_response(request)
  File "/Library/Frameworks/Python.framework/Versions/3.10/lib/python3.10/site-packages/django/core/handlers/base.py", line 197, in _get_response
    response = wrapped_callback(request, *callback_args, **callback_kwargs)
  File "/Library/Frameworks/Python.framework/Versions/3.10/lib/python3.10/site-packages/django/views/decorators/csrf.py", line 54, in wrapped_view
    return view_func(*args, **kwargs)
  File "/Library/Frameworks/Python.framework/Versions/3.10/lib/python3.10/site-packages/django/views/generic/base.py", line 103, in view
    return self.dispatch(request, *args, **kwargs)
  File "/Library/Frameworks/Python.framework/Versions/3.10/lib/python3.10/site-packages/rest_framework/views.py", line 509, in dispatch
    response = self.handle_exception(exc)
  File "/Library/Frameworks/Python.framework/Versions/3.10/lib/python3.10/site-packages/rest_framework/views.py", line 469, in handle_exception
    self.raise_uncaught_exception(exc)
  File "/Library/Frameworks/Python.framework/Versions/3.10/lib/python3.10/site-packages/rest_framework/views.py", line 480, in raise_uncaught_exception
    raise exc
  File "/Library/Frameworks/Python.framework/Versions/3.10/lib/python3.10/site-packages/rest_framework/views.py", line 506, in dispatch
    response = handler(request, *args, **kwargs)
  File "/Users/macmini/Machine Learning/kaarujbe/kaaruj/sales/api/inventory/views.py", line 816, in get
    notifications = Notification.objects.filter(user=user)
  File "/Library/Frameworks/Python.framework/Versions/3.10/lib/python3.10/site-packages/django/db/models/manager.py", line 85, in manager_method
    return getattr(self.get_queryset(), name)(*args, **kwargs)
  File "/Library/Frameworks/Python.framework/Versions/3.10/lib/python3.10/site-packages/django/db/models/query.py", line 1420, in filter
    return self._filter_or_exclude(False, args, kwargs)
  File "/Library/Frameworks/Python.framework/Versions/3.10/lib/python3.10/site-packages/django/db/models/query.py", line 1438, in _filter_or_exclude
    clone._filter_or_exclude_inplace(negate, args, kwargs)
  File "/Library/Frameworks/Python.framework/Versions/3.10/lib/python3.10/site-packages/django/db/models/query.py", line 1445, in _filter_or_exclude_inplace
    self._query.add_q(Q(*args, **kwargs))
  File "/Library/Frameworks/Python.framework/Versions/3.10/lib/python3.10/site-packages/django/db/models/sql/query.py", line 1532, in add_q
    clause, _ = self._add_q(q_object, self.used_aliases)
  File "/Library/Frameworks/Python.framework/Versions/3.10/lib/python3.10/site-packages/django/db/models/sql/query.py", line 1562, in _add_q
    child_clause, needed_inner = self.build_filter(
  File "/Library/Frameworks/Python.framework/Versions/3.10/lib/python3.10/site-packages/django/db/models/sql/query.py", line 1407, in build_filter
    lookups, parts, reffed_expression = self.solve_lookup_type(arg)
  File "/Library/Frameworks/Python.framework/Versions/3.10/lib/python3.10/site-packages/django/db/models/sql/query.py", line 1217, in solve_lookup_type
    _, field, _, lookup_parts = self.names_to_path(lookup_splitted, self.get_meta())
  File "/Library/Frameworks/Python.framework/Versions/3.10/lib/python3.10/site-packages/django/db/models/sql/query.py", line 1709, in names_to_path
    raise FieldError(
django.core.exceptions.FieldError: Cannot resolve keyword 'user' into field. Choices are: category, costumer, id, invoice, offer, product, reviews
"GET /api/v1/sales/inventory/inventory/notifications HTTP/1.1" 500 133364
Internal Server Error: /api/v1/sales/inventory/inventory/notifications
Traceback (most recent call last):
  File "/Library/Frameworks/Python.framework/Versions/3.10/lib/python3.10/site-packages/django/core/handlers/exception.py", line 55, in inner
    response = get_response(request)
  File "/Library/Frameworks/Python.framework/Versions/3.10/lib/python3.10/site-packages/django/core/handlers/base.py", line 197, in _get_response
    response = wrapped_callback(request, *callback_args, **callback_kwargs)
  File "/Library/Frameworks/Python.framework/Versions/3.10/lib/python3.10/site-packages/django/views/decorators/csrf.py", line 54, in wrapped_view
    return view_func(*args, **kwargs)
  File "/Library/Frameworks/Python.framework/Versions/3.10/lib/python3.10/site-packages/django/views/generic/base.py", line 103, in view
    return self.dispatch(request, *args, **kwargs)
  File "/Library/Frameworks/Python.framework/Versions/3.10/lib/python3.10/site-packages/rest_framework/views.py", line 509, in dispatch
    response = self.handle_exception(exc)
  File "/Library/Frameworks/Python.framework/Versions/3.10/lib/python3.10/site-packages/rest_framework/views.py", line 469, in handle_exception
    self.raise_uncaught_exception(exc)
  File "/Library/Frameworks/Python.framework/Versions/3.10/lib/python3.10/site-packages/rest_framework/views.py", line 480, in raise_uncaught_exception
    raise exc
  File "/Library/Frameworks/Python.framework/Versions/3.10/lib/python3.10/site-packages/rest_framework/views.py", line 506, in dispatch
    response = handler(request, *args, **kwargs)
  File "/Users/macmini/Machine Learning/kaarujbe/kaaruj/sales/api/inventory/views.py", line 816, in get
    notifications = Notification.objects.filter(user=user)
  File "/Library/Frameworks/Python.framework/Versions/3.10/lib/python3.10/site-packages/django/db/models/manager.py", line 85, in manager_method
    return getattr(self.get_queryset(), name)(*args, **kwargs)
  File "/Library/Frameworks/Python.framework/Versions/3.10/lib/python3.10/site-packages/django/db/models/query.py", line 1420, in filter
    return self._filter_or_exclude(False, args, kwargs)
  File "/Library/Frameworks/Python.framework/Versions/3.10/lib/python3.10/site-packages/django/db/models/query.py", line 1438, in _filter_or_exclude
    clone._filter_or_exclude_inplace(negate, args, kwargs)
  File "/Library/Frameworks/Python.framework/Versions/3.10/lib/python3.10/site-packages/django/db/models/query.py", line 1445, in _filter_or_exclude_inplace
    self._query.add_q(Q(*args, **kwargs))
  File "/Library/Frameworks/Python.framework/Versions/3.10/lib/python3.10/site-packages/django/db/models/sql/query.py", line 1532, in add_q
    clause, _ = self._add_q(q_object, self.used_aliases)
  File "/Library/Frameworks/Python.framework/Versions/3.10/lib/python3.10/site-packages/django/db/models/sql/query.py", line 1562, in _add_q
    child_clause, needed_inner = self.build_filter(
  File "/Library/Frameworks/Python.framework/Versions/3.10/lib/python3.10/site-packages/django/db/models/sql/query.py", line 1407, in build_filter
    lookups, parts, reffed_expression = self.solve_lookup_type(arg)
  File "/Library/Frameworks/Python.framework/Versions/3.10/lib/python3.10/site-packages/django/db/models/sql/query.py", line 1217, in solve_lookup_type
    _, field, _, lookup_parts = self.names_to_path(lookup_splitted, self.get_meta())
  File "/Library/Frameworks/Python.framework/Versions/3.10/lib/python3.10/site-packages/django/db/models/sql/query.py", line 1709, in names_to_path
    raise FieldError(
django.core.exceptions.FieldError: Cannot resolve keyword 'user' into field. Choices are: category, costumer, id, invoice, offer, product, reviews
"GET /api/v1/sales/inventory/inventory/notifications HTTP/1.1" 500 133364
Internal Server Error: /api/v1/sales/inventory/inventory/notifications
Traceback (most recent call last):
  File "/Library/Frameworks/Python.framework/Versions/3.10/lib/python3.10/site-packages/django/core/handlers/exception.py", line 55, in inner
    response = get_response(request)
  File "/Library/Frameworks/Python.framework/Versions/3.10/lib/python3.10/site-packages/django/core/handlers/base.py", line 197, in _get_response
    response = wrapped_callback(request, *callback_args, **callback_kwargs)
  File "/Library/Frameworks/Python.framework/Versions/3.10/lib/python3.10/site-packages/django/views/decorators/csrf.py", line 54, in wrapped_view
    return view_func(*args, **kwargs)
  File "/Library/Frameworks/Python.framework/Versions/3.10/lib/python3.10/site-packages/django/views/generic/base.py", line 103, in view
    return self.dispatch(request, *args, **kwargs)
  File "/Library/Frameworks/Python.framework/Versions/3.10/lib/python3.10/site-packages/rest_framework/views.py", line 509, in dispatch
    response = self.handle_exception(exc)
  File "/Library/Frameworks/Python.framework/Versions/3.10/lib/python3.10/site-packages/rest_framework/views.py", line 469, in handle_exception
    self.raise_uncaught_exception(exc)
  File "/Library/Frameworks/Python.framework/Versions/3.10/lib/python3.10/site-packages/rest_framework/views.py", line 480, in raise_uncaught_exception
    raise exc
  File "/Library/Frameworks/Python.framework/Versions/3.10/lib/python3.10/site-packages/rest_framework/views.py", line 506, in dispatch
    response = handler(request, *args, **kwargs)
  File "/Users/macmini/Machine Learning/kaarujbe/kaaruj/sales/api/inventory/views.py", line 816, in get
    notifications = Notification.objects.filter(user=user)
  File "/Library/Frameworks/Python.framework/Versions/3.10/lib/python3.10/site-packages/django/db/models/manager.py", line 85, in manager_method
    return getattr(self.get_queryset(), name)(*args, **kwargs)
  File "/Library/Frameworks/Python.framework/Versions/3.10/lib/python3.10/site-packages/django/db/models/query.py", line 1420, in filter
    return self._filter_or_exclude(False, args, kwargs)
  File "/Library/Frameworks/Python.framework/Versions/3.10/lib/python3.10/site-packages/django/db/models/query.py", line 1438, in _filter_or_exclude
    clone._filter_or_exclude_inplace(negate, args, kwargs)
  File "/Library/Frameworks/Python.framework/Versions/3.10/lib/python3.10/site-packages/django/db/models/query.py", line 1445, in _filter_or_exclude_inplace
    self._query.add_q(Q(*args, **kwargs))
  File "/Library/Frameworks/Python.framework/Versions/3.10/lib/python3.10/site-packages/django/db/models/sql/query.py", line 1532, in add_q
    clause, _ = self._add_q(q_object, self.used_aliases)
  File "/Library/Frameworks/Python.framework/Versions/3.10/lib/python3.10/site-packages/django/db/models/sql/query.py", line 1562, in _add_q
    child_clause, needed_inner = self.build_filter(
  File "/Library/Frameworks/Python.framework/Versions/3.10/lib/python3.10/site-packages/django/db/models/sql/query.py", line 1407, in build_filter
    lookups, parts, reffed_expression = self.solve_lookup_type(arg)
  File "/Library/Frameworks/Python.framework/Versions/3.10/lib/python3.10/site-packages/django/db/models/sql/query.py", line 1217, in solve_lookup_type
    _, field, _, lookup_parts = self.names_to_path(lookup_splitted, self.get_meta())
  File "/Library/Frameworks/Python.framework/Versions/3.10/lib/python3.10/site-packages/django/db/models/sql/query.py", line 1709, in names_to_path
    raise FieldError(
django.core.exceptions.FieldError: Cannot resolve keyword 'user' into field. Choices are: category, costumer, id, invoice, offer, product, reviews
"GET /api/v1/sales/inventory/inventory/notifications HTTP/1.1" 500 133364
Internal Server Error: /api/v1/sales/inventory/inventory/notifications
Traceback (most recent call last):
  File "/Library/Frameworks/Python.framework/Versions/3.10/lib/python3.10/site-packages/django/core/handlers/exception.py", line 55, in inner
    response = get_response(request)
  File "/Library/Frameworks/Python.framework/Versions/3.10/lib/python3.10/site-packages/django/core/handlers/base.py", line 197, in _get_response
    response = wrapped_callback(request, *callback_args, **callback_kwargs)
  File "/Library/Frameworks/Python.framework/Versions/3.10/lib/python3.10/site-packages/django/views/decorators/csrf.py", line 54, in wrapped_view
    return view_func(*args, **kwargs)
  File "/Library/Frameworks/Python.framework/Versions/3.10/lib/python3.10/site-packages/django/views/generic/base.py", line 103, in view
    return self.dispatch(request, *args, **kwargs)
  File "/Library/Frameworks/Python.framework/Versions/3.10/lib/python3.10/site-packages/rest_framework/views.py", line 509, in dispatch
    response = self.handle_exception(exc)
  File "/Library/Frameworks/Python.framework/Versions/3.10/lib/python3.10/site-packages/rest_framework/views.py", line 469, in handle_exception
    self.raise_uncaught_exception(exc)
  File "/Library/Frameworks/Python.framework/Versions/3.10/lib/python3.10/site-packages/rest_framework/views.py", line 480, in raise_uncaught_exception
    raise exc
  File "/Library/Frameworks/Python.framework/Versions/3.10/lib/python3.10/site-packages/rest_framework/views.py", line 506, in dispatch
    response = handler(request, *args, **kwargs)
  File "/Users/macmini/Machine Learning/kaarujbe/kaaruj/sales/api/inventory/views.py", line 816, in get
    notifications = Notification.objects.filter(user=user)
  File "/Library/Frameworks/Python.framework/Versions/3.10/lib/python3.10/site-packages/django/db/models/manager.py", line 85, in manager_method
    return getattr(self.get_queryset(), name)(*args, **kwargs)
  File "/Library/Frameworks/Python.framework/Versions/3.10/lib/python3.10/site-packages/django/db/models/query.py", line 1420, in filter
    return self._filter_or_exclude(False, args, kwargs)
  File "/Library/Frameworks/Python.framework/Versions/3.10/lib/python3.10/site-packages/django/db/models/query.py", line 1438, in _filter_or_exclude
    clone._filter_or_exclude_inplace(negate, args, kwargs)
  File "/Library/Frameworks/Python.framework/Versions/3.10/lib/python3.10/site-packages/django/db/models/query.py", line 1445, in _filter_or_exclude_inplace
    self._query.add_q(Q(*args, **kwargs))
  File "/Library/Frameworks/Python.framework/Versions/3.10/lib/python3.10/site-packages/django/db/models/sql/query.py", line 1532, in add_q
    clause, _ = self._add_q(q_object, self.used_aliases)
  File "/Library/Frameworks/Python.framework/Versions/3.10/lib/python3.10/site-packages/django/db/models/sql/query.py", line 1562, in _add_q
    child_clause, needed_inner = self.build_filter(
  File "/Library/Frameworks/Python.framework/Versions/3.10/lib/python3.10/site-packages/django/db/models/sql/query.py", line 1407, in build_filter
    lookups, parts, reffed_expression = self.solve_lookup_type(arg)
  File "/Library/Frameworks/Python.framework/Versions/3.10/lib/python3.10/site-packages/django/db/models/sql/query.py", line 1217, in solve_lookup_type
    _, field, _, lookup_parts = self.names_to_path(lookup_splitted, self.get_meta())
  File "/Library/Frameworks/Python.framework/Versions/3.10/lib/python3.10/site-packages/django/db/models/sql/query.py", line 1709, in names_to_path
    raise FieldError(
django.core.exceptions.FieldError: Cannot resolve keyword 'user' into field. Choices are: category, costumer, id, invoice, offer, product, reviews
"GET /api/v1/sales/inventory/inventory/notifications HTTP/1.1" 500 133364
Internal Server Error: /api/v1/sales/inventory/inventory/notifications
Traceback (most recent call last):
  File "/Library/Frameworks/Python.framework/Versions/3.10/lib/python3.10/site-packages/django/core/handlers/exception.py", line 55, in inner
    response = get_response(request)
  File "/Library/Frameworks/Python.framework/Versions/3.10/lib/python3.10/site-packages/django/core/handlers/base.py", line 197, in _get_response
    response = wrapped_callback(request, *callback_args, **callback_kwargs)
  File "/Library/Frameworks/Python.framework/Versions/3.10/lib/python3.10/site-packages/django/views/decorators/csrf.py", line 54, in wrapped_view
    return view_func(*args, **kwargs)
  File "/Library/Frameworks/Python.framework/Versions/3.10/lib/python3.10/site-packages/django/views/generic/base.py", line 103, in view
    return self.dispatch(request, *args, **kwargs)
  File "/Library/Frameworks/Python.framework/Versions/3.10/lib/python3.10/site-packages/rest_framework/views.py", line 509, in dispatch
    response = self.handle_exception(exc)
  File "/Library/Frameworks/Python.framework/Versions/3.10/lib/python3.10/site-packages/rest_framework/views.py", line 469, in handle_exception
    self.raise_uncaught_exception(exc)
  File "/Library/Frameworks/Python.framework/Versions/3.10/lib/python3.10/site-packages/rest_framework/views.py", line 480, in raise_uncaught_exception
    raise exc
  File "/Library/Frameworks/Python.framework/Versions/3.10/lib/python3.10/site-packages/rest_framework/views.py", line 506, in dispatch
    response = handler(request, *args, **kwargs)
  File "/Users/macmini/Machine Learning/kaarujbe/kaaruj/sales/api/inventory/views.py", line 816, in get
    notifications = Notification.objects.filter(user=user)
  File "/Library/Frameworks/Python.framework/Versions/3.10/lib/python3.10/site-packages/django/db/models/manager.py", line 85, in manager_method
    return getattr(self.get_queryset(), name)(*args, **kwargs)
  File "/Library/Frameworks/Python.framework/Versions/3.10/lib/python3.10/site-packages/django/db/models/query.py", line 1420, in filter
    return self._filter_or_exclude(False, args, kwargs)
  File "/Library/Frameworks/Python.framework/Versions/3.10/lib/python3.10/site-packages/django/db/models/query.py", line 1438, in _filter_or_exclude
    clone._filter_or_exclude_inplace(negate, args, kwargs)
  File "/Library/Frameworks/Python.framework/Versions/3.10/lib/python3.10/site-packages/django/db/models/query.py", line 1445, in _filter_or_exclude_inplace
    self._query.add_q(Q(*args, **kwargs))
  File "/Library/Frameworks/Python.framework/Versions/3.10/lib/python3.10/site-packages/django/db/models/sql/query.py", line 1532, in add_q
    clause, _ = self._add_q(q_object, self.used_aliases)
  File "/Library/Frameworks/Python.framework/Versions/3.10/lib/python3.10/site-packages/django/db/models/sql/query.py", line 1562, in _add_q
    child_clause, needed_inner = self.build_filter(
  File "/Library/Frameworks/Python.framework/Versions/3.10/lib/python3.10/site-packages/django/db/models/sql/query.py", line 1407, in build_filter
    lookups, parts, reffed_expression = self.solve_lookup_type(arg)
  File "/Library/Frameworks/Python.framework/Versions/3.10/lib/python3.10/site-packages/django/db/models/sql/query.py", line 1217, in solve_lookup_type
    _, field, _, lookup_parts = self.names_to_path(lookup_splitted, self.get_meta())
  File "/Library/Frameworks/Python.framework/Versions/3.10/lib/python3.10/site-packages/django/db/models/sql/query.py", line 1709, in names_to_path
    raise FieldError(
django.core.exceptions.FieldError: Cannot resolve keyword 'user' into field. Choices are: category, costumer, id, invoice, offer, product, reviews
"GET /api/v1/sales/inventory/inventory/notifications HTTP/1.1" 500 133364
Internal Server Error: /admin/sales/notification/add/
Traceback (most recent call last):
  File "/Library/Frameworks/Python.framework/Versions/3.10/lib/python3.10/site-packages/django/db/backends/utils.py", line 89, in _execute
    return self.cursor.execute(sql, params)
  File "/Library/Frameworks/Python.framework/Versions/3.10/lib/python3.10/site-packages/django/db/backends/sqlite3/base.py", line 357, in execute
    return Database.Cursor.execute(self, query, params)
sqlite3.IntegrityError: NOT NULL constraint failed: sales_notification.user_id

The above exception was the direct cause of the following exception:

Traceback (most recent call last):
  File "/Library/Frameworks/Python.framework/Versions/3.10/lib/python3.10/site-packages/django/core/handlers/exception.py", line 55, in inner
    response = get_response(request)
  File "/Library/Frameworks/Python.framework/Versions/3.10/lib/python3.10/site-packages/django/core/handlers/base.py", line 197, in _get_response
    response = wrapped_callback(request, *callback_args, **callback_kwargs)
  File "/Library/Frameworks/Python.framework/Versions/3.10/lib/python3.10/site-packages/django/contrib/admin/options.py", line 686, in wrapper
    return self.admin_site.admin_view(view)(*args, **kwargs)
  File "/Library/Frameworks/Python.framework/Versions/3.10/lib/python3.10/site-packages/django/utils/decorators.py", line 133, in _wrapped_view
    response = view_func(request, *args, **kwargs)
  File "/Library/Frameworks/Python.framework/Versions/3.10/lib/python3.10/site-packages/django/views/decorators/cache.py", line 62, in _wrapped_view_func
    response = view_func(request, *args, **kwargs)
  File "/Library/Frameworks/Python.framework/Versions/3.10/lib/python3.10/site-packages/django/contrib/admin/sites.py", line 242, in inner
    return view(request, *args, **kwargs)
  File "/Library/Frameworks/Python.framework/Versions/3.10/lib/python3.10/site-packages/django/contrib/admin/options.py", line 1890, in add_view
    return self.changeform_view(request, None, form_url, extra_context)
  File "/Library/Frameworks/Python.framework/Versions/3.10/lib/python3.10/site-packages/django/utils/decorators.py", line 46, in _wrapper
    return bound_method(*args, **kwargs)
  File "/Library/Frameworks/Python.framework/Versions/3.10/lib/python3.10/site-packages/django/utils/decorators.py", line 133, in _wrapped_view
    response = view_func(request, *args, **kwargs)
  File "/Library/Frameworks/Python.framework/Versions/3.10/lib/python3.10/site-packages/django/contrib/admin/options.py", line 1750, in changeform_view
    return self._changeform_view(request, object_id, form_url, extra_context)
  File "/Library/Frameworks/Python.framework/Versions/3.10/lib/python3.10/site-packages/django/contrib/admin/options.py", line 1802, in _changeform_view
    self.save_model(request, new_object, form, not add)
  File "/Library/Frameworks/Python.framework/Versions/3.10/lib/python3.10/site-packages/django/contrib/admin/options.py", line 1225, in save_model
    obj.save()
  File "/Library/Frameworks/Python.framework/Versions/3.10/lib/python3.10/site-packages/django/db/models/base.py", line 831, in save
    self.save_base(
  File "/Library/Frameworks/Python.framework/Versions/3.10/lib/python3.10/site-packages/django/db/models/base.py", line 882, in save_base
    updated = self._save_table(
  File "/Library/Frameworks/Python.framework/Versions/3.10/lib/python3.10/site-packages/django/db/models/base.py", line 1025, in _save_table
    results = self._do_insert(
  File "/Library/Frameworks/Python.framework/Versions/3.10/lib/python3.10/site-packages/django/db/models/base.py", line 1066, in _do_insert
    return manager._insert(
  File "/Library/Frameworks/Python.framework/Versions/3.10/lib/python3.10/site-packages/django/db/models/manager.py", line 85, in manager_method
    return getattr(self.get_queryset(), name)(*args, **kwargs)
  File "/Library/Frameworks/Python.framework/Versions/3.10/lib/python3.10/site-packages/django/db/models/query.py", line 1790, in _insert
    return query.get_compiler(using=using).execute_sql(returning_fields)
  File "/Library/Frameworks/Python.framework/Versions/3.10/lib/python3.10/site-packages/django/db/models/sql/compiler.py", line 1657, in execute_sql
    cursor.execute(sql, params)
  File "/Library/Frameworks/Python.framework/Versions/3.10/lib/python3.10/site-packages/django/db/backends/utils.py", line 103, in execute
    return super().execute(sql, params)
  File "/Library/Frameworks/Python.framework/Versions/3.10/lib/python3.10/site-packages/django/db/backends/utils.py", line 67, in execute
    return self._execute_with_wrappers(
  File "/Library/Frameworks/Python.framework/Versions/3.10/lib/python3.10/site-packages/django/db/backends/utils.py", line 80, in _execute_with_wrappers
    return executor(sql, params, many, context)
  File "/Library/Frameworks/Python.framework/Versions/3.10/lib/python3.10/site-packages/django/db/backends/utils.py", line 84, in _execute
    with self.db.wrap_database_errors:
  File "/Library/Frameworks/Python.framework/Versions/3.10/lib/python3.10/site-packages/django/db/utils.py", line 91, in __exit__
    raise dj_exc_value.with_traceback(traceback) from exc_value
  File "/Library/Frameworks/Python.framework/Versions/3.10/lib/python3.10/site-packages/django/db/backends/utils.py", line 89, in _execute
    return self.cursor.execute(sql, params)
  File "/Library/Frameworks/Python.framework/Versions/3.10/lib/python3.10/site-packages/django/db/backends/sqlite3/base.py", line 357, in execute
    return Database.Cursor.execute(self, query, params)
django.db.utils.IntegrityError: NOT NULL constraint failed: sales_notification.user_id
"POST /admin/sales/notification/add/ HTTP/1.1" 500 188338
test_path/bar_codes/base/white.png /bar_codes/base/out/out.png
test_path/bar_codes/base/white.png /bar_codes/base/out/out.png
test_path/bar_codes/base/white.png /bar_codes/base/out/out.png
test_path/bar_codes/base/white.png /bar_codes/base/out/out.png
Internal Server Error: /api/v1/sales/inventory/inventory/notifications
Traceback (most recent call last):
  File "/Library/Frameworks/Python.framework/Versions/3.10/lib/python3.10/site-packages/django/core/handlers/exception.py", line 55, in inner
    response = get_response(request)
  File "/Library/Frameworks/Python.framework/Versions/3.10/lib/python3.10/site-packages/django/core/handlers/base.py", line 197, in _get_response
    response = wrapped_callback(request, *callback_args, **callback_kwargs)
  File "/Library/Frameworks/Python.framework/Versions/3.10/lib/python3.10/site-packages/django/views/decorators/csrf.py", line 54, in wrapped_view
    return view_func(*args, **kwargs)
  File "/Library/Frameworks/Python.framework/Versions/3.10/lib/python3.10/site-packages/django/views/generic/base.py", line 103, in view
    return self.dispatch(request, *args, **kwargs)
  File "/Library/Frameworks/Python.framework/Versions/3.10/lib/python3.10/site-packages/rest_framework/views.py", line 509, in dispatch
    response = self.handle_exception(exc)
  File "/Library/Frameworks/Python.framework/Versions/3.10/lib/python3.10/site-packages/rest_framework/views.py", line 469, in handle_exception
    self.raise_uncaught_exception(exc)
  File "/Library/Frameworks/Python.framework/Versions/3.10/lib/python3.10/site-packages/rest_framework/views.py", line 480, in raise_uncaught_exception
    raise exc
  File "/Library/Frameworks/Python.framework/Versions/3.10/lib/python3.10/site-packages/rest_framework/views.py", line 506, in dispatch
    response = handler(request, *args, **kwargs)
  File "/Users/macmini/Machine Learning/kaarujbe/kaaruj/sales/api/inventory/views.py", line 816, in get
    notifications = Notification.objects.filter(user=user)
  File "/Library/Frameworks/Python.framework/Versions/3.10/lib/python3.10/site-packages/django/db/models/manager.py", line 85, in manager_method
    return getattr(self.get_queryset(), name)(*args, **kwargs)
  File "/Library/Frameworks/Python.framework/Versions/3.10/lib/python3.10/site-packages/django/db/models/query.py", line 1420, in filter
    return self._filter_or_exclude(False, args, kwargs)
  File "/Library/Frameworks/Python.framework/Versions/3.10/lib/python3.10/site-packages/django/db/models/query.py", line 1438, in _filter_or_exclude
    clone._filter_or_exclude_inplace(negate, args, kwargs)
  File "/Library/Frameworks/Python.framework/Versions/3.10/lib/python3.10/site-packages/django/db/models/query.py", line 1445, in _filter_or_exclude_inplace
    self._query.add_q(Q(*args, **kwargs))
  File "/Library/Frameworks/Python.framework/Versions/3.10/lib/python3.10/site-packages/django/db/models/sql/query.py", line 1532, in add_q
    clause, _ = self._add_q(q_object, self.used_aliases)
  File "/Library/Frameworks/Python.framework/Versions/3.10/lib/python3.10/site-packages/django/db/models/sql/query.py", line 1562, in _add_q
    child_clause, needed_inner = self.build_filter(
  File "/Library/Frameworks/Python.framework/Versions/3.10/lib/python3.10/site-packages/django/db/models/sql/query.py", line 1407, in build_filter
    lookups, parts, reffed_expression = self.solve_lookup_type(arg)
  File "/Library/Frameworks/Python.framework/Versions/3.10/lib/python3.10/site-packages/django/db/models/sql/query.py", line 1217, in solve_lookup_type
    _, field, _, lookup_parts = self.names_to_path(lookup_splitted, self.get_meta())
  File "/Library/Frameworks/Python.framework/Versions/3.10/lib/python3.10/site-packages/django/db/models/sql/query.py", line 1709, in names_to_path
    raise FieldError(
django.core.exceptions.FieldError: Cannot resolve keyword 'user' into field. Choices are: category, costumer, id, invoice, offer, product, reviews
"GET /api/v1/sales/inventory/inventory/notifications HTTP/1.1" 500 133552
Internal Server Error: /api/v1/sales/inventory/inventory/notifications
Traceback (most recent call last):
  File "/Library/Frameworks/Python.framework/Versions/3.10/lib/python3.10/site-packages/django/core/handlers/exception.py", line 55, in inner
    response = get_response(request)
  File "/Library/Frameworks/Python.framework/Versions/3.10/lib/python3.10/site-packages/django/core/handlers/base.py", line 197, in _get_response
    response = wrapped_callback(request, *callback_args, **callback_kwargs)
  File "/Library/Frameworks/Python.framework/Versions/3.10/lib/python3.10/site-packages/django/views/decorators/csrf.py", line 54, in wrapped_view
    return view_func(*args, **kwargs)
  File "/Library/Frameworks/Python.framework/Versions/3.10/lib/python3.10/site-packages/django/views/generic/base.py", line 103, in view
    return self.dispatch(request, *args, **kwargs)
  File "/Library/Frameworks/Python.framework/Versions/3.10/lib/python3.10/site-packages/rest_framework/views.py", line 509, in dispatch
    response = self.handle_exception(exc)
  File "/Library/Frameworks/Python.framework/Versions/3.10/lib/python3.10/site-packages/rest_framework/views.py", line 469, in handle_exception
    self.raise_uncaught_exception(exc)
  File "/Library/Frameworks/Python.framework/Versions/3.10/lib/python3.10/site-packages/rest_framework/views.py", line 480, in raise_uncaught_exception
    raise exc
  File "/Library/Frameworks/Python.framework/Versions/3.10/lib/python3.10/site-packages/rest_framework/views.py", line 506, in dispatch
    response = handler(request, *args, **kwargs)
  File "/Users/macmini/Machine Learning/kaarujbe/kaaruj/sales/api/inventory/views.py", line 816, in get
    notifications = Notification.objects.filter(user=user)
  File "/Library/Frameworks/Python.framework/Versions/3.10/lib/python3.10/site-packages/django/db/models/manager.py", line 85, in manager_method
    return getattr(self.get_queryset(), name)(*args, **kwargs)
  File "/Library/Frameworks/Python.framework/Versions/3.10/lib/python3.10/site-packages/django/db/models/query.py", line 1420, in filter
    return self._filter_or_exclude(False, args, kwargs)
  File "/Library/Frameworks/Python.framework/Versions/3.10/lib/python3.10/site-packages/django/db/models/query.py", line 1438, in _filter_or_exclude
    clone._filter_or_exclude_inplace(negate, args, kwargs)
  File "/Library/Frameworks/Python.framework/Versions/3.10/lib/python3.10/site-packages/django/db/models/query.py", line 1445, in _filter_or_exclude_inplace
    self._query.add_q(Q(*args, **kwargs))
  File "/Library/Frameworks/Python.framework/Versions/3.10/lib/python3.10/site-packages/django/db/models/sql/query.py", line 1532, in add_q
    clause, _ = self._add_q(q_object, self.used_aliases)
  File "/Library/Frameworks/Python.framework/Versions/3.10/lib/python3.10/site-packages/django/db/models/sql/query.py", line 1562, in _add_q
    child_clause, needed_inner = self.build_filter(
  File "/Library/Frameworks/Python.framework/Versions/3.10/lib/python3.10/site-packages/django/db/models/sql/query.py", line 1407, in build_filter
    lookups, parts, reffed_expression = self.solve_lookup_type(arg)
  File "/Library/Frameworks/Python.framework/Versions/3.10/lib/python3.10/site-packages/django/db/models/sql/query.py", line 1217, in solve_lookup_type
    _, field, _, lookup_parts = self.names_to_path(lookup_splitted, self.get_meta())
  File "/Library/Frameworks/Python.framework/Versions/3.10/lib/python3.10/site-packages/django/db/models/sql/query.py", line 1709, in names_to_path
    raise FieldError(
django.core.exceptions.FieldError: Cannot resolve keyword 'user' into field. Choices are: category, costumer, id, invoice, offer, product, reviews
"GET /api/v1/sales/inventory/inventory/notifications HTTP/1.1" 500 133552
Internal Server Error: /api/v1/sales/inventory/inventory/notifications
Traceback (most recent call last):
  File "/Library/Frameworks/Python.framework/Versions/3.10/lib/python3.10/site-packages/django/core/handlers/exception.py", line 55, in inner
    response = get_response(request)
  File "/Library/Frameworks/Python.framework/Versions/3.10/lib/python3.10/site-packages/django/core/handlers/base.py", line 197, in _get_response
    response = wrapped_callback(request, *callback_args, **callback_kwargs)
  File "/Library/Frameworks/Python.framework/Versions/3.10/lib/python3.10/site-packages/django/views/decorators/csrf.py", line 54, in wrapped_view
    return view_func(*args, **kwargs)
  File "/Library/Frameworks/Python.framework/Versions/3.10/lib/python3.10/site-packages/django/views/generic/base.py", line 103, in view
    return self.dispatch(request, *args, **kwargs)
  File "/Library/Frameworks/Python.framework/Versions/3.10/lib/python3.10/site-packages/rest_framework/views.py", line 509, in dispatch
    response = self.handle_exception(exc)
  File "/Library/Frameworks/Python.framework/Versions/3.10/lib/python3.10/site-packages/rest_framework/views.py", line 469, in handle_exception
    self.raise_uncaught_exception(exc)
  File "/Library/Frameworks/Python.framework/Versions/3.10/lib/python3.10/site-packages/rest_framework/views.py", line 480, in raise_uncaught_exception
    raise exc
  File "/Library/Frameworks/Python.framework/Versions/3.10/lib/python3.10/site-packages/rest_framework/views.py", line 506, in dispatch
    response = handler(request, *args, **kwargs)
  File "/Users/macmini/Machine Learning/kaarujbe/kaaruj/sales/api/inventory/views.py", line 816, in get
    notifications = Notification.objects.filter(user=user)
  File "/Library/Frameworks/Python.framework/Versions/3.10/lib/python3.10/site-packages/django/db/models/manager.py", line 85, in manager_method
    return getattr(self.get_queryset(), name)(*args, **kwargs)
  File "/Library/Frameworks/Python.framework/Versions/3.10/lib/python3.10/site-packages/django/db/models/query.py", line 1420, in filter
    return self._filter_or_exclude(False, args, kwargs)
  File "/Library/Frameworks/Python.framework/Versions/3.10/lib/python3.10/site-packages/django/db/models/query.py", line 1438, in _filter_or_exclude
    clone._filter_or_exclude_inplace(negate, args, kwargs)
  File "/Library/Frameworks/Python.framework/Versions/3.10/lib/python3.10/site-packages/django/db/models/query.py", line 1445, in _filter_or_exclude_inplace
    self._query.add_q(Q(*args, **kwargs))
  File "/Library/Frameworks/Python.framework/Versions/3.10/lib/python3.10/site-packages/django/db/models/sql/query.py", line 1532, in add_q
    clause, _ = self._add_q(q_object, self.used_aliases)
  File "/Library/Frameworks/Python.framework/Versions/3.10/lib/python3.10/site-packages/django/db/models/sql/query.py", line 1562, in _add_q
    child_clause, needed_inner = self.build_filter(
  File "/Library/Frameworks/Python.framework/Versions/3.10/lib/python3.10/site-packages/django/db/models/sql/query.py", line 1407, in build_filter
    lookups, parts, reffed_expression = self.solve_lookup_type(arg)
  File "/Library/Frameworks/Python.framework/Versions/3.10/lib/python3.10/site-packages/django/db/models/sql/query.py", line 1217, in solve_lookup_type
    _, field, _, lookup_parts = self.names_to_path(lookup_splitted, self.get_meta())
  File "/Library/Frameworks/Python.framework/Versions/3.10/lib/python3.10/site-packages/django/db/models/sql/query.py", line 1709, in names_to_path
    raise FieldError(
django.core.exceptions.FieldError: Cannot resolve keyword 'user' into field. Choices are: category, costumer, id, invoice, offer, product, reviews
"GET /api/v1/sales/inventory/inventory/notifications HTTP/1.1" 500 133552
Internal Server Error: /api/v1/sales/inventory/inventory/notifications
Traceback (most recent call last):
  File "/Library/Frameworks/Python.framework/Versions/3.10/lib/python3.10/site-packages/django/core/handlers/exception.py", line 55, in inner
    response = get_response(request)
  File "/Library/Frameworks/Python.framework/Versions/3.10/lib/python3.10/site-packages/django/core/handlers/base.py", line 197, in _get_response
    response = wrapped_callback(request, *callback_args, **callback_kwargs)
  File "/Library/Frameworks/Python.framework/Versions/3.10/lib/python3.10/site-packages/django/views/decorators/csrf.py", line 54, in wrapped_view
    return view_func(*args, **kwargs)
  File "/Library/Frameworks/Python.framework/Versions/3.10/lib/python3.10/site-packages/django/views/generic/base.py", line 103, in view
    return self.dispatch(request, *args, **kwargs)
  File "/Library/Frameworks/Python.framework/Versions/3.10/lib/python3.10/site-packages/rest_framework/views.py", line 509, in dispatch
    response = self.handle_exception(exc)
  File "/Library/Frameworks/Python.framework/Versions/3.10/lib/python3.10/site-packages/rest_framework/views.py", line 469, in handle_exception
    self.raise_uncaught_exception(exc)
  File "/Library/Frameworks/Python.framework/Versions/3.10/lib/python3.10/site-packages/rest_framework/views.py", line 480, in raise_uncaught_exception
    raise exc
  File "/Library/Frameworks/Python.framework/Versions/3.10/lib/python3.10/site-packages/rest_framework/views.py", line 506, in dispatch
    response = handler(request, *args, **kwargs)
  File "/Users/macmini/Machine Learning/kaarujbe/kaaruj/sales/api/inventory/views.py", line 816, in get
    notifications = Notification.objects.filter(user=user)
  File "/Library/Frameworks/Python.framework/Versions/3.10/lib/python3.10/site-packages/django/db/models/manager.py", line 85, in manager_method
    return getattr(self.get_queryset(), name)(*args, **kwargs)
  File "/Library/Frameworks/Python.framework/Versions/3.10/lib/python3.10/site-packages/django/db/models/query.py", line 1420, in filter
    return self._filter_or_exclude(False, args, kwargs)
  File "/Library/Frameworks/Python.framework/Versions/3.10/lib/python3.10/site-packages/django/db/models/query.py", line 1438, in _filter_or_exclude
    clone._filter_or_exclude_inplace(negate, args, kwargs)
  File "/Library/Frameworks/Python.framework/Versions/3.10/lib/python3.10/site-packages/django/db/models/query.py", line 1445, in _filter_or_exclude_inplace
    self._query.add_q(Q(*args, **kwargs))
  File "/Library/Frameworks/Python.framework/Versions/3.10/lib/python3.10/site-packages/django/db/models/sql/query.py", line 1532, in add_q
    clause, _ = self._add_q(q_object, self.used_aliases)
  File "/Library/Frameworks/Python.framework/Versions/3.10/lib/python3.10/site-packages/django/db/models/sql/query.py", line 1562, in _add_q
    child_clause, needed_inner = self.build_filter(
  File "/Library/Frameworks/Python.framework/Versions/3.10/lib/python3.10/site-packages/django/db/models/sql/query.py", line 1407, in build_filter
    lookups, parts, reffed_expression = self.solve_lookup_type(arg)
  File "/Library/Frameworks/Python.framework/Versions/3.10/lib/python3.10/site-packages/django/db/models/sql/query.py", line 1217, in solve_lookup_type
    _, field, _, lookup_parts = self.names_to_path(lookup_splitted, self.get_meta())
  File "/Library/Frameworks/Python.framework/Versions/3.10/lib/python3.10/site-packages/django/db/models/sql/query.py", line 1709, in names_to_path
    raise FieldError(
django.core.exceptions.FieldError: Cannot resolve keyword 'user' into field. Choices are: category, costumer, id, invoice, offer, product, reviews
"GET /api/v1/sales/inventory/inventory/notifications HTTP/1.1" 500 133552
Internal Server Error: /api/v1/sales/inventory/inventory/notifications
Traceback (most recent call last):
  File "/Library/Frameworks/Python.framework/Versions/3.10/lib/python3.10/site-packages/django/core/handlers/exception.py", line 55, in inner
    response = get_response(request)
  File "/Library/Frameworks/Python.framework/Versions/3.10/lib/python3.10/site-packages/django/core/handlers/base.py", line 197, in _get_response
    response = wrapped_callback(request, *callback_args, **callback_kwargs)
  File "/Library/Frameworks/Python.framework/Versions/3.10/lib/python3.10/site-packages/django/views/decorators/csrf.py", line 54, in wrapped_view
    return view_func(*args, **kwargs)
  File "/Library/Frameworks/Python.framework/Versions/3.10/lib/python3.10/site-packages/django/views/generic/base.py", line 103, in view
    return self.dispatch(request, *args, **kwargs)
  File "/Library/Frameworks/Python.framework/Versions/3.10/lib/python3.10/site-packages/rest_framework/views.py", line 509, in dispatch
    response = self.handle_exception(exc)
  File "/Library/Frameworks/Python.framework/Versions/3.10/lib/python3.10/site-packages/rest_framework/views.py", line 469, in handle_exception
    self.raise_uncaught_exception(exc)
  File "/Library/Frameworks/Python.framework/Versions/3.10/lib/python3.10/site-packages/rest_framework/views.py", line 480, in raise_uncaught_exception
    raise exc
  File "/Library/Frameworks/Python.framework/Versions/3.10/lib/python3.10/site-packages/rest_framework/views.py", line 506, in dispatch
    response = handler(request, *args, **kwargs)
  File "/Users/macmini/Machine Learning/kaarujbe/kaaruj/sales/api/inventory/views.py", line 816, in get
    notifications = Notification.objects.filter(user=user)
  File "/Library/Frameworks/Python.framework/Versions/3.10/lib/python3.10/site-packages/django/db/models/manager.py", line 85, in manager_method
    return getattr(self.get_queryset(), name)(*args, **kwargs)
  File "/Library/Frameworks/Python.framework/Versions/3.10/lib/python3.10/site-packages/django/db/models/query.py", line 1420, in filter
    return self._filter_or_exclude(False, args, kwargs)
  File "/Library/Frameworks/Python.framework/Versions/3.10/lib/python3.10/site-packages/django/db/models/query.py", line 1438, in _filter_or_exclude
    clone._filter_or_exclude_inplace(negate, args, kwargs)
  File "/Library/Frameworks/Python.framework/Versions/3.10/lib/python3.10/site-packages/django/db/models/query.py", line 1445, in _filter_or_exclude_inplace
    self._query.add_q(Q(*args, **kwargs))
  File "/Library/Frameworks/Python.framework/Versions/3.10/lib/python3.10/site-packages/django/db/models/sql/query.py", line 1532, in add_q
    clause, _ = self._add_q(q_object, self.used_aliases)
  File "/Library/Frameworks/Python.framework/Versions/3.10/lib/python3.10/site-packages/django/db/models/sql/query.py", line 1562, in _add_q
    child_clause, needed_inner = self.build_filter(
  File "/Library/Frameworks/Python.framework/Versions/3.10/lib/python3.10/site-packages/django/db/models/sql/query.py", line 1407, in build_filter
    lookups, parts, reffed_expression = self.solve_lookup_type(arg)
  File "/Library/Frameworks/Python.framework/Versions/3.10/lib/python3.10/site-packages/django/db/models/sql/query.py", line 1217, in solve_lookup_type
    _, field, _, lookup_parts = self.names_to_path(lookup_splitted, self.get_meta())
  File "/Library/Frameworks/Python.framework/Versions/3.10/lib/python3.10/site-packages/django/db/models/sql/query.py", line 1709, in names_to_path
    raise FieldError(
django.core.exceptions.FieldError: Cannot resolve keyword 'user' into field. Choices are: category, costumer, id, invoice, offer, product, reviews
"GET /api/v1/sales/inventory/inventory/notifications HTTP/1.1" 500 133552
Internal Server Error: /api/v1/sales/inventory/inventory/notifications
Traceback (most recent call last):
  File "/Library/Frameworks/Python.framework/Versions/3.10/lib/python3.10/site-packages/django/core/handlers/exception.py", line 55, in inner
    response = get_response(request)
  File "/Library/Frameworks/Python.framework/Versions/3.10/lib/python3.10/site-packages/django/core/handlers/base.py", line 197, in _get_response
    response = wrapped_callback(request, *callback_args, **callback_kwargs)
  File "/Library/Frameworks/Python.framework/Versions/3.10/lib/python3.10/site-packages/django/views/decorators/csrf.py", line 54, in wrapped_view
    return view_func(*args, **kwargs)
  File "/Library/Frameworks/Python.framework/Versions/3.10/lib/python3.10/site-packages/django/views/generic/base.py", line 103, in view
    return self.dispatch(request, *args, **kwargs)
  File "/Library/Frameworks/Python.framework/Versions/3.10/lib/python3.10/site-packages/rest_framework/views.py", line 509, in dispatch
    response = self.handle_exception(exc)
  File "/Library/Frameworks/Python.framework/Versions/3.10/lib/python3.10/site-packages/rest_framework/views.py", line 469, in handle_exception
    self.raise_uncaught_exception(exc)
  File "/Library/Frameworks/Python.framework/Versions/3.10/lib/python3.10/site-packages/rest_framework/views.py", line 480, in raise_uncaught_exception
    raise exc
  File "/Library/Frameworks/Python.framework/Versions/3.10/lib/python3.10/site-packages/rest_framework/views.py", line 506, in dispatch
    response = handler(request, *args, **kwargs)
  File "/Users/macmini/Machine Learning/kaarujbe/kaaruj/sales/api/inventory/views.py", line 816, in get
    notifications = Notification.objects.filter(user=user)
  File "/Library/Frameworks/Python.framework/Versions/3.10/lib/python3.10/site-packages/django/db/models/manager.py", line 85, in manager_method
    return getattr(self.get_queryset(), name)(*args, **kwargs)
  File "/Library/Frameworks/Python.framework/Versions/3.10/lib/python3.10/site-packages/django/db/models/query.py", line 1420, in filter
    return self._filter_or_exclude(False, args, kwargs)
  File "/Library/Frameworks/Python.framework/Versions/3.10/lib/python3.10/site-packages/django/db/models/query.py", line 1438, in _filter_or_exclude
    clone._filter_or_exclude_inplace(negate, args, kwargs)
  File "/Library/Frameworks/Python.framework/Versions/3.10/lib/python3.10/site-packages/django/db/models/query.py", line 1445, in _filter_or_exclude_inplace
    self._query.add_q(Q(*args, **kwargs))
  File "/Library/Frameworks/Python.framework/Versions/3.10/lib/python3.10/site-packages/django/db/models/sql/query.py", line 1532, in add_q
    clause, _ = self._add_q(q_object, self.used_aliases)
  File "/Library/Frameworks/Python.framework/Versions/3.10/lib/python3.10/site-packages/django/db/models/sql/query.py", line 1562, in _add_q
    child_clause, needed_inner = self.build_filter(
  File "/Library/Frameworks/Python.framework/Versions/3.10/lib/python3.10/site-packages/django/db/models/sql/query.py", line 1407, in build_filter
    lookups, parts, reffed_expression = self.solve_lookup_type(arg)
  File "/Library/Frameworks/Python.framework/Versions/3.10/lib/python3.10/site-packages/django/db/models/sql/query.py", line 1217, in solve_lookup_type
    _, field, _, lookup_parts = self.names_to_path(lookup_splitted, self.get_meta())
  File "/Library/Frameworks/Python.framework/Versions/3.10/lib/python3.10/site-packages/django/db/models/sql/query.py", line 1709, in names_to_path
    raise FieldError(
django.core.exceptions.FieldError: Cannot resolve keyword 'user' into field. Choices are: category, costumer, id, invoice, offer, product, reviews
"GET /api/v1/sales/inventory/inventory/notifications HTTP/1.1" 500 133552
Internal Server Error: /api/v1/sales/inventory/inventory/notifications
Traceback (most recent call last):
  File "/Library/Frameworks/Python.framework/Versions/3.10/lib/python3.10/site-packages/django/core/handlers/exception.py", line 55, in inner
    response = get_response(request)
  File "/Library/Frameworks/Python.framework/Versions/3.10/lib/python3.10/site-packages/django/core/handlers/base.py", line 197, in _get_response
    response = wrapped_callback(request, *callback_args, **callback_kwargs)
  File "/Library/Frameworks/Python.framework/Versions/3.10/lib/python3.10/site-packages/django/views/decorators/csrf.py", line 54, in wrapped_view
    return view_func(*args, **kwargs)
  File "/Library/Frameworks/Python.framework/Versions/3.10/lib/python3.10/site-packages/django/views/generic/base.py", line 103, in view
    return self.dispatch(request, *args, **kwargs)
  File "/Library/Frameworks/Python.framework/Versions/3.10/lib/python3.10/site-packages/rest_framework/views.py", line 509, in dispatch
    response = self.handle_exception(exc)
  File "/Library/Frameworks/Python.framework/Versions/3.10/lib/python3.10/site-packages/rest_framework/views.py", line 469, in handle_exception
    self.raise_uncaught_exception(exc)
  File "/Library/Frameworks/Python.framework/Versions/3.10/lib/python3.10/site-packages/rest_framework/views.py", line 480, in raise_uncaught_exception
    raise exc
  File "/Library/Frameworks/Python.framework/Versions/3.10/lib/python3.10/site-packages/rest_framework/views.py", line 506, in dispatch
    response = handler(request, *args, **kwargs)
  File "/Users/macmini/Machine Learning/kaarujbe/kaaruj/sales/api/inventory/views.py", line 816, in get
    notifications = Notification.objects.filter(user=user)
  File "/Library/Frameworks/Python.framework/Versions/3.10/lib/python3.10/site-packages/django/db/models/manager.py", line 85, in manager_method
    return getattr(self.get_queryset(), name)(*args, **kwargs)
  File "/Library/Frameworks/Python.framework/Versions/3.10/lib/python3.10/site-packages/django/db/models/query.py", line 1420, in filter
    return self._filter_or_exclude(False, args, kwargs)
  File "/Library/Frameworks/Python.framework/Versions/3.10/lib/python3.10/site-packages/django/db/models/query.py", line 1438, in _filter_or_exclude
    clone._filter_or_exclude_inplace(negate, args, kwargs)
  File "/Library/Frameworks/Python.framework/Versions/3.10/lib/python3.10/site-packages/django/db/models/query.py", line 1445, in _filter_or_exclude_inplace
    self._query.add_q(Q(*args, **kwargs))
  File "/Library/Frameworks/Python.framework/Versions/3.10/lib/python3.10/site-packages/django/db/models/sql/query.py", line 1532, in add_q
    clause, _ = self._add_q(q_object, self.used_aliases)
  File "/Library/Frameworks/Python.framework/Versions/3.10/lib/python3.10/site-packages/django/db/models/sql/query.py", line 1562, in _add_q
    child_clause, needed_inner = self.build_filter(
  File "/Library/Frameworks/Python.framework/Versions/3.10/lib/python3.10/site-packages/django/db/models/sql/query.py", line 1407, in build_filter
    lookups, parts, reffed_expression = self.solve_lookup_type(arg)
  File "/Library/Frameworks/Python.framework/Versions/3.10/lib/python3.10/site-packages/django/db/models/sql/query.py", line 1217, in solve_lookup_type
    _, field, _, lookup_parts = self.names_to_path(lookup_splitted, self.get_meta())
  File "/Library/Frameworks/Python.framework/Versions/3.10/lib/python3.10/site-packages/django/db/models/sql/query.py", line 1709, in names_to_path
    raise FieldError(
django.core.exceptions.FieldError: Cannot resolve keyword 'user' into field. Choices are: category, costumer, id, invoice, offer, product, reviews
"GET /api/v1/sales/inventory/inventory/notifications HTTP/1.1" 500 133552
Internal Server Error: /api/v1/sales/inventory/inventory/notifications
Traceback (most recent call last):
  File "/Library/Frameworks/Python.framework/Versions/3.10/lib/python3.10/site-packages/django/core/handlers/exception.py", line 55, in inner
    response = get_response(request)
  File "/Library/Frameworks/Python.framework/Versions/3.10/lib/python3.10/site-packages/django/core/handlers/base.py", line 197, in _get_response
    response = wrapped_callback(request, *callback_args, **callback_kwargs)
  File "/Library/Frameworks/Python.framework/Versions/3.10/lib/python3.10/site-packages/django/views/decorators/csrf.py", line 54, in wrapped_view
    return view_func(*args, **kwargs)
  File "/Library/Frameworks/Python.framework/Versions/3.10/lib/python3.10/site-packages/django/views/generic/base.py", line 103, in view
    return self.dispatch(request, *args, **kwargs)
  File "/Library/Frameworks/Python.framework/Versions/3.10/lib/python3.10/site-packages/rest_framework/views.py", line 509, in dispatch
    response = self.handle_exception(exc)
  File "/Library/Frameworks/Python.framework/Versions/3.10/lib/python3.10/site-packages/rest_framework/views.py", line 469, in handle_exception
    self.raise_uncaught_exception(exc)
  File "/Library/Frameworks/Python.framework/Versions/3.10/lib/python3.10/site-packages/rest_framework/views.py", line 480, in raise_uncaught_exception
    raise exc
  File "/Library/Frameworks/Python.framework/Versions/3.10/lib/python3.10/site-packages/rest_framework/views.py", line 506, in dispatch
    response = handler(request, *args, **kwargs)
  File "/Users/macmini/Machine Learning/kaarujbe/kaaruj/sales/api/inventory/views.py", line 816, in get
    notifications = Notification.objects.filter(user=user)
  File "/Library/Frameworks/Python.framework/Versions/3.10/lib/python3.10/site-packages/django/db/models/manager.py", line 85, in manager_method
    return getattr(self.get_queryset(), name)(*args, **kwargs)
  File "/Library/Frameworks/Python.framework/Versions/3.10/lib/python3.10/site-packages/django/db/models/query.py", line 1420, in filter
    return self._filter_or_exclude(False, args, kwargs)
  File "/Library/Frameworks/Python.framework/Versions/3.10/lib/python3.10/site-packages/django/db/models/query.py", line 1438, in _filter_or_exclude
    clone._filter_or_exclude_inplace(negate, args, kwargs)
  File "/Library/Frameworks/Python.framework/Versions/3.10/lib/python3.10/site-packages/django/db/models/query.py", line 1445, in _filter_or_exclude_inplace
    self._query.add_q(Q(*args, **kwargs))
  File "/Library/Frameworks/Python.framework/Versions/3.10/lib/python3.10/site-packages/django/db/models/sql/query.py", line 1532, in add_q
    clause, _ = self._add_q(q_object, self.used_aliases)
  File "/Library/Frameworks/Python.framework/Versions/3.10/lib/python3.10/site-packages/django/db/models/sql/query.py", line 1562, in _add_q
    child_clause, needed_inner = self.build_filter(
  File "/Library/Frameworks/Python.framework/Versions/3.10/lib/python3.10/site-packages/django/db/models/sql/query.py", line 1407, in build_filter
    lookups, parts, reffed_expression = self.solve_lookup_type(arg)
  File "/Library/Frameworks/Python.framework/Versions/3.10/lib/python3.10/site-packages/django/db/models/sql/query.py", line 1217, in solve_lookup_type
    _, field, _, lookup_parts = self.names_to_path(lookup_splitted, self.get_meta())
  File "/Library/Frameworks/Python.framework/Versions/3.10/lib/python3.10/site-packages/django/db/models/sql/query.py", line 1709, in names_to_path
    raise FieldError(
django.core.exceptions.FieldError: Cannot resolve keyword 'user' into field. Choices are: category, costumer, id, invoice, offer, product, reviews
"GET /api/v1/sales/inventory/inventory/notifications HTTP/1.1" 500 133552
Internal Server Error: /api/v1/sales/inventory/inventory/notifications
Traceback (most recent call last):
  File "/Library/Frameworks/Python.framework/Versions/3.10/lib/python3.10/site-packages/django/core/handlers/exception.py", line 55, in inner
    response = get_response(request)
  File "/Library/Frameworks/Python.framework/Versions/3.10/lib/python3.10/site-packages/django/core/handlers/base.py", line 197, in _get_response
    response = wrapped_callback(request, *callback_args, **callback_kwargs)
  File "/Library/Frameworks/Python.framework/Versions/3.10/lib/python3.10/site-packages/django/views/decorators/csrf.py", line 54, in wrapped_view
    return view_func(*args, **kwargs)
  File "/Library/Frameworks/Python.framework/Versions/3.10/lib/python3.10/site-packages/django/views/generic/base.py", line 103, in view
    return self.dispatch(request, *args, **kwargs)
  File "/Library/Frameworks/Python.framework/Versions/3.10/lib/python3.10/site-packages/rest_framework/views.py", line 509, in dispatch
    response = self.handle_exception(exc)
  File "/Library/Frameworks/Python.framework/Versions/3.10/lib/python3.10/site-packages/rest_framework/views.py", line 469, in handle_exception
    self.raise_uncaught_exception(exc)
  File "/Library/Frameworks/Python.framework/Versions/3.10/lib/python3.10/site-packages/rest_framework/views.py", line 480, in raise_uncaught_exception
    raise exc
  File "/Library/Frameworks/Python.framework/Versions/3.10/lib/python3.10/site-packages/rest_framework/views.py", line 506, in dispatch
    response = handler(request, *args, **kwargs)
  File "/Users/macmini/Machine Learning/kaarujbe/kaaruj/sales/api/inventory/views.py", line 816, in get
    notifications = Notification.objects.filter(user=user)
  File "/Library/Frameworks/Python.framework/Versions/3.10/lib/python3.10/site-packages/django/db/models/manager.py", line 85, in manager_method
    return getattr(self.get_queryset(), name)(*args, **kwargs)
  File "/Library/Frameworks/Python.framework/Versions/3.10/lib/python3.10/site-packages/django/db/models/query.py", line 1420, in filter
    return self._filter_or_exclude(False, args, kwargs)
  File "/Library/Frameworks/Python.framework/Versions/3.10/lib/python3.10/site-packages/django/db/models/query.py", line 1438, in _filter_or_exclude
    clone._filter_or_exclude_inplace(negate, args, kwargs)
  File "/Library/Frameworks/Python.framework/Versions/3.10/lib/python3.10/site-packages/django/db/models/query.py", line 1445, in _filter_or_exclude_inplace
    self._query.add_q(Q(*args, **kwargs))
  File "/Library/Frameworks/Python.framework/Versions/3.10/lib/python3.10/site-packages/django/db/models/sql/query.py", line 1532, in add_q
    clause, _ = self._add_q(q_object, self.used_aliases)
  File "/Library/Frameworks/Python.framework/Versions/3.10/lib/python3.10/site-packages/django/db/models/sql/query.py", line 1562, in _add_q
    child_clause, needed_inner = self.build_filter(
  File "/Library/Frameworks/Python.framework/Versions/3.10/lib/python3.10/site-packages/django/db/models/sql/query.py", line 1407, in build_filter
    lookups, parts, reffed_expression = self.solve_lookup_type(arg)
  File "/Library/Frameworks/Python.framework/Versions/3.10/lib/python3.10/site-packages/django/db/models/sql/query.py", line 1217, in solve_lookup_type
    _, field, _, lookup_parts = self.names_to_path(lookup_splitted, self.get_meta())
  File "/Library/Frameworks/Python.framework/Versions/3.10/lib/python3.10/site-packages/django/db/models/sql/query.py", line 1709, in names_to_path
    raise FieldError(
django.core.exceptions.FieldError: Cannot resolve keyword 'user' into field. Choices are: category, costumer, id, invoice, offer, product, reviews
"GET /api/v1/sales/inventory/inventory/notifications HTTP/1.1" 500 133552
test_path/bar_codes/base/white.png /bar_codes/base/out/out.png
Internal Server Error: /api/v1/sales/inventory/inventory/notifications
Traceback (most recent call last):
  File "/Library/Frameworks/Python.framework/Versions/3.10/lib/python3.10/site-packages/django/core/handlers/exception.py", line 55, in inner
    response = get_response(request)
  File "/Library/Frameworks/Python.framework/Versions/3.10/lib/python3.10/site-packages/django/core/handlers/base.py", line 197, in _get_response
    response = wrapped_callback(request, *callback_args, **callback_kwargs)
  File "/Library/Frameworks/Python.framework/Versions/3.10/lib/python3.10/site-packages/django/views/decorators/csrf.py", line 54, in wrapped_view
    return view_func(*args, **kwargs)
  File "/Library/Frameworks/Python.framework/Versions/3.10/lib/python3.10/site-packages/django/views/generic/base.py", line 103, in view
    return self.dispatch(request, *args, **kwargs)
  File "/Library/Frameworks/Python.framework/Versions/3.10/lib/python3.10/site-packages/rest_framework/views.py", line 509, in dispatch
    response = self.handle_exception(exc)
  File "/Library/Frameworks/Python.framework/Versions/3.10/lib/python3.10/site-packages/rest_framework/views.py", line 469, in handle_exception
    self.raise_uncaught_exception(exc)
  File "/Library/Frameworks/Python.framework/Versions/3.10/lib/python3.10/site-packages/rest_framework/views.py", line 480, in raise_uncaught_exception
    raise exc
  File "/Library/Frameworks/Python.framework/Versions/3.10/lib/python3.10/site-packages/rest_framework/views.py", line 506, in dispatch
    response = handler(request, *args, **kwargs)
  File "/Users/macmini/Machine Learning/kaarujbe/kaaruj/sales/api/inventory/views.py", line 816, in get
    notifications = Notification.objects.get()
  File "/Library/Frameworks/Python.framework/Versions/3.10/lib/python3.10/site-packages/django/db/models/manager.py", line 85, in manager_method
    return getattr(self.get_queryset(), name)(*args, **kwargs)
  File "/Library/Frameworks/Python.framework/Versions/3.10/lib/python3.10/site-packages/django/db/models/query.py", line 653, in get
    raise self.model.MultipleObjectsReturned(
sales.models.Notification.MultipleObjectsReturned: get() returned more than one Notification -- it returned 2!
"GET /api/v1/sales/inventory/inventory/notifications HTTP/1.1" 500 99640
Internal Server Error: /api/v1/sales/inventory/inventory/notifications
Traceback (most recent call last):
  File "/Library/Frameworks/Python.framework/Versions/3.10/lib/python3.10/site-packages/django/core/handlers/exception.py", line 55, in inner
    response = get_response(request)
  File "/Library/Frameworks/Python.framework/Versions/3.10/lib/python3.10/site-packages/django/core/handlers/base.py", line 197, in _get_response
    response = wrapped_callback(request, *callback_args, **callback_kwargs)
  File "/Library/Frameworks/Python.framework/Versions/3.10/lib/python3.10/site-packages/django/views/decorators/csrf.py", line 54, in wrapped_view
    return view_func(*args, **kwargs)
  File "/Library/Frameworks/Python.framework/Versions/3.10/lib/python3.10/site-packages/django/views/generic/base.py", line 103, in view
    return self.dispatch(request, *args, **kwargs)
  File "/Library/Frameworks/Python.framework/Versions/3.10/lib/python3.10/site-packages/rest_framework/views.py", line 509, in dispatch
    response = self.handle_exception(exc)
  File "/Library/Frameworks/Python.framework/Versions/3.10/lib/python3.10/site-packages/rest_framework/views.py", line 469, in handle_exception
    self.raise_uncaught_exception(exc)
  File "/Library/Frameworks/Python.framework/Versions/3.10/lib/python3.10/site-packages/rest_framework/views.py", line 480, in raise_uncaught_exception
    raise exc
  File "/Library/Frameworks/Python.framework/Versions/3.10/lib/python3.10/site-packages/rest_framework/views.py", line 506, in dispatch
    response = handler(request, *args, **kwargs)
  File "/Users/macmini/Machine Learning/kaarujbe/kaaruj/sales/api/inventory/views.py", line 816, in get
    notifications = Notification.objects.get()
  File "/Library/Frameworks/Python.framework/Versions/3.10/lib/python3.10/site-packages/django/db/models/manager.py", line 85, in manager_method
    return getattr(self.get_queryset(), name)(*args, **kwargs)
  File "/Library/Frameworks/Python.framework/Versions/3.10/lib/python3.10/site-packages/django/db/models/query.py", line 653, in get
    raise self.model.MultipleObjectsReturned(
sales.models.Notification.MultipleObjectsReturned: get() returned more than one Notification -- it returned 2!
"GET /api/v1/sales/inventory/inventory/notifications HTTP/1.1" 500 99640
Internal Server Error: /api/v1/sales/inventory/inventory/notifications
Traceback (most recent call last):
  File "/Library/Frameworks/Python.framework/Versions/3.10/lib/python3.10/site-packages/django/core/handlers/exception.py", line 55, in inner
    response = get_response(request)
  File "/Library/Frameworks/Python.framework/Versions/3.10/lib/python3.10/site-packages/django/core/handlers/base.py", line 197, in _get_response
    response = wrapped_callback(request, *callback_args, **callback_kwargs)
  File "/Library/Frameworks/Python.framework/Versions/3.10/lib/python3.10/site-packages/django/views/decorators/csrf.py", line 54, in wrapped_view
    return view_func(*args, **kwargs)
  File "/Library/Frameworks/Python.framework/Versions/3.10/lib/python3.10/site-packages/django/views/generic/base.py", line 103, in view
    return self.dispatch(request, *args, **kwargs)
  File "/Library/Frameworks/Python.framework/Versions/3.10/lib/python3.10/site-packages/rest_framework/views.py", line 509, in dispatch
    response = self.handle_exception(exc)
  File "/Library/Frameworks/Python.framework/Versions/3.10/lib/python3.10/site-packages/rest_framework/views.py", line 469, in handle_exception
    self.raise_uncaught_exception(exc)
  File "/Library/Frameworks/Python.framework/Versions/3.10/lib/python3.10/site-packages/rest_framework/views.py", line 480, in raise_uncaught_exception
    raise exc
  File "/Library/Frameworks/Python.framework/Versions/3.10/lib/python3.10/site-packages/rest_framework/views.py", line 506, in dispatch
    response = handler(request, *args, **kwargs)
  File "/Users/macmini/Machine Learning/kaarujbe/kaaruj/sales/api/inventory/views.py", line 816, in get
    notifications = Notification.objects.get()
  File "/Library/Frameworks/Python.framework/Versions/3.10/lib/python3.10/site-packages/django/db/models/manager.py", line 85, in manager_method
    return getattr(self.get_queryset(), name)(*args, **kwargs)
  File "/Library/Frameworks/Python.framework/Versions/3.10/lib/python3.10/site-packages/django/db/models/query.py", line 653, in get
    raise self.model.MultipleObjectsReturned(
sales.models.Notification.MultipleObjectsReturned: get() returned more than one Notification -- it returned 2!
"GET /api/v1/sales/inventory/inventory/notifications HTTP/1.1" 500 99640
Internal Server Error: /api/v1/sales/inventory/inventory/notifications
Traceback (most recent call last):
  File "/Library/Frameworks/Python.framework/Versions/3.10/lib/python3.10/site-packages/django/core/handlers/exception.py", line 55, in inner
    response = get_response(request)
  File "/Library/Frameworks/Python.framework/Versions/3.10/lib/python3.10/site-packages/django/core/handlers/base.py", line 197, in _get_response
    response = wrapped_callback(request, *callback_args, **callback_kwargs)
  File "/Library/Frameworks/Python.framework/Versions/3.10/lib/python3.10/site-packages/django/views/decorators/csrf.py", line 54, in wrapped_view
    return view_func(*args, **kwargs)
  File "/Library/Frameworks/Python.framework/Versions/3.10/lib/python3.10/site-packages/django/views/generic/base.py", line 103, in view
    return self.dispatch(request, *args, **kwargs)
  File "/Library/Frameworks/Python.framework/Versions/3.10/lib/python3.10/site-packages/rest_framework/views.py", line 509, in dispatch
    response = self.handle_exception(exc)
  File "/Library/Frameworks/Python.framework/Versions/3.10/lib/python3.10/site-packages/rest_framework/views.py", line 469, in handle_exception
    self.raise_uncaught_exception(exc)
  File "/Library/Frameworks/Python.framework/Versions/3.10/lib/python3.10/site-packages/rest_framework/views.py", line 480, in raise_uncaught_exception
    raise exc
  File "/Library/Frameworks/Python.framework/Versions/3.10/lib/python3.10/site-packages/rest_framework/views.py", line 506, in dispatch
    response = handler(request, *args, **kwargs)
  File "/Users/macmini/Machine Learning/kaarujbe/kaaruj/sales/api/inventory/views.py", line 816, in get
    notifications = Notification.objects.get()
  File "/Library/Frameworks/Python.framework/Versions/3.10/lib/python3.10/site-packages/django/db/models/manager.py", line 85, in manager_method
    return getattr(self.get_queryset(), name)(*args, **kwargs)
  File "/Library/Frameworks/Python.framework/Versions/3.10/lib/python3.10/site-packages/django/db/models/query.py", line 653, in get
    raise self.model.MultipleObjectsReturned(
sales.models.Notification.MultipleObjectsReturned: get() returned more than one Notification -- it returned 2!
"GET /api/v1/sales/inventory/inventory/notifications HTTP/1.1" 500 99640
test_path/bar_codes/base/white.png /bar_codes/base/out/out.png
test_path/bar_codes/base/white.png /bar_codes/base/out/out.png
Internal Server Error: /api/v1/sales/inventory/inventory/notifications
Traceback (most recent call last):
  File "/Library/Frameworks/Python.framework/Versions/3.10/lib/python3.10/site-packages/django/core/handlers/exception.py", line 55, in inner
    response = get_response(request)
  File "/Library/Frameworks/Python.framework/Versions/3.10/lib/python3.10/site-packages/django/core/handlers/base.py", line 197, in _get_response
    response = wrapped_callback(request, *callback_args, **callback_kwargs)
  File "/Library/Frameworks/Python.framework/Versions/3.10/lib/python3.10/site-packages/django/views/decorators/csrf.py", line 54, in wrapped_view
    return view_func(*args, **kwargs)
  File "/Library/Frameworks/Python.framework/Versions/3.10/lib/python3.10/site-packages/django/views/generic/base.py", line 103, in view
    return self.dispatch(request, *args, **kwargs)
  File "/Library/Frameworks/Python.framework/Versions/3.10/lib/python3.10/site-packages/rest_framework/views.py", line 509, in dispatch
    response = self.handle_exception(exc)
  File "/Library/Frameworks/Python.framework/Versions/3.10/lib/python3.10/site-packages/rest_framework/views.py", line 469, in handle_exception
    self.raise_uncaught_exception(exc)
  File "/Library/Frameworks/Python.framework/Versions/3.10/lib/python3.10/site-packages/rest_framework/views.py", line 480, in raise_uncaught_exception
    raise exc
  File "/Library/Frameworks/Python.framework/Versions/3.10/lib/python3.10/site-packages/rest_framework/views.py", line 506, in dispatch
    response = handler(request, *args, **kwargs)
  File "/Users/macmini/Machine Learning/kaarujbe/kaaruj/sales/api/inventory/views.py", line 816, in get
    notifications = Notification.objects.get()
  File "/Library/Frameworks/Python.framework/Versions/3.10/lib/python3.10/site-packages/django/db/models/manager.py", line 85, in manager_method
    return getattr(self.get_queryset(), name)(*args, **kwargs)
  File "/Library/Frameworks/Python.framework/Versions/3.10/lib/python3.10/site-packages/django/db/models/query.py", line 653, in get
    raise self.model.MultipleObjectsReturned(
sales.models.Notification.MultipleObjectsReturned: get() returned more than one Notification -- it returned 2!
"GET /api/v1/sales/inventory/inventory/notifications HTTP/1.1" 500 99640
test_path/bar_codes/base/white.png /bar_codes/base/out/out.png
test_path/bar_codes/base/white.png /bar_codes/base/out/out.png
Internal Server Error: /admin/sales/notification/
Traceback (most recent call last):
  File "/Library/Frameworks/Python.framework/Versions/3.10/lib/python3.10/site-packages/django/db/backends/utils.py", line 89, in _execute
    return self.cursor.execute(sql, params)
  File "/Library/Frameworks/Python.framework/Versions/3.10/lib/python3.10/site-packages/django/db/backends/sqlite3/base.py", line 357, in execute
    return Database.Cursor.execute(self, query, params)
sqlite3.OperationalError: no such column: sales_notification.user_id

The above exception was the direct cause of the following exception:

Traceback (most recent call last):
  File "/Library/Frameworks/Python.framework/Versions/3.10/lib/python3.10/site-packages/django/core/handlers/exception.py", line 55, in inner
    response = get_response(request)
  File "/Library/Frameworks/Python.framework/Versions/3.10/lib/python3.10/site-packages/django/core/handlers/base.py", line 197, in _get_response
    response = wrapped_callback(request, *callback_args, **callback_kwargs)
  File "/Library/Frameworks/Python.framework/Versions/3.10/lib/python3.10/site-packages/django/contrib/admin/options.py", line 686, in wrapper
    return self.admin_site.admin_view(view)(*args, **kwargs)
  File "/Library/Frameworks/Python.framework/Versions/3.10/lib/python3.10/site-packages/django/utils/decorators.py", line 133, in _wrapped_view
    response = view_func(request, *args, **kwargs)
  File "/Library/Frameworks/Python.framework/Versions/3.10/lib/python3.10/site-packages/django/views/decorators/cache.py", line 62, in _wrapped_view_func
    response = view_func(request, *args, **kwargs)
  File "/Library/Frameworks/Python.framework/Versions/3.10/lib/python3.10/site-packages/django/contrib/admin/sites.py", line 242, in inner
    return view(request, *args, **kwargs)
  File "/Library/Frameworks/Python.framework/Versions/3.10/lib/python3.10/site-packages/django/utils/decorators.py", line 46, in _wrapper
    return bound_method(*args, **kwargs)
  File "/Library/Frameworks/Python.framework/Versions/3.10/lib/python3.10/site-packages/django/utils/decorators.py", line 133, in _wrapped_view
    response = view_func(request, *args, **kwargs)
  File "/Library/Frameworks/Python.framework/Versions/3.10/lib/python3.10/site-packages/django/contrib/admin/options.py", line 2068, in changelist_view
    "selection_note": _("0 of %(cnt)s selected") % {"cnt": len(cl.result_list)},
  File "/Library/Frameworks/Python.framework/Versions/3.10/lib/python3.10/site-packages/django/db/models/query.py", line 376, in __len__
    self._fetch_all()
  File "/Library/Frameworks/Python.framework/Versions/3.10/lib/python3.10/site-packages/django/db/models/query.py", line 1866, in _fetch_all
    self._result_cache = list(self._iterable_class(self))
  File "/Library/Frameworks/Python.framework/Versions/3.10/lib/python3.10/site-packages/django/db/models/query.py", line 87, in __iter__
    results = compiler.execute_sql(
  File "/Library/Frameworks/Python.framework/Versions/3.10/lib/python3.10/site-packages/django/db/models/sql/compiler.py", line 1395, in execute_sql
    cursor.execute(sql, params)
  File "/Library/Frameworks/Python.framework/Versions/3.10/lib/python3.10/site-packages/django/db/backends/utils.py", line 103, in execute
    return super().execute(sql, params)
  File "/Library/Frameworks/Python.framework/Versions/3.10/lib/python3.10/site-packages/django/db/backends/utils.py", line 67, in execute
    return self._execute_with_wrappers(
  File "/Library/Frameworks/Python.framework/Versions/3.10/lib/python3.10/site-packages/django/db/backends/utils.py", line 80, in _execute_with_wrappers
    return executor(sql, params, many, context)
  File "/Library/Frameworks/Python.framework/Versions/3.10/lib/python3.10/site-packages/django/db/backends/utils.py", line 84, in _execute
    with self.db.wrap_database_errors:
  File "/Library/Frameworks/Python.framework/Versions/3.10/lib/python3.10/site-packages/django/db/utils.py", line 91, in __exit__
    raise dj_exc_value.with_traceback(traceback) from exc_value
  File "/Library/Frameworks/Python.framework/Versions/3.10/lib/python3.10/site-packages/django/db/backends/utils.py", line 89, in _execute
    return self.cursor.execute(sql, params)
  File "/Library/Frameworks/Python.framework/Versions/3.10/lib/python3.10/site-packages/django/db/backends/sqlite3/base.py", line 357, in execute
    return Database.Cursor.execute(self, query, params)
django.db.utils.OperationalError: no such column: sales_notification.user_id
"GET /admin/sales/notification/ HTTP/1.1" 500 154833
test_path/bar_codes/base/white.png /bar_codes/base/out/out.png
test_path/bar_codes/base/white.png /bar_codes/base/out/out.png
test_path/bar_codes/base/white.png /bar_codes/base/out/out.png
test_path/bar_codes/base/white.png /bar_codes/base/out/out.png
Internal Server Error: /admin/sales/notification/
Traceback (most recent call last):
  File "/Library/Frameworks/Python.framework/Versions/3.10/lib/python3.10/site-packages/django/db/backends/utils.py", line 89, in _execute
    return self.cursor.execute(sql, params)
  File "/Library/Frameworks/Python.framework/Versions/3.10/lib/python3.10/site-packages/django/db/backends/sqlite3/base.py", line 357, in execute
    return Database.Cursor.execute(self, query, params)
sqlite3.OperationalError: no such column: sales_notification.user_id

The above exception was the direct cause of the following exception:

Traceback (most recent call last):
  File "/Library/Frameworks/Python.framework/Versions/3.10/lib/python3.10/site-packages/django/core/handlers/exception.py", line 55, in inner
    response = get_response(request)
  File "/Library/Frameworks/Python.framework/Versions/3.10/lib/python3.10/site-packages/django/core/handlers/base.py", line 197, in _get_response
    response = wrapped_callback(request, *callback_args, **callback_kwargs)
  File "/Library/Frameworks/Python.framework/Versions/3.10/lib/python3.10/site-packages/django/contrib/admin/options.py", line 686, in wrapper
    return self.admin_site.admin_view(view)(*args, **kwargs)
  File "/Library/Frameworks/Python.framework/Versions/3.10/lib/python3.10/site-packages/django/utils/decorators.py", line 133, in _wrapped_view
    response = view_func(request, *args, **kwargs)
  File "/Library/Frameworks/Python.framework/Versions/3.10/lib/python3.10/site-packages/django/views/decorators/cache.py", line 62, in _wrapped_view_func
    response = view_func(request, *args, **kwargs)
  File "/Library/Frameworks/Python.framework/Versions/3.10/lib/python3.10/site-packages/django/contrib/admin/sites.py", line 242, in inner
    return view(request, *args, **kwargs)
  File "/Library/Frameworks/Python.framework/Versions/3.10/lib/python3.10/site-packages/django/utils/decorators.py", line 46, in _wrapper
    return bound_method(*args, **kwargs)
  File "/Library/Frameworks/Python.framework/Versions/3.10/lib/python3.10/site-packages/django/utils/decorators.py", line 133, in _wrapped_view
    response = view_func(request, *args, **kwargs)
  File "/Library/Frameworks/Python.framework/Versions/3.10/lib/python3.10/site-packages/django/contrib/admin/options.py", line 2068, in changelist_view
    "selection_note": _("0 of %(cnt)s selected") % {"cnt": len(cl.result_list)},
  File "/Library/Frameworks/Python.framework/Versions/3.10/lib/python3.10/site-packages/django/db/models/query.py", line 376, in __len__
    self._fetch_all()
  File "/Library/Frameworks/Python.framework/Versions/3.10/lib/python3.10/site-packages/django/db/models/query.py", line 1866, in _fetch_all
    self._result_cache = list(self._iterable_class(self))
  File "/Library/Frameworks/Python.framework/Versions/3.10/lib/python3.10/site-packages/django/db/models/query.py", line 87, in __iter__
    results = compiler.execute_sql(
  File "/Library/Frameworks/Python.framework/Versions/3.10/lib/python3.10/site-packages/django/db/models/sql/compiler.py", line 1395, in execute_sql
    cursor.execute(sql, params)
  File "/Library/Frameworks/Python.framework/Versions/3.10/lib/python3.10/site-packages/django/db/backends/utils.py", line 103, in execute
    return super().execute(sql, params)
  File "/Library/Frameworks/Python.framework/Versions/3.10/lib/python3.10/site-packages/django/db/backends/utils.py", line 67, in execute
    return self._execute_with_wrappers(
  File "/Library/Frameworks/Python.framework/Versions/3.10/lib/python3.10/site-packages/django/db/backends/utils.py", line 80, in _execute_with_wrappers
    return executor(sql, params, many, context)
  File "/Library/Frameworks/Python.framework/Versions/3.10/lib/python3.10/site-packages/django/db/backends/utils.py", line 84, in _execute
    with self.db.wrap_database_errors:
  File "/Library/Frameworks/Python.framework/Versions/3.10/lib/python3.10/site-packages/django/db/utils.py", line 91, in __exit__
    raise dj_exc_value.with_traceback(traceback) from exc_value
  File "/Library/Frameworks/Python.framework/Versions/3.10/lib/python3.10/site-packages/django/db/backends/utils.py", line 89, in _execute
    return self.cursor.execute(sql, params)
  File "/Library/Frameworks/Python.framework/Versions/3.10/lib/python3.10/site-packages/django/db/backends/sqlite3/base.py", line 357, in execute
    return Database.Cursor.execute(self, query, params)
django.db.utils.OperationalError: no such column: sales_notification.user_id
"GET /admin/sales/notification/ HTTP/1.1" 500 154970
test_path/bar_codes/base/white.png /bar_codes/base/out/out.png
test_path/bar_codes/base/white.png /bar_codes/base/out/out.png
Internal Server Error: /admin/sales/notification/
Traceback (most recent call last):
  File "/Library/Frameworks/Python.framework/Versions/3.10/lib/python3.10/site-packages/django/db/backends/utils.py", line 89, in _execute
    return self.cursor.execute(sql, params)
  File "/Library/Frameworks/Python.framework/Versions/3.10/lib/python3.10/site-packages/django/db/backends/sqlite3/base.py", line 357, in execute
    return Database.Cursor.execute(self, query, params)
sqlite3.OperationalError: no such column: sales_notification.user_id

The above exception was the direct cause of the following exception:

Traceback (most recent call last):
  File "/Library/Frameworks/Python.framework/Versions/3.10/lib/python3.10/site-packages/django/core/handlers/exception.py", line 55, in inner
    response = get_response(request)
  File "/Library/Frameworks/Python.framework/Versions/3.10/lib/python3.10/site-packages/django/core/handlers/base.py", line 197, in _get_response
    response = wrapped_callback(request, *callback_args, **callback_kwargs)
  File "/Library/Frameworks/Python.framework/Versions/3.10/lib/python3.10/site-packages/django/contrib/admin/options.py", line 686, in wrapper
    return self.admin_site.admin_view(view)(*args, **kwargs)
  File "/Library/Frameworks/Python.framework/Versions/3.10/lib/python3.10/site-packages/django/utils/decorators.py", line 133, in _wrapped_view
    response = view_func(request, *args, **kwargs)
  File "/Library/Frameworks/Python.framework/Versions/3.10/lib/python3.10/site-packages/django/views/decorators/cache.py", line 62, in _wrapped_view_func
    response = view_func(request, *args, **kwargs)
  File "/Library/Frameworks/Python.framework/Versions/3.10/lib/python3.10/site-packages/django/contrib/admin/sites.py", line 242, in inner
    return view(request, *args, **kwargs)
  File "/Library/Frameworks/Python.framework/Versions/3.10/lib/python3.10/site-packages/django/utils/decorators.py", line 46, in _wrapper
    return bound_method(*args, **kwargs)
  File "/Library/Frameworks/Python.framework/Versions/3.10/lib/python3.10/site-packages/django/utils/decorators.py", line 133, in _wrapped_view
    response = view_func(request, *args, **kwargs)
  File "/Library/Frameworks/Python.framework/Versions/3.10/lib/python3.10/site-packages/django/contrib/admin/options.py", line 2068, in changelist_view
    "selection_note": _("0 of %(cnt)s selected") % {"cnt": len(cl.result_list)},
  File "/Library/Frameworks/Python.framework/Versions/3.10/lib/python3.10/site-packages/django/db/models/query.py", line 376, in __len__
    self._fetch_all()
  File "/Library/Frameworks/Python.framework/Versions/3.10/lib/python3.10/site-packages/django/db/models/query.py", line 1866, in _fetch_all
    self._result_cache = list(self._iterable_class(self))
  File "/Library/Frameworks/Python.framework/Versions/3.10/lib/python3.10/site-packages/django/db/models/query.py", line 87, in __iter__
    results = compiler.execute_sql(
  File "/Library/Frameworks/Python.framework/Versions/3.10/lib/python3.10/site-packages/django/db/models/sql/compiler.py", line 1395, in execute_sql
    cursor.execute(sql, params)
  File "/Library/Frameworks/Python.framework/Versions/3.10/lib/python3.10/site-packages/django/db/backends/utils.py", line 103, in execute
    return super().execute(sql, params)
  File "/Library/Frameworks/Python.framework/Versions/3.10/lib/python3.10/site-packages/django/db/backends/utils.py", line 67, in execute
    return self._execute_with_wrappers(
  File "/Library/Frameworks/Python.framework/Versions/3.10/lib/python3.10/site-packages/django/db/backends/utils.py", line 80, in _execute_with_wrappers
    return executor(sql, params, many, context)
  File "/Library/Frameworks/Python.framework/Versions/3.10/lib/python3.10/site-packages/django/db/backends/utils.py", line 84, in _execute
    with self.db.wrap_database_errors:
  File "/Library/Frameworks/Python.framework/Versions/3.10/lib/python3.10/site-packages/django/db/utils.py", line 91, in __exit__
    raise dj_exc_value.with_traceback(traceback) from exc_value
  File "/Library/Frameworks/Python.framework/Versions/3.10/lib/python3.10/site-packages/django/db/backends/utils.py", line 89, in _execute
    return self.cursor.execute(sql, params)
  File "/Library/Frameworks/Python.framework/Versions/3.10/lib/python3.10/site-packages/django/db/backends/sqlite3/base.py", line 357, in execute
    return Database.Cursor.execute(self, query, params)
django.db.utils.OperationalError: no such column: sales_notification.user_id
"GET /admin/sales/notification/ HTTP/1.1" 500 154833
test_path/bar_codes/base/white.png /bar_codes/base/out/out.png
test_path/bar_codes/base/white.png /bar_codes/base/out/out.png
test_path/bar_codes/base/white.png /bar_codes/base/out/out.png
test_path/bar_codes/base/white.png /bar_codes/base/out/out.png
test_path/bar_codes/base/white.png /bar_codes/base/out/out.png
test_path/bar_codes/base/white.png /bar_codes/base/out/out.png
test_path/bar_codes/base/white.png /bar_codes/base/out/out.png
test_path/bar_codes/base/white.png /bar_codes/base/out/out.png
test_path/bar_codes/base/white.png /bar_codes/base/out/out.png
test_path/bar_codes/base/white.png /bar_codes/base/out/out.png
Internal Server Error: /admin/sales/notification/
Traceback (most recent call last):
  File "/Library/Frameworks/Python.framework/Versions/3.10/lib/python3.10/site-packages/django/db/backends/utils.py", line 89, in _execute
    return self.cursor.execute(sql, params)
  File "/Library/Frameworks/Python.framework/Versions/3.10/lib/python3.10/site-packages/django/db/backends/sqlite3/base.py", line 357, in execute
    return Database.Cursor.execute(self, query, params)
sqlite3.OperationalError: no such column: sales_notification.contact_us

The above exception was the direct cause of the following exception:

Traceback (most recent call last):
  File "/Library/Frameworks/Python.framework/Versions/3.10/lib/python3.10/site-packages/django/core/handlers/exception.py", line 55, in inner
    response = get_response(request)
  File "/Library/Frameworks/Python.framework/Versions/3.10/lib/python3.10/site-packages/django/core/handlers/base.py", line 197, in _get_response
    response = wrapped_callback(request, *callback_args, **callback_kwargs)
  File "/Library/Frameworks/Python.framework/Versions/3.10/lib/python3.10/site-packages/django/contrib/admin/options.py", line 686, in wrapper
    return self.admin_site.admin_view(view)(*args, **kwargs)
  File "/Library/Frameworks/Python.framework/Versions/3.10/lib/python3.10/site-packages/django/utils/decorators.py", line 133, in _wrapped_view
    response = view_func(request, *args, **kwargs)
  File "/Library/Frameworks/Python.framework/Versions/3.10/lib/python3.10/site-packages/django/views/decorators/cache.py", line 62, in _wrapped_view_func
    response = view_func(request, *args, **kwargs)
  File "/Library/Frameworks/Python.framework/Versions/3.10/lib/python3.10/site-packages/django/contrib/admin/sites.py", line 242, in inner
    return view(request, *args, **kwargs)
  File "/Library/Frameworks/Python.framework/Versions/3.10/lib/python3.10/site-packages/django/utils/decorators.py", line 46, in _wrapper
    return bound_method(*args, **kwargs)
  File "/Library/Frameworks/Python.framework/Versions/3.10/lib/python3.10/site-packages/django/utils/decorators.py", line 133, in _wrapped_view
    response = view_func(request, *args, **kwargs)
  File "/Library/Frameworks/Python.framework/Versions/3.10/lib/python3.10/site-packages/django/contrib/admin/options.py", line 2068, in changelist_view
    "selection_note": _("0 of %(cnt)s selected") % {"cnt": len(cl.result_list)},
  File "/Library/Frameworks/Python.framework/Versions/3.10/lib/python3.10/site-packages/django/db/models/query.py", line 376, in __len__
    self._fetch_all()
  File "/Library/Frameworks/Python.framework/Versions/3.10/lib/python3.10/site-packages/django/db/models/query.py", line 1866, in _fetch_all
    self._result_cache = list(self._iterable_class(self))
  File "/Library/Frameworks/Python.framework/Versions/3.10/lib/python3.10/site-packages/django/db/models/query.py", line 87, in __iter__
    results = compiler.execute_sql(
  File "/Library/Frameworks/Python.framework/Versions/3.10/lib/python3.10/site-packages/django/db/models/sql/compiler.py", line 1395, in execute_sql
    cursor.execute(sql, params)
  File "/Library/Frameworks/Python.framework/Versions/3.10/lib/python3.10/site-packages/django/db/backends/utils.py", line 103, in execute
    return super().execute(sql, params)
  File "/Library/Frameworks/Python.framework/Versions/3.10/lib/python3.10/site-packages/django/db/backends/utils.py", line 67, in execute
    return self._execute_with_wrappers(
  File "/Library/Frameworks/Python.framework/Versions/3.10/lib/python3.10/site-packages/django/db/backends/utils.py", line 80, in _execute_with_wrappers
    return executor(sql, params, many, context)
  File "/Library/Frameworks/Python.framework/Versions/3.10/lib/python3.10/site-packages/django/db/backends/utils.py", line 84, in _execute
    with self.db.wrap_database_errors:
  File "/Library/Frameworks/Python.framework/Versions/3.10/lib/python3.10/site-packages/django/db/utils.py", line 91, in __exit__
    raise dj_exc_value.with_traceback(traceback) from exc_value
  File "/Library/Frameworks/Python.framework/Versions/3.10/lib/python3.10/site-packages/django/db/backends/utils.py", line 89, in _execute
    return self.cursor.execute(sql, params)
  File "/Library/Frameworks/Python.framework/Versions/3.10/lib/python3.10/site-packages/django/db/backends/sqlite3/base.py", line 357, in execute
    return Database.Cursor.execute(self, query, params)
django.db.utils.OperationalError: no such column: sales_notification.contact_us
"GET /admin/sales/notification/ HTTP/1.1" 500 154398
test_path/bar_codes/base/white.png /bar_codes/base/out/out.png
test_path/bar_codes/base/white.png /bar_codes/base/out/out.png
test_path/bar_codes/base/white.png /bar_codes/base/out/out.png
test_path/bar_codes/base/white.png /bar_codes/base/out/out.png
test_path/bar_codes/base/white.png /bar_codes/base/out/out.png
test_path/bar_codes/base/white.png /bar_codes/base/out/out.png
test_path/bar_codes/base/white.png /bar_codes/base/out/out.png
test_path/bar_codes/base/white.png /bar_codes/base/out/out.png
test_path/bar_codes/base/white.png /bar_codes/base/out/out.png
test_path/bar_codes/base/white.png /bar_codes/base/out/out.png
test_path/bar_codes/base/white.png /bar_codes/base/out/out.png
test_path/bar_codes/base/white.png /bar_codes/base/out/out.png
test_path/bar_codes/base/white.png /bar_codes/base/out/out.png
test_path/bar_codes/base/white.png /bar_codes/base/out/out.png
test_path/bar_codes/base/white.png /bar_codes/base/out/out.png
test_path/bar_codes/base/white.png /bar_codes/base/out/out.png
test_path/bar_codes/base/white.png /bar_codes/base/out/out.png
test_path/bar_codes/base/white.png /bar_codes/base/out/out.png
test_path/bar_codes/base/white.png /bar_codes/base/out/out.png
Internal Server Error: /api/v1/sales/inventory/inventory/notifications
Traceback (most recent call last):
  File "/Library/Frameworks/Python.framework/Versions/3.10/lib/python3.10/site-packages/rest_framework/fields.py", line 446, in get_attribute
    return get_attribute(instance, self.source_attrs)
  File "/Library/Frameworks/Python.framework/Versions/3.10/lib/python3.10/site-packages/rest_framework/fields.py", line 96, in get_attribute
    instance = getattr(instance, attr)
AttributeError: 'QuerySet' object has no attribute 'user'

During handling of the above exception, another exception occurred:

Traceback (most recent call last):
  File "/Library/Frameworks/Python.framework/Versions/3.10/lib/python3.10/site-packages/django/core/handlers/exception.py", line 55, in inner
    response = get_response(request)
  File "/Library/Frameworks/Python.framework/Versions/3.10/lib/python3.10/site-packages/django/core/handlers/base.py", line 197, in _get_response
    response = wrapped_callback(request, *callback_args, **callback_kwargs)
  File "/Library/Frameworks/Python.framework/Versions/3.10/lib/python3.10/site-packages/django/views/decorators/csrf.py", line 54, in wrapped_view
    return view_func(*args, **kwargs)
  File "/Library/Frameworks/Python.framework/Versions/3.10/lib/python3.10/site-packages/django/views/generic/base.py", line 103, in view
    return self.dispatch(request, *args, **kwargs)
  File "/Library/Frameworks/Python.framework/Versions/3.10/lib/python3.10/site-packages/rest_framework/views.py", line 509, in dispatch
    response = self.handle_exception(exc)
  File "/Library/Frameworks/Python.framework/Versions/3.10/lib/python3.10/site-packages/rest_framework/views.py", line 469, in handle_exception
    self.raise_uncaught_exception(exc)
  File "/Library/Frameworks/Python.framework/Versions/3.10/lib/python3.10/site-packages/rest_framework/views.py", line 480, in raise_uncaught_exception
    raise exc
  File "/Library/Frameworks/Python.framework/Versions/3.10/lib/python3.10/site-packages/rest_framework/views.py", line 506, in dispatch
    response = handler(request, *args, **kwargs)
  File "/Users/macmini/Machine Learning/kaarujbe/kaaruj/sales/api/inventory/views.py", line 819, in get
    return Response(serializer.data)
  File "/Library/Frameworks/Python.framework/Versions/3.10/lib/python3.10/site-packages/rest_framework/serializers.py", line 555, in data
    ret = super().data
  File "/Library/Frameworks/Python.framework/Versions/3.10/lib/python3.10/site-packages/rest_framework/serializers.py", line 253, in data
    self._data = self.to_representation(self.instance)
  File "/Library/Frameworks/Python.framework/Versions/3.10/lib/python3.10/site-packages/rest_framework/serializers.py", line 509, in to_representation
    attribute = field.get_attribute(instance)
  File "/Library/Frameworks/Python.framework/Versions/3.10/lib/python3.10/site-packages/rest_framework/relations.py", line 190, in get_attribute
    return super().get_attribute(instance)
  File "/Library/Frameworks/Python.framework/Versions/3.10/lib/python3.10/site-packages/rest_framework/fields.py", line 479, in get_attribute
    raise type(exc)(msg)
AttributeError: Got AttributeError when attempting to get a value for field `user` on serializer `NotificationSerializer`.
The serializer field might be named incorrectly and not match any attribute or key on the `QuerySet` instance.
Original exception text was: 'QuerySet' object has no attribute 'user'.
"GET /api/v1/sales/inventory/inventory/notifications HTTP/1.1" 500 122774
Internal Server Error: /api/v1/sales/inventory/inventory/notifications
Traceback (most recent call last):
  File "/Library/Frameworks/Python.framework/Versions/3.10/lib/python3.10/site-packages/rest_framework/fields.py", line 446, in get_attribute
    return get_attribute(instance, self.source_attrs)
  File "/Library/Frameworks/Python.framework/Versions/3.10/lib/python3.10/site-packages/rest_framework/fields.py", line 96, in get_attribute
    instance = getattr(instance, attr)
AttributeError: 'QuerySet' object has no attribute 'user'

During handling of the above exception, another exception occurred:

Traceback (most recent call last):
  File "/Library/Frameworks/Python.framework/Versions/3.10/lib/python3.10/site-packages/django/core/handlers/exception.py", line 55, in inner
    response = get_response(request)
  File "/Library/Frameworks/Python.framework/Versions/3.10/lib/python3.10/site-packages/django/core/handlers/base.py", line 197, in _get_response
    response = wrapped_callback(request, *callback_args, **callback_kwargs)
  File "/Library/Frameworks/Python.framework/Versions/3.10/lib/python3.10/site-packages/django/views/decorators/csrf.py", line 54, in wrapped_view
    return view_func(*args, **kwargs)
  File "/Library/Frameworks/Python.framework/Versions/3.10/lib/python3.10/site-packages/django/views/generic/base.py", line 103, in view
    return self.dispatch(request, *args, **kwargs)
  File "/Library/Frameworks/Python.framework/Versions/3.10/lib/python3.10/site-packages/rest_framework/views.py", line 509, in dispatch
    response = self.handle_exception(exc)
  File "/Library/Frameworks/Python.framework/Versions/3.10/lib/python3.10/site-packages/rest_framework/views.py", line 469, in handle_exception
    self.raise_uncaught_exception(exc)
  File "/Library/Frameworks/Python.framework/Versions/3.10/lib/python3.10/site-packages/rest_framework/views.py", line 480, in raise_uncaught_exception
    raise exc
  File "/Library/Frameworks/Python.framework/Versions/3.10/lib/python3.10/site-packages/rest_framework/views.py", line 506, in dispatch
    response = handler(request, *args, **kwargs)
  File "/Users/macmini/Machine Learning/kaarujbe/kaaruj/sales/api/inventory/views.py", line 819, in get
    return Response(serializer.data)
  File "/Library/Frameworks/Python.framework/Versions/3.10/lib/python3.10/site-packages/rest_framework/serializers.py", line 555, in data
    ret = super().data
  File "/Library/Frameworks/Python.framework/Versions/3.10/lib/python3.10/site-packages/rest_framework/serializers.py", line 253, in data
    self._data = self.to_representation(self.instance)
  File "/Library/Frameworks/Python.framework/Versions/3.10/lib/python3.10/site-packages/rest_framework/serializers.py", line 509, in to_representation
    attribute = field.get_attribute(instance)
  File "/Library/Frameworks/Python.framework/Versions/3.10/lib/python3.10/site-packages/rest_framework/relations.py", line 190, in get_attribute
    return super().get_attribute(instance)
  File "/Library/Frameworks/Python.framework/Versions/3.10/lib/python3.10/site-packages/rest_framework/fields.py", line 479, in get_attribute
    raise type(exc)(msg)
AttributeError: Got AttributeError when attempting to get a value for field `user` on serializer `NotificationSerializer`.
The serializer field might be named incorrectly and not match any attribute or key on the `QuerySet` instance.
Original exception text was: 'QuerySet' object has no attribute 'user'.
"GET /api/v1/sales/inventory/inventory/notifications HTTP/1.1" 500 122774
test_path/bar_codes/base/white.png /bar_codes/base/out/out.png
test_path/bar_codes/base/white.png /bar_codes/base/out/out.png
Internal Server Error: /api/v1/sales/inventory/inventory/notifications
Traceback (most recent call last):
  File "/Library/Frameworks/Python.framework/Versions/3.10/lib/python3.10/site-packages/rest_framework/fields.py", line 446, in get_attribute
    return get_attribute(instance, self.source_attrs)
  File "/Library/Frameworks/Python.framework/Versions/3.10/lib/python3.10/site-packages/rest_framework/fields.py", line 96, in get_attribute
    instance = getattr(instance, attr)
AttributeError: 'QuerySet' object has no attribute 'user'

During handling of the above exception, another exception occurred:

Traceback (most recent call last):
  File "/Library/Frameworks/Python.framework/Versions/3.10/lib/python3.10/site-packages/django/core/handlers/exception.py", line 55, in inner
    response = get_response(request)
  File "/Library/Frameworks/Python.framework/Versions/3.10/lib/python3.10/site-packages/django/core/handlers/base.py", line 197, in _get_response
    response = wrapped_callback(request, *callback_args, **callback_kwargs)
  File "/Library/Frameworks/Python.framework/Versions/3.10/lib/python3.10/site-packages/django/views/decorators/csrf.py", line 54, in wrapped_view
    return view_func(*args, **kwargs)
  File "/Library/Frameworks/Python.framework/Versions/3.10/lib/python3.10/site-packages/django/views/generic/base.py", line 103, in view
    return self.dispatch(request, *args, **kwargs)
  File "/Library/Frameworks/Python.framework/Versions/3.10/lib/python3.10/site-packages/rest_framework/views.py", line 509, in dispatch
    response = self.handle_exception(exc)
  File "/Library/Frameworks/Python.framework/Versions/3.10/lib/python3.10/site-packages/rest_framework/views.py", line 469, in handle_exception
    self.raise_uncaught_exception(exc)
  File "/Library/Frameworks/Python.framework/Versions/3.10/lib/python3.10/site-packages/rest_framework/views.py", line 480, in raise_uncaught_exception
    raise exc
  File "/Library/Frameworks/Python.framework/Versions/3.10/lib/python3.10/site-packages/rest_framework/views.py", line 506, in dispatch
    response = handler(request, *args, **kwargs)
  File "/Users/macmini/Machine Learning/kaarujbe/kaaruj/sales/api/inventory/views.py", line 819, in get
    return Response(serializer.data)
  File "/Library/Frameworks/Python.framework/Versions/3.10/lib/python3.10/site-packages/rest_framework/serializers.py", line 555, in data
    ret = super().data
  File "/Library/Frameworks/Python.framework/Versions/3.10/lib/python3.10/site-packages/rest_framework/serializers.py", line 253, in data
    self._data = self.to_representation(self.instance)
  File "/Library/Frameworks/Python.framework/Versions/3.10/lib/python3.10/site-packages/rest_framework/serializers.py", line 509, in to_representation
    attribute = field.get_attribute(instance)
  File "/Library/Frameworks/Python.framework/Versions/3.10/lib/python3.10/site-packages/rest_framework/relations.py", line 190, in get_attribute
    return super().get_attribute(instance)
  File "/Library/Frameworks/Python.framework/Versions/3.10/lib/python3.10/site-packages/rest_framework/fields.py", line 479, in get_attribute
    raise type(exc)(msg)
AttributeError: Got AttributeError when attempting to get a value for field `user` on serializer `NotificationSerializer`.
The serializer field might be named incorrectly and not match any attribute or key on the `QuerySet` instance.
Original exception text was: 'QuerySet' object has no attribute 'user'.
"GET /api/v1/sales/inventory/inventory/notifications HTTP/1.1" 500 122774
test_path/bar_codes/base/white.png /bar_codes/base/out/out.png
test_path/bar_codes/base/white.png /bar_codes/base/out/out.png
test_path/bar_codes/base/white.png /bar_codes/base/out/out.png
test_path/bar_codes/base/white.png /bar_codes/base/out/out.png
Internal Server Error: /api/v1/sales/inventory/inventory/notifications
Traceback (most recent call last):
  File "/Library/Frameworks/Python.framework/Versions/3.10/lib/python3.10/site-packages/rest_framework/fields.py", line 446, in get_attribute
    return get_attribute(instance, self.source_attrs)
  File "/Library/Frameworks/Python.framework/Versions/3.10/lib/python3.10/site-packages/rest_framework/fields.py", line 96, in get_attribute
    instance = getattr(instance, attr)
AttributeError: 'QuerySet' object has no attribute 'user'

During handling of the above exception, another exception occurred:

Traceback (most recent call last):
  File "/Library/Frameworks/Python.framework/Versions/3.10/lib/python3.10/site-packages/django/core/handlers/exception.py", line 55, in inner
    response = get_response(request)
  File "/Library/Frameworks/Python.framework/Versions/3.10/lib/python3.10/site-packages/django/core/handlers/base.py", line 197, in _get_response
    response = wrapped_callback(request, *callback_args, **callback_kwargs)
  File "/Library/Frameworks/Python.framework/Versions/3.10/lib/python3.10/site-packages/django/views/decorators/csrf.py", line 54, in wrapped_view
    return view_func(*args, **kwargs)
  File "/Library/Frameworks/Python.framework/Versions/3.10/lib/python3.10/site-packages/django/views/generic/base.py", line 103, in view
    return self.dispatch(request, *args, **kwargs)
  File "/Library/Frameworks/Python.framework/Versions/3.10/lib/python3.10/site-packages/rest_framework/views.py", line 509, in dispatch
    response = self.handle_exception(exc)
  File "/Library/Frameworks/Python.framework/Versions/3.10/lib/python3.10/site-packages/rest_framework/views.py", line 469, in handle_exception
    self.raise_uncaught_exception(exc)
  File "/Library/Frameworks/Python.framework/Versions/3.10/lib/python3.10/site-packages/rest_framework/views.py", line 480, in raise_uncaught_exception
    raise exc
  File "/Library/Frameworks/Python.framework/Versions/3.10/lib/python3.10/site-packages/rest_framework/views.py", line 506, in dispatch
    response = handler(request, *args, **kwargs)
  File "/Users/macmini/Machine Learning/kaarujbe/kaaruj/sales/api/inventory/views.py", line 819, in get
    return Response(serializer.data)
  File "/Library/Frameworks/Python.framework/Versions/3.10/lib/python3.10/site-packages/rest_framework/serializers.py", line 555, in data
    ret = super().data
  File "/Library/Frameworks/Python.framework/Versions/3.10/lib/python3.10/site-packages/rest_framework/serializers.py", line 253, in data
    self._data = self.to_representation(self.instance)
  File "/Library/Frameworks/Python.framework/Versions/3.10/lib/python3.10/site-packages/rest_framework/serializers.py", line 509, in to_representation
    attribute = field.get_attribute(instance)
  File "/Library/Frameworks/Python.framework/Versions/3.10/lib/python3.10/site-packages/rest_framework/relations.py", line 190, in get_attribute
    return super().get_attribute(instance)
  File "/Library/Frameworks/Python.framework/Versions/3.10/lib/python3.10/site-packages/rest_framework/fields.py", line 479, in get_attribute
    raise type(exc)(msg)
AttributeError: Got AttributeError when attempting to get a value for field `user` on serializer `NotificationSerializer`.
The serializer field might be named incorrectly and not match any attribute or key on the `QuerySet` instance.
Original exception text was: 'QuerySet' object has no attribute 'user'.
"GET /api/v1/sales/inventory/inventory/notifications HTTP/1.1" 500 122777
Internal Server Error: /api/v1/sales/inventory/inventory/notifications
Traceback (most recent call last):
  File "/Library/Frameworks/Python.framework/Versions/3.10/lib/python3.10/site-packages/rest_framework/fields.py", line 446, in get_attribute
    return get_attribute(instance, self.source_attrs)
  File "/Library/Frameworks/Python.framework/Versions/3.10/lib/python3.10/site-packages/rest_framework/fields.py", line 96, in get_attribute
    instance = getattr(instance, attr)
AttributeError: 'QuerySet' object has no attribute 'user'

During handling of the above exception, another exception occurred:

Traceback (most recent call last):
  File "/Library/Frameworks/Python.framework/Versions/3.10/lib/python3.10/site-packages/django/core/handlers/exception.py", line 55, in inner
    response = get_response(request)
  File "/Library/Frameworks/Python.framework/Versions/3.10/lib/python3.10/site-packages/django/core/handlers/base.py", line 197, in _get_response
    response = wrapped_callback(request, *callback_args, **callback_kwargs)
  File "/Library/Frameworks/Python.framework/Versions/3.10/lib/python3.10/site-packages/django/views/decorators/csrf.py", line 54, in wrapped_view
    return view_func(*args, **kwargs)
  File "/Library/Frameworks/Python.framework/Versions/3.10/lib/python3.10/site-packages/django/views/generic/base.py", line 103, in view
    return self.dispatch(request, *args, **kwargs)
  File "/Library/Frameworks/Python.framework/Versions/3.10/lib/python3.10/site-packages/rest_framework/views.py", line 509, in dispatch
    response = self.handle_exception(exc)
  File "/Library/Frameworks/Python.framework/Versions/3.10/lib/python3.10/site-packages/rest_framework/views.py", line 469, in handle_exception
    self.raise_uncaught_exception(exc)
  File "/Library/Frameworks/Python.framework/Versions/3.10/lib/python3.10/site-packages/rest_framework/views.py", line 480, in raise_uncaught_exception
    raise exc
  File "/Library/Frameworks/Python.framework/Versions/3.10/lib/python3.10/site-packages/rest_framework/views.py", line 506, in dispatch
    response = handler(request, *args, **kwargs)
  File "/Users/macmini/Machine Learning/kaarujbe/kaaruj/sales/api/inventory/views.py", line 819, in get
    return Response(serializer.data)
  File "/Library/Frameworks/Python.framework/Versions/3.10/lib/python3.10/site-packages/rest_framework/serializers.py", line 555, in data
    ret = super().data
  File "/Library/Frameworks/Python.framework/Versions/3.10/lib/python3.10/site-packages/rest_framework/serializers.py", line 253, in data
    self._data = self.to_representation(self.instance)
  File "/Library/Frameworks/Python.framework/Versions/3.10/lib/python3.10/site-packages/rest_framework/serializers.py", line 509, in to_representation
    attribute = field.get_attribute(instance)
  File "/Library/Frameworks/Python.framework/Versions/3.10/lib/python3.10/site-packages/rest_framework/relations.py", line 190, in get_attribute
    return super().get_attribute(instance)
  File "/Library/Frameworks/Python.framework/Versions/3.10/lib/python3.10/site-packages/rest_framework/fields.py", line 479, in get_attribute
    raise type(exc)(msg)
AttributeError: Got AttributeError when attempting to get a value for field `user` on serializer `NotificationSerializer`.
The serializer field might be named incorrectly and not match any attribute or key on the `QuerySet` instance.
Original exception text was: 'QuerySet' object has no attribute 'user'.
"GET /api/v1/sales/inventory/inventory/notifications HTTP/1.1" 500 122777
test_path/bar_codes/base/white.png /bar_codes/base/out/out.png
test_path/bar_codes/base/white.png /bar_codes/base/out/out.png
test_path/bar_codes/base/white.png /bar_codes/base/out/out.png
test_path/bar_codes/base/white.png /bar_codes/base/out/out.png
test_path/bar_codes/base/white.png /bar_codes/base/out/out.png
test_path/bar_codes/base/white.png /bar_codes/base/out/out.png
Internal Server Error: /admin/sales/notification/add/
Traceback (most recent call last):
  File "/Library/Frameworks/Python.framework/Versions/3.10/lib/python3.10/site-packages/django/core/handlers/exception.py", line 55, in inner
    response = get_response(request)
  File "/Library/Frameworks/Python.framework/Versions/3.10/lib/python3.10/site-packages/django/core/handlers/base.py", line 197, in _get_response
    response = wrapped_callback(request, *callback_args, **callback_kwargs)
  File "/Library/Frameworks/Python.framework/Versions/3.10/lib/python3.10/site-packages/django/contrib/admin/options.py", line 686, in wrapper
    return self.admin_site.admin_view(view)(*args, **kwargs)
  File "/Library/Frameworks/Python.framework/Versions/3.10/lib/python3.10/site-packages/django/utils/decorators.py", line 133, in _wrapped_view
    response = view_func(request, *args, **kwargs)
  File "/Library/Frameworks/Python.framework/Versions/3.10/lib/python3.10/site-packages/django/views/decorators/cache.py", line 62, in _wrapped_view_func
    response = view_func(request, *args, **kwargs)
  File "/Library/Frameworks/Python.framework/Versions/3.10/lib/python3.10/site-packages/django/contrib/admin/sites.py", line 242, in inner
    return view(request, *args, **kwargs)
  File "/Library/Frameworks/Python.framework/Versions/3.10/lib/python3.10/site-packages/django/contrib/admin/options.py", line 1890, in add_view
    return self.changeform_view(request, None, form_url, extra_context)
  File "/Library/Frameworks/Python.framework/Versions/3.10/lib/python3.10/site-packages/django/utils/decorators.py", line 46, in _wrapper
    return bound_method(*args, **kwargs)
  File "/Library/Frameworks/Python.framework/Versions/3.10/lib/python3.10/site-packages/django/utils/decorators.py", line 133, in _wrapped_view
    response = view_func(request, *args, **kwargs)
  File "/Library/Frameworks/Python.framework/Versions/3.10/lib/python3.10/site-packages/django/contrib/admin/options.py", line 1750, in changeform_view
    return self._changeform_view(request, object_id, form_url, extra_context)
  File "/Library/Frameworks/Python.framework/Versions/3.10/lib/python3.10/site-packages/django/contrib/admin/options.py", line 1808, in _changeform_view
    self.log_addition(request, new_object, change_message)
  File "/Library/Frameworks/Python.framework/Versions/3.10/lib/python3.10/site-packages/django/contrib/admin/options.py", line 924, in log_addition
    object_repr=str(obj),
TypeError: __str__ returned non-string (type int)
"POST /admin/sales/notification/add/ HTTP/1.1" 500 110851
test_path/bar_codes/base/white.png /bar_codes/base/out/out.png
test_path/bar_codes/base/white.png /bar_codes/base/out/out.png
Internal Server Error: /admin/sales/notification/add/
Traceback (most recent call last):
  File "/Library/Frameworks/Python.framework/Versions/3.10/lib/python3.10/site-packages/django/core/handlers/exception.py", line 55, in inner
    response = get_response(request)
  File "/Library/Frameworks/Python.framework/Versions/3.10/lib/python3.10/site-packages/django/core/handlers/base.py", line 197, in _get_response
    response = wrapped_callback(request, *callback_args, **callback_kwargs)
  File "/Library/Frameworks/Python.framework/Versions/3.10/lib/python3.10/site-packages/django/contrib/admin/options.py", line 686, in wrapper
    return self.admin_site.admin_view(view)(*args, **kwargs)
  File "/Library/Frameworks/Python.framework/Versions/3.10/lib/python3.10/site-packages/django/utils/decorators.py", line 133, in _wrapped_view
    response = view_func(request, *args, **kwargs)
  File "/Library/Frameworks/Python.framework/Versions/3.10/lib/python3.10/site-packages/django/views/decorators/cache.py", line 62, in _wrapped_view_func
    response = view_func(request, *args, **kwargs)
  File "/Library/Frameworks/Python.framework/Versions/3.10/lib/python3.10/site-packages/django/contrib/admin/sites.py", line 242, in inner
    return view(request, *args, **kwargs)
  File "/Library/Frameworks/Python.framework/Versions/3.10/lib/python3.10/site-packages/django/contrib/admin/options.py", line 1890, in add_view
    return self.changeform_view(request, None, form_url, extra_context)
  File "/Library/Frameworks/Python.framework/Versions/3.10/lib/python3.10/site-packages/django/utils/decorators.py", line 46, in _wrapper
    return bound_method(*args, **kwargs)
  File "/Library/Frameworks/Python.framework/Versions/3.10/lib/python3.10/site-packages/django/utils/decorators.py", line 133, in _wrapped_view
    response = view_func(request, *args, **kwargs)
  File "/Library/Frameworks/Python.framework/Versions/3.10/lib/python3.10/site-packages/django/contrib/admin/options.py", line 1750, in changeform_view
    return self._changeform_view(request, object_id, form_url, extra_context)
  File "/Library/Frameworks/Python.framework/Versions/3.10/lib/python3.10/site-packages/django/contrib/admin/options.py", line 1808, in _changeform_view
    self.log_addition(request, new_object, change_message)
  File "/Library/Frameworks/Python.framework/Versions/3.10/lib/python3.10/site-packages/django/contrib/admin/options.py", line 924, in log_addition
    object_repr=str(obj),
TypeError: __str__ returned non-string (type User)
"POST /admin/sales/notification/add/ HTTP/1.1" 500 110857
Internal Server Error: /admin/sales/notification/add/
Traceback (most recent call last):
  File "/Library/Frameworks/Python.framework/Versions/3.10/lib/python3.10/site-packages/django/core/handlers/exception.py", line 55, in inner
    response = get_response(request)
  File "/Library/Frameworks/Python.framework/Versions/3.10/lib/python3.10/site-packages/django/core/handlers/base.py", line 197, in _get_response
    response = wrapped_callback(request, *callback_args, **callback_kwargs)
  File "/Library/Frameworks/Python.framework/Versions/3.10/lib/python3.10/site-packages/django/contrib/admin/options.py", line 686, in wrapper
    return self.admin_site.admin_view(view)(*args, **kwargs)
  File "/Library/Frameworks/Python.framework/Versions/3.10/lib/python3.10/site-packages/django/utils/decorators.py", line 133, in _wrapped_view
    response = view_func(request, *args, **kwargs)
  File "/Library/Frameworks/Python.framework/Versions/3.10/lib/python3.10/site-packages/django/views/decorators/cache.py", line 62, in _wrapped_view_func
    response = view_func(request, *args, **kwargs)
  File "/Library/Frameworks/Python.framework/Versions/3.10/lib/python3.10/site-packages/django/contrib/admin/sites.py", line 242, in inner
    return view(request, *args, **kwargs)
  File "/Library/Frameworks/Python.framework/Versions/3.10/lib/python3.10/site-packages/django/contrib/admin/options.py", line 1890, in add_view
    return self.changeform_view(request, None, form_url, extra_context)
  File "/Library/Frameworks/Python.framework/Versions/3.10/lib/python3.10/site-packages/django/utils/decorators.py", line 46, in _wrapper
    return bound_method(*args, **kwargs)
  File "/Library/Frameworks/Python.framework/Versions/3.10/lib/python3.10/site-packages/django/utils/decorators.py", line 133, in _wrapped_view
    response = view_func(request, *args, **kwargs)
  File "/Library/Frameworks/Python.framework/Versions/3.10/lib/python3.10/site-packages/django/contrib/admin/options.py", line 1750, in changeform_view
    return self._changeform_view(request, object_id, form_url, extra_context)
  File "/Library/Frameworks/Python.framework/Versions/3.10/lib/python3.10/site-packages/django/contrib/admin/options.py", line 1808, in _changeform_view
    self.log_addition(request, new_object, change_message)
  File "/Library/Frameworks/Python.framework/Versions/3.10/lib/python3.10/site-packages/django/contrib/admin/options.py", line 924, in log_addition
    object_repr=str(obj),
TypeError: __str__ returned non-string (type User)
"POST /admin/sales/notification/add/ HTTP/1.1" 500 110856
test_path/bar_codes/base/white.png /bar_codes/base/out/out.png
test_path/bar_codes/base/white.png /bar_codes/base/out/out.png
Internal Server Error: /admin/inventory/customer/
Traceback (most recent call last):
  File "/Library/Frameworks/Python.framework/Versions/3.10/lib/python3.10/site-packages/django/db/backends/utils.py", line 89, in _execute
    return self.cursor.execute(sql, params)
  File "/Library/Frameworks/Python.framework/Versions/3.10/lib/python3.10/site-packages/django/db/backends/sqlite3/base.py", line 357, in execute
    return Database.Cursor.execute(self, query, params)
sqlite3.OperationalError: no such table: inventory_customer

The above exception was the direct cause of the following exception:

Traceback (most recent call last):
  File "/Library/Frameworks/Python.framework/Versions/3.10/lib/python3.10/site-packages/django/core/handlers/exception.py", line 55, in inner
    response = get_response(request)
  File "/Library/Frameworks/Python.framework/Versions/3.10/lib/python3.10/site-packages/django/core/handlers/base.py", line 197, in _get_response
    response = wrapped_callback(request, *callback_args, **callback_kwargs)
  File "/Library/Frameworks/Python.framework/Versions/3.10/lib/python3.10/site-packages/django/contrib/admin/options.py", line 686, in wrapper
    return self.admin_site.admin_view(view)(*args, **kwargs)
  File "/Library/Frameworks/Python.framework/Versions/3.10/lib/python3.10/site-packages/django/utils/decorators.py", line 133, in _wrapped_view
    response = view_func(request, *args, **kwargs)
  File "/Library/Frameworks/Python.framework/Versions/3.10/lib/python3.10/site-packages/django/views/decorators/cache.py", line 62, in _wrapped_view_func
    response = view_func(request, *args, **kwargs)
  File "/Library/Frameworks/Python.framework/Versions/3.10/lib/python3.10/site-packages/django/contrib/admin/sites.py", line 242, in inner
    return view(request, *args, **kwargs)
  File "/Library/Frameworks/Python.framework/Versions/3.10/lib/python3.10/site-packages/import_export/admin.py", line 571, in changelist_view
    return super().changelist_view(request, extra_context)
  File "/Library/Frameworks/Python.framework/Versions/3.10/lib/python3.10/site-packages/import_export/admin.py", line 734, in changelist_view
    return super().changelist_view(request, extra_context)
  File "/Library/Frameworks/Python.framework/Versions/3.10/lib/python3.10/site-packages/import_export/admin.py", line 70, in changelist_view
    return super().changelist_view(request, extra_context)
  File "/Library/Frameworks/Python.framework/Versions/3.10/lib/python3.10/site-packages/django/utils/decorators.py", line 46, in _wrapper
    return bound_method(*args, **kwargs)
  File "/Library/Frameworks/Python.framework/Versions/3.10/lib/python3.10/site-packages/django/utils/decorators.py", line 133, in _wrapped_view
    response = view_func(request, *args, **kwargs)
  File "/Library/Frameworks/Python.framework/Versions/3.10/lib/python3.10/site-packages/django/contrib/admin/options.py", line 1931, in changelist_view
    cl = self.get_changelist_instance(request)
  File "/Library/Frameworks/Python.framework/Versions/3.10/lib/python3.10/site-packages/django/contrib/admin/options.py", line 834, in get_changelist_instance
    return ChangeList(
  File "/Library/Frameworks/Python.framework/Versions/3.10/lib/python3.10/site-packages/django/contrib/admin/views/main.py", line 123, in __init__
    self.get_results(request)
  File "/Library/Frameworks/Python.framework/Versions/3.10/lib/python3.10/site-packages/django/contrib/admin/views/main.py", line 279, in get_results
    result_count = paginator.count
  File "/Library/Frameworks/Python.framework/Versions/3.10/lib/python3.10/site-packages/django/utils/functional.py", line 57, in __get__
    res = instance.__dict__[self.name] = self.func(instance)
  File "/Library/Frameworks/Python.framework/Versions/3.10/lib/python3.10/site-packages/django/core/paginator.py", line 96, in count
    return c()
  File "/Library/Frameworks/Python.framework/Versions/3.10/lib/python3.10/site-packages/django/db/models/query.py", line 621, in count
    return self.query.get_count(using=self.db)
  File "/Library/Frameworks/Python.framework/Versions/3.10/lib/python3.10/site-packages/django/db/models/sql/query.py", line 559, in get_count
    return obj.get_aggregation(using, ["__count"])["__count"]
  File "/Library/Frameworks/Python.framework/Versions/3.10/lib/python3.10/site-packages/django/db/models/sql/query.py", line 544, in get_aggregation
    result = compiler.execute_sql(SINGLE)
  File "/Library/Frameworks/Python.framework/Versions/3.10/lib/python3.10/site-packages/django/db/models/sql/compiler.py", line 1395, in execute_sql
    cursor.execute(sql, params)
  File "/Library/Frameworks/Python.framework/Versions/3.10/lib/python3.10/site-packages/django/db/backends/utils.py", line 103, in execute
    return super().execute(sql, params)
  File "/Library/Frameworks/Python.framework/Versions/3.10/lib/python3.10/site-packages/django/db/backends/utils.py", line 67, in execute
    return self._execute_with_wrappers(
  File "/Library/Frameworks/Python.framework/Versions/3.10/lib/python3.10/site-packages/django/db/backends/utils.py", line 80, in _execute_with_wrappers
    return executor(sql, params, many, context)
  File "/Library/Frameworks/Python.framework/Versions/3.10/lib/python3.10/site-packages/django/db/backends/utils.py", line 84, in _execute
    with self.db.wrap_database_errors:
  File "/Library/Frameworks/Python.framework/Versions/3.10/lib/python3.10/site-packages/django/db/utils.py", line 91, in __exit__
    raise dj_exc_value.with_traceback(traceback) from exc_value
  File "/Library/Frameworks/Python.framework/Versions/3.10/lib/python3.10/site-packages/django/db/backends/utils.py", line 89, in _execute
    return self.cursor.execute(sql, params)
  File "/Library/Frameworks/Python.framework/Versions/3.10/lib/python3.10/site-packages/django/db/backends/sqlite3/base.py", line 357, in execute
    return Database.Cursor.execute(self, query, params)
django.db.utils.OperationalError: no such table: inventory_customer
"GET /admin/inventory/customer/ HTTP/1.1" 500 187054
Internal Server Error: /admin/inventory/category/
Traceback (most recent call last):
  File "/Library/Frameworks/Python.framework/Versions/3.10/lib/python3.10/site-packages/django/db/backends/utils.py", line 89, in _execute
    return self.cursor.execute(sql, params)
  File "/Library/Frameworks/Python.framework/Versions/3.10/lib/python3.10/site-packages/django/db/backends/sqlite3/base.py", line 357, in execute
    return Database.Cursor.execute(self, query, params)
sqlite3.OperationalError: no such table: inventory_category

The above exception was the direct cause of the following exception:

Traceback (most recent call last):
  File "/Library/Frameworks/Python.framework/Versions/3.10/lib/python3.10/site-packages/django/core/handlers/exception.py", line 55, in inner
    response = get_response(request)
  File "/Library/Frameworks/Python.framework/Versions/3.10/lib/python3.10/site-packages/django/core/handlers/base.py", line 197, in _get_response
    response = wrapped_callback(request, *callback_args, **callback_kwargs)
  File "/Library/Frameworks/Python.framework/Versions/3.10/lib/python3.10/site-packages/django/contrib/admin/options.py", line 686, in wrapper
    return self.admin_site.admin_view(view)(*args, **kwargs)
  File "/Library/Frameworks/Python.framework/Versions/3.10/lib/python3.10/site-packages/django/utils/decorators.py", line 133, in _wrapped_view
    response = view_func(request, *args, **kwargs)
  File "/Library/Frameworks/Python.framework/Versions/3.10/lib/python3.10/site-packages/django/views/decorators/cache.py", line 62, in _wrapped_view_func
    response = view_func(request, *args, **kwargs)
  File "/Library/Frameworks/Python.framework/Versions/3.10/lib/python3.10/site-packages/django/contrib/admin/sites.py", line 242, in inner
    return view(request, *args, **kwargs)
  File "/Library/Frameworks/Python.framework/Versions/3.10/lib/python3.10/site-packages/django/utils/decorators.py", line 46, in _wrapper
    return bound_method(*args, **kwargs)
  File "/Library/Frameworks/Python.framework/Versions/3.10/lib/python3.10/site-packages/django/utils/decorators.py", line 133, in _wrapped_view
    response = view_func(request, *args, **kwargs)
  File "/Library/Frameworks/Python.framework/Versions/3.10/lib/python3.10/site-packages/django/contrib/admin/options.py", line 1931, in changelist_view
    cl = self.get_changelist_instance(request)
  File "/Library/Frameworks/Python.framework/Versions/3.10/lib/python3.10/site-packages/django/contrib/admin/options.py", line 834, in get_changelist_instance
    return ChangeList(
  File "/Library/Frameworks/Python.framework/Versions/3.10/lib/python3.10/site-packages/django/contrib/admin/views/main.py", line 123, in __init__
    self.get_results(request)
  File "/Library/Frameworks/Python.framework/Versions/3.10/lib/python3.10/site-packages/django/contrib/admin/views/main.py", line 279, in get_results
    result_count = paginator.count
  File "/Library/Frameworks/Python.framework/Versions/3.10/lib/python3.10/site-packages/django/utils/functional.py", line 57, in __get__
    res = instance.__dict__[self.name] = self.func(instance)
  File "/Library/Frameworks/Python.framework/Versions/3.10/lib/python3.10/site-packages/django/core/paginator.py", line 96, in count
    return c()
  File "/Library/Frameworks/Python.framework/Versions/3.10/lib/python3.10/site-packages/django/db/models/query.py", line 621, in count
    return self.query.get_count(using=self.db)
  File "/Library/Frameworks/Python.framework/Versions/3.10/lib/python3.10/site-packages/django/db/models/sql/query.py", line 559, in get_count
    return obj.get_aggregation(using, ["__count"])["__count"]
  File "/Library/Frameworks/Python.framework/Versions/3.10/lib/python3.10/site-packages/django/db/models/sql/query.py", line 544, in get_aggregation
    result = compiler.execute_sql(SINGLE)
  File "/Library/Frameworks/Python.framework/Versions/3.10/lib/python3.10/site-packages/django/db/models/sql/compiler.py", line 1395, in execute_sql
    cursor.execute(sql, params)
  File "/Library/Frameworks/Python.framework/Versions/3.10/lib/python3.10/site-packages/django/db/backends/utils.py", line 103, in execute
    return super().execute(sql, params)
  File "/Library/Frameworks/Python.framework/Versions/3.10/lib/python3.10/site-packages/django/db/backends/utils.py", line 67, in execute
    return self._execute_with_wrappers(
  File "/Library/Frameworks/Python.framework/Versions/3.10/lib/python3.10/site-packages/django/db/backends/utils.py", line 80, in _execute_with_wrappers
    return executor(sql, params, many, context)
  File "/Library/Frameworks/Python.framework/Versions/3.10/lib/python3.10/site-packages/django/db/backends/utils.py", line 84, in _execute
    with self.db.wrap_database_errors:
  File "/Library/Frameworks/Python.framework/Versions/3.10/lib/python3.10/site-packages/django/db/utils.py", line 91, in __exit__
    raise dj_exc_value.with_traceback(traceback) from exc_value
  File "/Library/Frameworks/Python.framework/Versions/3.10/lib/python3.10/site-packages/django/db/backends/utils.py", line 89, in _execute
    return self.cursor.execute(sql, params)
  File "/Library/Frameworks/Python.framework/Versions/3.10/lib/python3.10/site-packages/django/db/backends/sqlite3/base.py", line 357, in execute
    return Database.Cursor.execute(self, query, params)
django.db.utils.OperationalError: no such table: inventory_category
"GET /admin/inventory/category/ HTTP/1.1" 500 173447
test_path/bar_codes/base/white.png /bar_codes/base/out/out.png
test_path/bar_codes/base/white.png /bar_codes/base/out/out.png
test_path/bar_codes/base/white.png /bar_codes/base/out/out.png
test_path/bar_codes/base/white.png /bar_codes/base/out/out.png
test_path/bar_codes/base/white.png /bar_codes/base/out/out.png
test_path/bar_codes/base/white.png /bar_codes/base/out/out.png
test_path/bar_codes/base/white.png /bar_codes/base/out/out.png
test_path/bar_codes/base/white.png /bar_codes/base/out/out.png
test_path/bar_codes/base/white.png /bar_codes/base/out/out.png
test_path/bar_codes/base/white.png /bar_codes/base/out/out.png
test_path/bar_codes/base/white.png /bar_codes/base/out/out.png
test_path/bar_codes/base/white.png /bar_codes/base/out/out.png
test_path/bar_codes/base/white.png /bar_codes/base/out/out.png
test_path/bar_codes/base/white.png /bar_codes/base/out/out.png
test_path/bar_codes/base/white.png /bar_codes/base/out/out.png
test_path/bar_codes/base/white.png /bar_codes/base/out/out.png
test_path/bar_codes/base/white.png /bar_codes/base/out/out.png
test_path/bar_codes/base/white.png /bar_codes/base/out/out.png
test_path/bar_codes/base/white.png /bar_codes/base/out/out.png
test_path/bar_codes/base/white.png /bar_codes/base/out/out.png
test_path/bar_codes/base/white.png /bar_codes/base/out/out.png
test_path/bar_codes/base/white.png /bar_codes/base/out/out.png
test_path/bar_codes/base/white.png /bar_codes/base/out/out.png
test_path/bar_codes/base/white.png /bar_codes/base/out/out.png
test_path/bar_codes/base/white.png /bar_codes/base/out/out.png
test_path/bar_codes/base/white.png /bar_codes/base/out/out.png
test_path/bar_codes/base/white.png /bar_codes/base/out/out.png
test_path/bar_codes/base/white.png /bar_codes/base/out/out.png
test_path/bar_codes/base/white.png /bar_codes/base/out/out.png
test_path/bar_codes/base/white.png /bar_codes/base/out/out.png
test_path/bar_codes/base/white.png /bar_codes/base/out/out.png
test_path/bar_codes/base/white.png /bar_codes/base/out/out.png
test_path/bar_codes/base/white.png /bar_codes/base/out/out.png
test_path/bar_codes/base/white.png /bar_codes/base/out/out.png
test_path/bar_codes/base/white.png /bar_codes/base/out/out.png
test_path/bar_codes/base/white.png /bar_codes/base/out/out.png
test_path/bar_codes/base/white.png /bar_codes/base/out/out.png
test_path/bar_codes/base/white.png /bar_codes/base/out/out.png
test_path/bar_codes/base/white.png /bar_codes/base/out/out.png
